Workbook

Sheet 1부리그
D2: ALL-STAR LEAGUE - NATIONS 1ST
F4: LEAGUE TABLE | T4: TOP SCORERS
D5: POS | F5: TEAM | H5: P | I5: W | J5: D | K5: L | L5: G | M5: D | N5: GD | O5: PTS | S5: POS | U5: PLAYER | X5: P
D6: 1 | F6: =IFERROR(VLOOKUP(G6,시즌이미지12[[팀명]:[시즌]],2,0),"") -> #VALUE! | G6: {=_xlfn._xlws.SORT(_xlfn._xlws.SORT(_xlfn._xlws.SORT(_xlfn._xlws.SORT(_xlfn._xlws.FILTER(표1부리그[],표1부리그[경기]>0),7,1),6,-1),8,-1),9,-1)} -> 도르트문트 | H6: 6 | I6: 9 | J6: 1 | K6: 2 | L6: 47 | M6: 25 | N6: 22 | O6: 28 | S6: 1 | U6: =VLOOKUP(V6,LOGO_DB!$D:$F,3,0) -> #VALUE! | V6: {=_xlfn.TAKE(_xlfn._xlws.SORT(_xlfn.CHOOSECOLS(_xlfn._xlws.FILTER(득점데이터[], 득점데이터[대회종류]="1부리그"), 3, 2, 4), 3, -1), 10)} -> INT | W6: 사뮈엘 에토 | X6: 5
D7: 2 | F7: =IFERROR(VLOOKUP(G7,시즌이미지12[[팀명]:[시즌]],2,0),"") -> #VALUE! | G7: 인테르 | H7: 8 | I7: 6 | J7: 3 | K7: 3 | L7: 30 | M7: 24 | N7: 6 | O7: 21 | S7: 2 | U7: =VLOOKUP(V7,LOGO_DB!$D:$F,3,0) -> #VALUE! | V7: BVB | W7: P.오바메양 | X7: 4
D8: 3 | F8: =IFERROR(VLOOKUP(G8,시즌이미지12[[팀명]:[시즌]],2,0),"") | G8: 비야레알 | H8: 6 | I8: 4 | J8: 3 | K8: 1 | L8: 24 | M8: 16 | N8: 8 | O8: 15 | S8: 3 | U8: =VLOOKUP(V8,LOGO_DB!$D:$F,3,0) -> #VALUE! | V8: INT | W8: 로타어 마테우스 | X8: 2
D9: 4 | F9: =IFERROR(VLOOKUP(G9,시즌이미지12[[팀명]:[시즌]],2,0),"") -> #VALUE! | G9: 맨체스터 유나이티드 | H9: 4 | I9: 3 | J9: 4 | K9: 3 | L9: 24 | M9: 19 | N9: 5 | O9: 13 | S9: 4 | U9: =VLOOKUP(V9,LOGO_DB!$D:$F,3,0) -> #VALUE! | V9: MUN | W9: 웨인 루니 | X9: 2
D10: 5 | F10: =IFERROR(VLOOKUP(G10,시즌이미지12[[팀명]:[시즌]],2,0),"") -> #VALUE! | G10: 바이에른 뮌헨 | H10: 4 | I10: 1 | J10: 1 | K10: 2 | L10: 7 | M10: 8 | N10: -1 | O10: 4 | S10: 5 | U10: =VLOOKUP(V10,LOGO_DB!$D:$F,3,0) -> #VALUE! | V10: BVB | W10: 세루 기라시 | X10: 1
D11: 6 | F11: =IFERROR(VLOOKUP(G11,시즌이미지12[[팀명]:[시즌]],2,0),"") | S11: 6 | U11: =VLOOKUP(V11,LOGO_DB!$D:$F,3,0) -> #VALUE! | V11: BVB | W11: A.크나우프 | X11: 1
D12: 7 | F12: =IFERROR(VLOOKUP(G12,시즌이미지12[[팀명]:[시즌]],2,0),"") | S12: 7 | U12: =VLOOKUP(V12,LOGO_DB!$D:$F,3,0) -> #VALUE! | V12: BVB | W12: 율리안 브란트 | X12: 1
S13: 8 | U13: =VLOOKUP(V13,LOGO_DB!$D:$F,3,0) -> #N/A
S14: 9 | U14: =VLOOKUP(V14,LOGO_DB!$D:$F,3,0) -> #N/A
S15: 10 | U15: =VLOOKUP(V15,LOGO_DB!$D:$F,3,0) -> #N/A

Sheet 2부리그
D2: ALL-STAR LEAGUE - DIVISION 2
F4: LEAGUE TABLE | T4: TOP SCORERS
D5: POS | F5: TEAM | H5: P | I5: W | J5: D | K5: L | L5: G | M5: D | N5: GD | O5: PTS | S5: POS | U5: PLAYER | X5: P
D6: 1 | F6: =VLOOKUP(G6,시즌이미지12[[팀명]:[시즌]],2,0) -> #VALUE! | G6: {=_xlfn._xlws.SORT(_xlfn._xlws.SORT(_xlfn._xlws.SORT(_xlfn._xlws.SORT(_xlfn._xlws.FILTER(표2부리그[],표2부리그[경기]>0),7,1),6,-1),8,-1),9,-1)} -> 레버쿠젠 | H6: 9 | I6: 9 | J6: 1 | K6: 4 | L6: 34 | M6: 27 | N6: 7 | O6: 28 | S6: 1 | U6: =VLOOKUP(V6,LOGO_DB!$D:$F,3,0) -> #VALUE! | V6: {=_xlfn.TAKE(_xlfn._xlws.SORT(_xlfn.CHOOSECOLS(_xlfn._xlws.FILTER(득점데이터[], 득점데이터[대회종류]="2부리그"), 3, 2, 4), 3, -1), 10)} -> LEV | W6: 차범근 | X6: 6
D7: 2 | F7: =VLOOKUP(G7,시즌이미지12[[팀명]:[시즌]],2,0) -> #VALUE! | G7: 아틀레티코 마드리드 | H7: 7 | I7: 8 | J7: 0 | K7: 4 | L7: 37 | M7: 22 | N7: 15 | O7: 24 | S7: 2 | U7: =VLOOKUP(V7,LOGO_DB!$D:$F,3,0) -> #VALUE! | V7: ATM | W7: 모라타 | X7: 6
D8: 3 | F8: =VLOOKUP(G8,시즌이미지12[[팀명]:[시즌]],2,0) -> #VALUE! | G8: 첼시 | H8: 7 | I8: 5 | J8: 1 | K8: 6 | L8: 35 | M8: 31 | N8: 4 | O8: 16 | S8: 3 | U8: =VLOOKUP(V8,LOGO_DB!$D:$F,3,0) -> #VALUE! | V8: TOT | W8: 손흥민 | X8: 2
D9: 4 | F9: =VLOOKUP(G9,시즌이미지12[[팀명]:[시즌]],2,0) -> #VALUE! | G9: 토트넘 | H9: 5 | I9: 4 | J9: 1 | K9: 8 | L9: 23 | M9: 42 | N9: -19 | O9: 13 | S9: 4 | U9: =VLOOKUP(V9,LOGO_DB!$D:$F,3,0) -> #VALUE! | V9: LEV | W9: 플로리안 비르츠 | X9: 2
D10: 5 | F10: =VLOOKUP(G10,시즌이미지12[[팀명]:[시즌]],2,0) -> #VALUE! | G10: PSV | H10: 2 | I10: 2 | J10: 1 | K10: 2 | L10: 18 | M10: 18 | N10: 0 | O10: 7 | S10: 5 | U10: =VLOOKUP(V10,LOGO_DB!$D:$F,3,0) -> #VALUE! | V10: ATM | W10: 앙투안 그리즈만 | X10: 2
D11: 6 | F11: =VLOOKUP(G11,시즌이미지12[[팀명]:[시즌]],2,0) -> #VALUE! | G11: 유벤투스 | H11: 4 | I11: 1 | J11: 2 | K11: 4 | L11: 8 | M11: 19 | N11: -11 | O11: 5 | S11: 6 | U11: =VLOOKUP(V11,LOGO_DB!$D:$F,3,0) -> #N/A | V11: AUG | W11: 필리프 티츠 | X11: 1
D12: 7 | F12: =VLOOKUP(G12,시즌이미지12[[팀명]:[시즌]],2,0) -> #N/A | G12: 아우크스부르크 | H12: 8 | I12: 0 | J12: 2 | K12: 13 | L12: 17 | M12: 53 | N12: -36 | O12: 2 | S12: 7 | U12: =VLOOKUP(V12,LOGO_DB!$D:$F,3,0) -> #VALUE! | V12: ATM | W12: 차을라르 쇠윈쥐 | X12: 1
S13: 8 | U13: =VLOOKUP(V13,LOGO_DB!$D:$F,3,0) -> #VALUE! | V13: ATM | W13: 마르코스 요렌테 | X13: 1
S14: 9 | U14: =VLOOKUP(V14,LOGO_DB!$D:$F,3,0) -> #VALUE! | V14: TOT | W14: 해리 케인 | X14: 1
S15: 10 | U15: =VLOOKUP(V15,LOGO_DB!$D:$F,3,0) -> #VALUE! | V15: LEV | W15: 율리안 브란트 | X15: 1

Sheet FA컵
D2: ALL-STAR LEAGUE - DIVISION 2
F4: LEAGUE TABLE | T4: TOP SCORERS
D5: POS | F5: TEAM | H5: P | I5: W | J5: D | K5: L | L5: G | M5: D | N5: GD | O5: PTS | S5: POS | U5: PLAYER | X5: P
D6: 1 | F6: =VLOOKUP(G6,시즌이미지12[[팀명]:[시즌]],2,0) -> #VALUE! | G6: {=_xlfn._xlws.SORT(_xlfn._xlws.SORT(_xlfn._xlws.SORT(_xlfn._xlws.SORT(_xlfn._xlws.FILTER(표1부리그[],표1부리그[경기]>0),7,1),6,-1),8,-1),9,-1)} -> 도르트문트 | H6: 6 | I6: 9 | J6: 1 | K6: 2 | L6: 47 | M6: 25 | N6: 22 | O6: 28 | S6: 1 | U6: =VLOOKUP(V6,LOGO_DB!$D:$F,3,0) -> #VALUE! | V6: {=_xlfn.TAKE(_xlfn._xlws.SORT(_xlfn.CHOOSECOLS(_xlfn._xlws.FILTER(득점데이터[], 득점데이터[대회종류]="1부리그"), 3, 2, 4), 3, -1), 10)} -> INT | W6: 사뮈엘 에토 | X6: 5
D7: 2 | F7: =VLOOKUP(G7,시즌이미지12[[팀명]:[시즌]],2,0) -> #VALUE! | G7: 인테르 | H7: 8 | I7: 6 | J7: 3 | K7: 3 | L7: 30 | M7: 24 | N7: 6 | O7: 21 | S7: 2 | U7: =VLOOKUP(V7,LOGO_DB!$D:$F,3,0) -> #VALUE! | V7: BVB | W7: P.오바메양 | X7: 4
D8: 3 | F8: =VLOOKUP(G8,시즌이미지12[[팀명]:[시즌]],2,0) -> #N/A | G8: 비야레알 | H8: 6 | I8: 4 | J8: 3 | K8: 1 | L8: 24 | M8: 16 | N8: 8 | O8: 15 | S8: 3 | U8: =VLOOKUP(V8,LOGO_DB!$D:$F,3,0) -> #VALUE! | V8: INT | W8: 로타어 마테우스 | X8: 2
D9: 4 | F9: =VLOOKUP(G9,시즌이미지12[[팀명]:[시즌]],2,0) -> #VALUE! | G9: 맨체스터 유나이티드 | H9: 4 | I9: 3 | J9: 4 | K9: 3 | L9: 24 | M9: 19 | N9: 5 | O9: 13 | S9: 4 | U9: =VLOOKUP(V9,LOGO_DB!$D:$F,3,0) -> #VALUE! | V9: MUN | W9: 웨인 루니 | X9: 2
D10: 5 | F10: =VLOOKUP(G10,시즌이미지12[[팀명]:[시즌]],2,0) -> #VALUE! | G10: 바이에른 뮌헨 | H10: 4 | I10: 1 | J10: 1 | K10: 2 | L10: 7 | M10: 8 | N10: -1 | O10: 4 | S10: 5 | U10: =VLOOKUP(V10,LOGO_DB!$D:$F,3,0) -> #VALUE! | V10: BVB | W10: 세루 기라시 | X10: 1
D11: 6 | F11: =VLOOKUP(G11,시즌이미지12[[팀명]:[시즌]],2,0) -> #N/A | S11: 6 | U11: =VLOOKUP(V11,LOGO_DB!$D:$F,3,0) -> #VALUE! | V11: BVB | W11: A.크나우프 | X11: 1
D12: 7 | F12: =VLOOKUP(G12,시즌이미지12[[팀명]:[시즌]],2,0) -> #N/A | S12: 7 | U12: =VLOOKUP(V12,LOGO_DB!$D:$F,3,0) -> #VALUE! | V12: BVB | W12: 율리안 브란트 | X12: 1
S13: 8 | U13: =VLOOKUP(V13,LOGO_DB!$D:$F,3,0) -> #N/A
S14: 9 | U14: =VLOOKUP(V14,LOGO_DB!$D:$F,3,0) -> #N/A
S15: 10 | U15: =VLOOKUP(V15,LOGO_DB!$D:$F,3,0) -> #N/A

Sheet UCL
D2: ALL-STAR LEAGUE - DIVISION 2
F4: LEAGUE TABLE | T4: TOP SCORERS
D5: POS | F5: TEAM | H5: P | I5: W | J5: D | K5: L | L5: G | M5: D | N5: GD | O5: PTS | S5: POS | U5: PLAYER | X5: P
D6: 1 | F6: =VLOOKUP(G6,시즌이미지12[[팀명]:[시즌]],2,0) -> #VALUE! | G6: {=_xlfn._xlws.SORT(_xlfn._xlws.SORT(_xlfn._xlws.SORT(_xlfn._xlws.SORT(_xlfn._xlws.FILTER(표1부리그[],표1부리그[경기]>0),7,1),6,-1),8,-1),9,-1)} -> 도르트문트 | H6: 6 | I6: 9 | J6: 1 | K6: 2 | L6: 47 | M6: 25 | N6: 22 | O6: 28 | S6: 1 | U6: =VLOOKUP(V6,LOGO_DB!$D:$F,3,0) -> #VALUE! | V6: {=_xlfn.TAKE(_xlfn._xlws.SORT(_xlfn.CHOOSECOLS(_xlfn._xlws.FILTER(득점데이터[], 득점데이터[대회종류]="1부리그"), 3, 2, 4), 3, -1), 10)} -> INT | W6: 사뮈엘 에토 | X6: 5
D7: 2 | F7: =VLOOKUP(G7,시즌이미지12[[팀명]:[시즌]],2,0) -> #VALUE! | G7: 인테르 | H7: 8 | I7: 6 | J7: 3 | K7: 3 | L7: 30 | M7: 24 | N7: 6 | O7: 21 | S7: 2 | U7: =VLOOKUP(V7,LOGO_DB!$D:$F,3,0) -> #VALUE! | V7: BVB | W7: P.오바메양 | X7: 4
D8: 3 | F8: =VLOOKUP(G8,시즌이미지12[[팀명]:[시즌]],2,0) -> #N/A | G8: 비야레알 | H8: 6 | I8: 4 | J8: 3 | K8: 1 | L8: 24 | M8: 16 | N8: 8 | O8: 15 | S8: 3 | U8: =VLOOKUP(V8,LOGO_DB!$D:$F,3,0) -> #VALUE! | V8: INT | W8: 로타어 마테우스 | X8: 2
D9: 4 | F9: =VLOOKUP(G9,시즌이미지12[[팀명]:[시즌]],2,0) -> #VALUE! | G9: 맨체스터 유나이티드 | H9: 4 | I9: 3 | J9: 4 | K9: 3 | L9: 24 | M9: 19 | N9: 5 | O9: 13 | S9: 4 | U9: =VLOOKUP(V9,LOGO_DB!$D:$F,3,0) -> #VALUE! | V9: MUN | W9: 웨인 루니 | X9: 2
D10: 5 | F10: =VLOOKUP(G10,시즌이미지12[[팀명]:[시즌]],2,0) -> #VALUE! | G10: 바이에른 뮌헨 | H10: 4 | I10: 1 | J10: 1 | K10: 2 | L10: 7 | M10: 8 | N10: -1 | O10: 4 | S10: 5 | U10: =VLOOKUP(V10,LOGO_DB!$D:$F,3,0) -> #VALUE! | V10: BVB | W10: 세루 기라시 | X10: 1
D11: 6 | F11: =VLOOKUP(G11,시즌이미지12[[팀명]:[시즌]],2,0) -> #N/A | S11: 6 | U11: =VLOOKUP(V11,LOGO_DB!$D:$F,3,0) -> #VALUE! | V11: BVB | W11: A.크나우프 | X11: 1
D12: 7 | F12: =VLOOKUP(G12,시즌이미지12[[팀명]:[시즌]],2,0) -> #N/A | S12: 7 | U12: =VLOOKUP(V12,LOGO_DB!$D:$F,3,0) -> #VALUE! | V12: BVB | W12: 율리안 브란트 | X12: 1
S13: 8 | U13: =VLOOKUP(V13,LOGO_DB!$D:$F,3,0) -> #N/A
S14: 9 | U14: =VLOOKUP(V14,LOGO_DB!$D:$F,3,0) -> #N/A
S15: 10 | U15: =VLOOKUP(V15,LOGO_DB!$D:$F,3,0) -> #N/A

Sheet 리그테이블DB
A1: 경기결과확정체크 | B1: 대회 종류 | C1: 팀명 | D1: 득점 | E1: 실점 | F1: 상대팀 | G1: 승점 | H1: 승 | I1: 무 | J1: 패 | K1: 승(개수) | L1: 무(개수) | M1: 패(개수) | N1: 득실 | P1: 1부리그 | Q1: 2 | R1: 3 | S1: 4 | T1: 5 | U1: 6 | V1: 7 | W1: 8 | X1: 9 | Y1: 9
A2: TRUE, | I2: 1 | P2: 팀명 | Q2: 경기 | R2: 승 | S2: 무 | T2: 패 | U2: 득점 | V2: 실점 | W2: 득실 | X2: 승점
A3: TRUE, | I3: 1 | P3: 도르트문트 | Q3: =COUNTIFS(전체순위표[팀명],표1부리그[[#This Row],[팀명]],전체순위표[대회 종류],$P$1) -> 6 | R3: =SUMIF(전체순위표[팀명],표1부리그[[#This Row],[팀명]],전체순위표[승]) -> 9 | S3: =SUMIF(전체순위표[팀명],표1부리그[[#This Row],[팀명]],전체순위표[무]) -> 1 | T3: =SUMIF(전체순위표[팀명],표1부리그[[#This Row],[팀명]],전체순위표[패]) -> 2 | U3: =SUMIF(전체순위표[팀명],표1부리그[[#This Row],[팀명]],전체순위표[득점]) -> 47 | V3: =SUMIF(전체순위표[팀명],표1부리그[[#This Row],[팀명]],전체순위표[실점]) -> 25 | W3: =SUMIF(전체순위표[팀명],표1부리그[[#This Row],[팀명]],전체순위표[득실]) -> 22 | X3: =SUMIF(전체순위표[팀명],표1부리그[[#This Row],[팀명]],전체순위표[승점]) -> 28 | Z3: {=_xlfn._xlws.SORT(_xlfn._xlws.SORT(_xlfn._xlws.SORT(_xlfn._xlws.SORT(_xlfn._xlws.FILTER(표1부리그[],표1부리그[경기]>0),7,1),6,-1),8,-1),9,-1)} -> 도르트문트 | AA3: 6 | AB3: 9 | AC3: 1 | AD3: 2 | AE3: 47 | AF3: 25 | AG3: 22 | AH3: 28
A4: TRUE, | B4: 1부리그 | C4: 맨체스터 유나이티드 | D4: 2 | E4: 2 | F4: 인테르 | G4: 1 | H4: 0 | I4: 1 | J4: 0 | K4: 0 | L4: 1 | M4: 0 | N4: 0 | P4: 바이에른 뮌헨 | Q4: =COUNTIFS(전체순위표[팀명],표1부리그[[#This Row],[팀명]],전체순위표[대회 종류],$P$1) -> 4 | R4: =SUMIF(전체순위표[팀명],표1부리그[[#This Row],[팀명]],전체순위표[승]) -> 1 | S4: =SUMIF(전체순위표[팀명],표1부리그[[#This Row],[팀명]],전체순위표[무]) -> 1 | T4: =SUMIF(전체순위표[팀명],표1부리그[[#This Row],[팀명]],전체순위표[패]) -> 2 | U4: =SUMIF(전체순위표[팀명],표1부리그[[#This Row],[팀명]],전체순위표[득점]) -> 7 | V4: =SUMIF(전체순위표[팀명],표1부리그[[#This Row],[팀명]],전체순위표[실점]) -> 8 | W4: =SUMIF(전체순위표[팀명],표1부리그[[#This Row],[팀명]],전체순위표[득실]) -> -1 | X4: =SUMIF(전체순위표[팀명],표1부리그[[#This Row],[팀명]],전체순위표[승점]) -> 4 | Z4: 인테르 | AA4: 8 | AB4: 6 | AC4: 3 | AD4: 3 | AE4: 30 | AF4: 24 | AG4: 6 | AH4: 21
A5: TRUE, | B5: 1부리그 | C5: 맨체스터 유나이티드 | D5: 0 | E5: 1 | F5: 인테르 | G5: 0 | H5: 0 | I5: 0 | J5: 1 | K5: 0 | L5: 0 | M5: 1 | N5: -1 | P5: 맨체스터 유나이티드 | Q5: =COUNTIFS(전체순위표[팀명],표1부리그[[#This Row],[팀명]],전체순위표[대회 종류],$P$1) -> 4 | R5: =SUMIF(전체순위표[팀명],표1부리그[[#This Row],[팀명]],전체순위표[승]) -> 3 | S5: =SUMIF(전체순위표[팀명],표1부리그[[#This Row],[팀명]],전체순위표[무]) -> 4 | T5: =SUMIF(전체순위표[팀명],표1부리그[[#This Row],[팀명]],전체순위표[패]) -> 3 | U5: =SUMIF(전체순위표[팀명],표1부리그[[#This Row],[팀명]],전체순위표[득점]) -> 24 | V5: =SUMIF(전체순위표[팀명],표1부리그[[#This Row],[팀명]],전체순위표[실점]) -> 19 | W5: =SUMIF(전체순위표[팀명],표1부리그[[#This Row],[팀명]],전체순위표[득실]) -> 5 | X5: =SUMIF(전체순위표[팀명],표1부리그[[#This Row],[팀명]],전체순위표[승점]) -> 13 | Z5: 비야레알 | AA5: 6 | AB5: 4 | AC5: 3 | AD5: 1 | AE5: 24 | AF5: 16 | AG5: 8 | AH5: 15
A6: TRUE, | B6: 1부리그 | C6: 도르트문트 | D6: 3 | E6: 2 | F6: 인테르 | G6: 3 | H6: 1 | I6: 0 | J6: 0 | K6: 1 | L6: 0 | M6: 0 | N6: 1 | P6: 인테르 | Q6: =COUNTIFS(전체순위표[팀명],표1부리그[[#This Row],[팀명]],전체순위표[대회 종류],$P$1) -> 8 | R6: =SUMIF(전체순위표[팀명],표1부리그[[#This Row],[팀명]],전체순위표[승]) -> 6 | S6: =SUMIF(전체순위표[팀명],표1부리그[[#This Row],[팀명]],전체순위표[무]) -> 3 | T6: =SUMIF(전체순위표[팀명],표1부리그[[#This Row],[팀명]],전체순위표[패]) -> 3 | U6: =SUMIF(전체순위표[팀명],표1부리그[[#This Row],[팀명]],전체순위표[득점]) -> 30 | V6: =SUMIF(전체순위표[팀명],표1부리그[[#This Row],[팀명]],전체순위표[실점]) -> 24 | W6: =SUMIF(전체순위표[팀명],표1부리그[[#This Row],[팀명]],전체순위표[득실]) -> 6 | X6: =SUMIF(전체순위표[팀명],표1부리그[[#This Row],[팀명]],전체순위표[승점]) -> 21 | Z6: 맨체스터 유나이티드 | AA6: 4 | AB6: 3 | AC6: 4 | AD6: 3 | AE6: 24 | AF6: 19 | AG6: 5 | AH6: 13
A7: TRUE, | B7: 1부리그 | C7: 인테르 | D7: 2 | E7: 4 | F7: 도르트문트 | G7: 0 | H7: 0 | I7: 0 | J7: 1 | K7: 0 | L7: 0 | M7: 1 | N7: -2 | P7: 비야레알 | Q7: =COUNTIFS(전체순위표[팀명],표1부리그[[#This Row],[팀명]],전체순위표[대회 종류],$P$1) -> 6 | R7: =SUMIF(전체순위표[팀명],표1부리그[[#This Row],[팀명]],전체순위표[승]) -> 4 | S7: =SUMIF(전체순위표[팀명],표1부리그[[#This Row],[팀명]],전체순위표[무]) -> 3 | T7: =SUMIF(전체순위표[팀명],표1부리그[[#This Row],[팀명]],전체순위표[패]) -> 1 | U7: =SUMIF(전체순위표[팀명],표1부리그[[#This Row],[팀명]],전체순위표[득점]) -> 24 | V7: =SUMIF(전체순위표[팀명],표1부리그[[#This Row],[팀명]],전체순위표[실점]) -> 16 | W7: =SUMIF(전체순위표[팀명],표1부리그[[#This Row],[팀명]],전체순위표[득실]) -> 8 | X7: =SUMIF(전체순위표[팀명],표1부리그[[#This Row],[팀명]],전체순위표[승점]) -> 15 | Z7: 바이에른 뮌헨 | AA7: 4 | AB7: 1 | AC7: 1 | AD7: 2 | AE7: 7 | AF7: 8 | AG7: -1 | AH7: 4
A8: TRUE, | B8: 1부리그 | C8: 인테르 | D8: 2 | E8: 2 | F8: 바이에른 뮌헨 | G8: 1 | H8: 0 | I8: 1 | J8: 0 | K8: 0 | L8: 1 | M8: 0 | N8: 0 | P8: 뉴캐슬 | Q8: =COUNTIFS(전체순위표[팀명],표1부리그[[#This Row],[팀명]],전체순위표[대회 종류],$P$1) -> 0 | R8: =SUMIF(전체순위표[팀명],표1부리그[[#This Row],[팀명]],전체순위표[승]) -> 0 | S8: =SUMIF(전체순위표[팀명],표1부리그[[#This Row],[팀명]],전체순위표[무]) -> 0 | T8: =SUMIF(전체순위표[팀명],표1부리그[[#This Row],[팀명]],전체순위표[패]) -> 0 | U8: =SUMIF(전체순위표[팀명],표1부리그[[#This Row],[팀명]],전체순위표[득점]) -> 0 | V8: =SUMIF(전체순위표[팀명],표1부리그[[#This Row],[팀명]],전체순위표[실점]) -> 0 | W8: =SUMIF(전체순위표[팀명],표1부리그[[#This Row],[팀명]],전체순위표[득실]) -> 0 | X8: =SUMIF(전체순위표[팀명],표1부리그[[#This Row],[팀명]],전체순위표[승점]) -> 0
A9: TRUE, | B9: 1부리그 | C9: 인테르 | D9: 2 | E9: 0 | F9: 바이에른 뮌헨 | G9: 3 | H9: 1 | I9: 0 | J9: 0 | K9: 1 | L9: 0 | M9: 0 | N9: 2
A10: TRUE, | B10: 1부리그 | C10: 도르트문트 | D10: 4 | E10: 2 | F10: 바이에른 뮌헨 | G10: 3 | H10: 1 | I10: 0 | J10: 0 | K10: 1 | L10: 0 | M10: 0 | N10: 2
A11: TRUE, | B11: 1부리그 | C11: 도르트문트 | D11: 0 | E11: 3 | F11: 바이에른 뮌헨 | G11: 0 | H11: 0 | I11: 0 | J11: 1 | K11: 0 | L11: 0 | M11: 1 | N11: -3 | P11: 2부리그
A12: TRUE, | B12: 1부리그 | C12: 인테르 | D12: 1 | E12: 3 | F12: 비야레알 | G12: 0 | H12: 0 | I12: 0 | J12: 1 | K12: 0 | L12: 0 | M12: 1 | N12: -2 | P12: 팀명 | Q12: 경기 | R12: 승 | S12: 무 | T12: 패 | U12: 득점 | V12: 실점 | W12: 득실 | X12: 승점
A13: TRUE, | B13: 1부리그 | C13: 인테르 | D13: 3 | E13: 3 | F13: 비야레알 | G13: 1 | H13: 0 | I13: 1 | J13: 0 | K13: 0 | L13: 1 | M13: 0 | N13: 0 | P13: 아틀레티코 마드리드 | Q13: =COUNTIFS(전체순위표[팀명],표2부리그[[#This Row],[팀명]],전체순위표[대회 종류],$P$11) -> 7 | R13: =SUMIF(전체순위표[팀명],표2부리그[[#This Row],[팀명]],전체순위표[승]) -> 8 | S13: =SUMIF(전체순위표[팀명],표2부리그[[#This Row],[팀명]],전체순위표[무]) -> 0 | T13: =SUMIF(전체순위표[팀명],표2부리그[[#This Row],[팀명]],전체순위표[패]) -> 4 | U13: =SUMIF(전체순위표[팀명],표2부리그[[#This Row],[팀명]],전체순위표[득점]) -> 37 | V13: =SUMIF(전체순위표[팀명],표2부리그[[#This Row],[팀명]],전체순위표[실점]) -> 22 | W13: =SUMIF(전체순위표[팀명],표2부리그[[#This Row],[팀명]],전체순위표[득실]) -> 15 | X13: =SUMIF(전체순위표[팀명],표2부리그[[#This Row],[팀명]],전체순위표[승점]) -> 24
A14: TRUE, | B14: 1부리그 | C14: 도르트문트 | D14: 2 | E14: 3 | F14: 비야레알 | G14: 0 | H14: 0 | I14: 0 | J14: 1 | K14: 0 | L14: 0 | M14: 1 | N14: -1 | P14: 레버쿠젠 | Q14: =COUNTIFS(전체순위표[팀명],표2부리그[[#This Row],[팀명]],전체순위표[대회 종류],$P$11) -> 9 | R14: =SUMIF(전체순위표[팀명],표2부리그[[#This Row],[팀명]],전체순위표[승]) -> 9 | S14: =SUMIF(전체순위표[팀명],표2부리그[[#This Row],[팀명]],전체순위표[무]) -> 1 | T14: =SUMIF(전체순위표[팀명],표2부리그[[#This Row],[팀명]],전체순위표[패]) -> 4 | U14: =SUMIF(전체순위표[팀명],표2부리그[[#This Row],[팀명]],전체순위표[득점]) -> 34 | V14: =SUMIF(전체순위표[팀명],표2부리그[[#This Row],[팀명]],전체순위표[실점]) -> 27 | W14: =SUMIF(전체순위표[팀명],표2부리그[[#This Row],[팀명]],전체순위표[득실]) -> 7 | X14: =SUMIF(전체순위표[팀명],표2부리그[[#This Row],[팀명]],전체순위표[승점]) -> 28
A15: TRUE, | B15: 1부리그 | C15: 도르트문트 | D15: 4 | E15: 3 | F15: 비야레알 | G15: 3 | H15: 1 | I15: 0 | J15: 0 | K15: 1 | L15: 0 | M15: 0 | N15: 1 | P15: 레알 마드리드 | Q15: =COUNTIFS(전체순위표[팀명],표2부리그[[#This Row],[팀명]],전체순위표[대회 종류],$P$11) -> 0 | R15: =SUMIF(전체순위표[팀명],표2부리그[[#This Row],[팀명]],전체순위표[승]) -> 0 | S15: =SUMIF(전체순위표[팀명],표2부리그[[#This Row],[팀명]],전체순위표[무]) -> 0 | T15: =SUMIF(전체순위표[팀명],표2부리그[[#This Row],[팀명]],전체순위표[패]) -> 0 | U15: =SUMIF(전체순위표[팀명],표2부리그[[#This Row],[팀명]],전체순위표[득점]) -> 0 | V15: =SUMIF(전체순위표[팀명],표2부리그[[#This Row],[팀명]],전체순위표[실점]) -> 0 | W15: =SUMIF(전체순위표[팀명],표2부리그[[#This Row],[팀명]],전체순위표[득실]) -> 0 | X15: =SUMIF(전체순위표[팀명],표2부리그[[#This Row],[팀명]],전체순위표[승점]) -> 0
A16: TRUE, | B16: 1부리그 | C16: 맨체스터 유나이티드 | D16: 2 | E16: 2 | F16: 비야레알 | G16: 1 | H16: 0 | I16: 1 | J16: 0 | K16: 0 | L16: 1 | M16: 0 | N16: 0 | P16: 첼시 | Q16: =COUNTIFS(전체순위표[팀명],표2부리그[[#This Row],[팀명]],전체순위표[대회 종류],$P$11) -> 7 | R16: =SUMIF(전체순위표[팀명],표2부리그[[#This Row],[팀명]],전체순위표[승]) -> 5 | S16: =SUMIF(전체순위표[팀명],표2부리그[[#This Row],[팀명]],전체순위표[무]) -> 1 | T16: =SUMIF(전체순위표[팀명],표2부리그[[#This Row],[팀명]],전체순위표[패]) -> 6 | U16: =SUMIF(전체순위표[팀명],표2부리그[[#This Row],[팀명]],전체순위표[득점]) -> 35 | V16: =SUMIF(전체순위표[팀명],표2부리그[[#This Row],[팀명]],전체순위표[실점]) -> 31 | W16: =SUMIF(전체순위표[팀명],표2부리그[[#This Row],[팀명]],전체순위표[득실]) -> 4 | X16: =SUMIF(전체순위표[팀명],표2부리그[[#This Row],[팀명]],전체순위표[승점]) -> 16
A17: TRUE, | B17: 1부리그 | C17: 맨체스터 유나이티드 | D17: 1 | E17: 1 | F17: 비야레알 | G17: 1 | H17: 0 | I17: 1 | J17: 0 | K17: 0 | L17: 1 | M17: 0 | N17: 0 | P17: PSV | Q17: =COUNTIFS(전체순위표[팀명],표2부리그[[#This Row],[팀명]],전체순위표[대회 종류],$P$11) -> 2 | R17: =SUMIF(전체순위표[팀명],표2부리그[[#This Row],[팀명]],전체순위표[승]) -> 2 | S17: =SUMIF(전체순위표[팀명],표2부리그[[#This Row],[팀명]],전체순위표[무]) -> 1 | T17: =SUMIF(전체순위표[팀명],표2부리그[[#This Row],[팀명]],전체순위표[패]) -> 2 | U17: =SUMIF(전체순위표[팀명],표2부리그[[#This Row],[팀명]],전체순위표[득점]) -> 18 | V17: =SUMIF(전체순위표[팀명],표2부리그[[#This Row],[팀명]],전체순위표[실점]) -> 18 | W17: =SUMIF(전체순위표[팀명],표2부리그[[#This Row],[팀명]],전체순위표[득실]) -> 0 | X17: =SUMIF(전체순위표[팀명],표2부리그[[#This Row],[팀명]],전체순위표[승점]) -> 7
A18: TRUE, | B18: 1부리그 | C18: 인테르 | D18: 2 | E18: 2 | F18: 맨체스터 유나이티드 | G18: 1 | H18: 0 | I18: 1 | J18: 0 | K18: 0 | L18: 1 | M18: 0 | N18: 0 | P18: 토트넘 | Q18: =COUNTIFS(전체순위표[팀명],표2부리그[[#This Row],[팀명]],전체순위표[대회 종류],$P$11) -> 5 | R18: =SUMIF(전체순위표[팀명],표2부리그[[#This Row],[팀명]],전체순위표[승]) -> 4 | S18: =SUMIF(전체순위표[팀명],표2부리그[[#This Row],[팀명]],전체순위표[무]) -> 1 | T18: =SUMIF(전체순위표[팀명],표2부리그[[#This Row],[팀명]],전체순위표[패]) -> 8 | U18: =SUMIF(전체순위표[팀명],표2부리그[[#This Row],[팀명]],전체순위표[득점]) -> 23 | V18: =SUMIF(전체순위표[팀명],표2부리그[[#This Row],[팀명]],전체순위표[실점]) -> 42 | W18: =SUMIF(전체순위표[팀명],표2부리그[[#This Row],[팀명]],전체순위표[득실]) -> -19 | X18: =SUMIF(전체순위표[팀명],표2부리그[[#This Row],[팀명]],전체순위표[승점]) -> 13
A19: TRUE, | B19: 1부리그 | C19: 인테르 | D19: 1 | E19: 0 | F19: 맨체스터 유나이티드 | G19: 3 | H19: 1 | I19: 0 | J19: 0 | K19: 1 | L19: 0 | M19: 0 | N19: 1 | P19: 유벤투스 | Q19: =COUNTIFS(전체순위표[팀명],표2부리그[[#This Row],[팀명]],전체순위표[대회 종류],$P$11) -> 4 | R19: =SUMIF(전체순위표[팀명],표2부리그[[#This Row],[팀명]],전체순위표[승]) -> 1 | S19: =SUMIF(전체순위표[팀명],표2부리그[[#This Row],[팀명]],전체순위표[무]) -> 2 | T19: =SUMIF(전체순위표[팀명],표2부리그[[#This Row],[팀명]],전체순위표[패]) -> 4 | U19: =SUMIF(전체순위표[팀명],표2부리그[[#This Row],[팀명]],전체순위표[득점]) -> 8 | V19: =SUMIF(전체순위표[팀명],표2부리그[[#This Row],[팀명]],전체순위표[실점]) -> 19 | W19: =SUMIF(전체순위표[팀명],표2부리그[[#This Row],[팀명]],전체순위표[득실]) -> -11 | X19: =SUMIF(전체순위표[팀명],표2부리그[[#This Row],[팀명]],전체순위표[승점]) -> 5
A20: TRUE, | B20: 1부리그 | C20: 인테르 | D20: 2 | E20: 3 | F20: 도르트문트 | G20: 0 | H20: 0 | I20: 0 | J20: 1 | K20: 0 | L20: 0 | M20: 1 | N20: -1 | P20: 아우크스부르크 | Q20: =COUNTIFS(전체순위표[팀명],표2부리그[[#This Row],[팀명]],전체순위표[대회 종류],$P$11) -> 8 | R20: =SUMIF(전체순위표[팀명],표2부리그[[#This Row],[팀명]],전체순위표[승]) -> 0 | S20: =SUMIF(전체순위표[팀명],표2부리그[[#This Row],[팀명]],전체순위표[무]) -> 2 | T20: =SUMIF(전체순위표[팀명],표2부리그[[#This Row],[팀명]],전체순위표[패]) -> 13 | U20: =SUMIF(전체순위표[팀명],표2부리그[[#This Row],[팀명]],전체순위표[득점]) -> 17 | V20: =SUMIF(전체순위표[팀명],표2부리그[[#This Row],[팀명]],전체순위표[실점]) -> 53 | W20: =SUMIF(전체순위표[팀명],표2부리그[[#This Row],[팀명]],전체순위표[득실]) -> -36 | X20: =SUMIF(전체순위표[팀명],표2부리그[[#This Row],[팀명]],전체순위표[승점]) -> 2
A21: TRUE, | B21: 1부리그 | C21: 도르트문트 | D21: 4 | E21: 2 | F21: 인테르 | G21: 3 | H21: 1 | I21: 0 | J21: 0 | K21: 1 | L21: 0 | M21: 0 | N21: 2
A22: TRUE, | B22: 1부리그 | C22: 바이에른 뮌헨 | D22: 2 | E22: 2 | F22: 인테르 | G22: 1 | H22: 0 | I22: 1 | J22: 0 | K22: 0 | L22: 1 | M22: 0 | N22: 0
A23: TRUE, | B23: 1부리그 | C23: 바이에른 뮌헨 | D23: 0 | E23: 2 | F23: 인테르 | G23: 0 | H23: 0 | I23: 0 | J23: 1 | K23: 0 | L23: 0 | M23: 1 | N23: -2
A24: TRUE, | B24: 1부리그 | C24: 바이에른 뮌헨 | D24: 2 | E24: 4 | F24: 도르트문트 | G24: 0 | H24: 0 | I24: 0 | J24: 1 | K24: 0 | L24: 0 | M24: 1 | N24: -2 | Z24: {=_xlfn._xlws.SORT(_xlfn._xlws.SORT(_xlfn._xlws.SORT(_xlfn._xlws.SORT(_xlfn._xlws.FILTER(표2부리그[],표2부리그[경기]>0),7,1),6,-1),8,-1),9,-1)} -> 레버쿠젠 | AA24: 9 | AB24: 9 | AC24: 1 | AD24: 4 | AE24: 34 | AF24: 27 | AG24: 7 | AH24: 28
A25: TRUE, | B25: 1부리그 | C25: 바이에른 뮌헨 | D25: 3 | E25: 0 | F25: 도르트문트 | G25: 3 | H25: 1 | I25: 0 | J25: 0 | K25: 1 | L25: 0 | M25: 0 | N25: 3 | Z25: 아틀레티코 마드리드 | AA25: 7 | AB25: 8 | AC25: 0 | AD25: 4 | AE25: 37 | AF25: 22 | AG25: 15 | AH25: 24
A26: TRUE, | B26: 1부리그 | C26: 비야레알 | D26: 3 | E26: 1 | F26: 인테르 | G26: 3 | H26: 1 | I26: 0 | J26: 0 | K26: 1 | L26: 0 | M26: 0 | N26: 2 | Z26: 첼시 | AA26: 7 | AB26: 5 | AC26: 1 | AD26: 6 | AE26: 35 | AF26: 31 | AG26: 4 | AH26: 16
A27: TRUE, | B27: 1부리그 | C27: 비야레알 | D27: 3 | E27: 3 | F27: 인테르 | G27: 1 | H27: 0 | I27: 1 | J27: 0 | K27: 0 | L27: 1 | M27: 0 | N27: 0 | Z27: 토트넘 | AA27: 5 | AB27: 4 | AC27: 1 | AD27: 8 | AE27: 23 | AF27: 42 | AG27: -19 | AH27: 13
A28: TRUE, | B28: 1부리그 | C28: 비야레알 | D28: 3 | E28: 2 | F28: 도르트문트 | G28: 3 | H28: 1 | I28: 0 | J28: 0 | K28: 1 | L28: 0 | M28: 0 | N28: 1 | Z28: PSV | AA28: 2 | AB28: 2 | AC28: 1 | AD28: 2 | AE28: 18 | AF28: 18 | AG28: 0 | AH28: 7
A29: TRUE, | B29: 1부리그 | C29: 비야레알 | D29: 3 | E29: 4 | F29: 도르트문트 | G29: 0 | H29: 0 | I29: 0 | J29: 1 | K29: 0 | L29: 0 | M29: 1 | N29: -1 | Z29: 유벤투스 | AA29: 4 | AB29: 1 | AC29: 2 | AD29: 4 | AE29: 8 | AF29: 19 | AG29: -11 | AH29: 5
A30: TRUE, | B30: 1부리그 | C30: 비야레알 | D30: 2 | E30: 2 | F30: 맨체스터 유나이티드 | G30: 1 | H30: 0 | I30: 1 | J30: 0 | K30: 0 | L30: 1 | M30: 0 | N30: 0 | Z30: 아우크스부르크 | AA30: 8 | AB30: 0 | AC30: 2 | AD30: 13 | AE30: 17 | AF30: 53 | AG30: -36 | AH30: 2
A31: TRUE, | B31: 1부리그 | C31: 비야레알 | D31: 1 | E31: 1 | F31: 맨체스터 유나이티드 | G31: 1 | H31: 0 | I31: 1 | J31: 0 | K31: 0 | L31: 1 | M31: 0 | N31: 0
A32: TRUE, | B32: 2부리그 | C32: 아틀레티코 마드리드 | D32: 5 | E32: 2 | F32: 토트넘 | G32: 3 | H32: 1 | I32: 0 | J32: 0 | K32: 1 | L32: 0 | M32: 0 | N32: 3
A33: TRUE, | B33: 2부리그 | C33: 토트넘 | D33: 1 | E33: 5 | F33: 아틀레티코 마드리드 | G33: 0 | H33: 0 | I33: 0 | J33: 1 | K33: 0 | L33: 0 | M33: 1 | N33: -4
A34: TRUE, | B34: 2부리그 | C34: 아우크스부르크 | D34: 1 | E34: 3 | F34: 레버쿠젠 | G34: 0 | H34: 0 | I34: 0 | J34: 1 | K34: 0 | L34: 0 | M34: 1 | N34: -2
A35: TRUE, | B35: 2부리그 | C35: 토트넘 | D35: 3 | E35: 2 | F35: 아우크스부르크 | G35: 3 | H35: 1 | I35: 0 | J35: 0 | K35: 1 | L35: 0 | M35: 0 | N35: 1
A36: TRUE, | B36: 2부리그 | C36: PSV | D36: 4 | E36: 3 | F36: 첼시 | G36: 3 | H36: 1 | I36: 0 | J36: 0 | K36: 1 | L36: 0 | M36: 0 | N36: 1
A37: TRUE, | B37: 2부리그 | C37: PSV | D37: 5 | E37: 3 | F37: 첼시 | G37: 3 | H37: 1 | I37: 0 | J37: 0 | K37: 1 | L37: 0 | M37: 0 | N37: 2
A38: TRUE, | B38: 2부리그 | C38: 아틀레티코 마드리드 | D38: 2 | E38: 0 | F38: 아우크스부르크 | G38: 3 | H38: 1 | I38: 0 | J38: 0 | K38: 1 | L38: 0 | M38: 0 | N38: 2
A39: TRUE, | B39: 2부리그 | C39: 아틀레티코 마드리드 | D39: 3 | E39: 1 | F39: 아우크스부르크 | G39: 3 | H39: 1 | I39: 0 | J39: 0 | K39: 1 | L39: 0 | M39: 0 | N39: 2
A40: TRUE, | B40: 2부리그 | C40: 레버쿠젠 | D40: 3 | E40: 0 | F40: 유벤투스 | G40: 3 | H40: 1 | I40: 0 | J40: 0 | K40: 1 | L40: 0 | M40: 0 | N40: 3
...

Sheet 득점왕DB
A1: 대회종류 | B1: 선수 | C1: 팀약자 | D1: 득점
A2: UCL | B2: 세루 기라시 | C2: BVB | D2: 6
A3: 2부리그 | B3: 차범근 | C3: LEV | D3: 6
A4: 2부리그 | B4: 모라타 | C4: ATM | D4: 6
A5: 1부리그 | B5: 사뮈엘 에토 | C5: INT | D5: 5
A6: UCL | B6: 웨인 루니 | C6: MUN | D6: 5 | I6: {=_xlfn.TAKE(_xlfn._xlws.SORT(_xlfn.CHOOSECOLS(_xlfn._xlws.FILTER(득점데이터[], 득점데이터[대회종류]="2부리그"), 3, 2, 4), 3, -1), 10)} -> LEV | J6: 차범근 | K6: 6
A7: 1부리그 | B7: P.오바메양 | C7: BVB | D7: 4 | I7: ATM | J7: 모라타 | K7: 6
A8: UCL | B8: 마르셀 자비처 | C8: BVB | D8: 2 | I8: TOT | J8: 손흥민 | K8: 2
A9: UCL | B9: 카를로스 테베스 | C9: MUN | D9: 2 | I9: LEV | J9: 플로리안 비르츠 | K9: 2
A10: UCL | B10: 조지 베스트 | C10: MUN | D10: 2 | I10: ATM | J10: 앙투안 그리즈만 | K10: 2
A11: UCL | B11: 로빈 반페르시 | C11: MUN | D11: 2 | I11: AUG | J11: 필리프 티츠 | K11: 1
A12: UCL | B12: 지동원 | C12: AUG | D12: 2 | I12: ATM | J12: 차을라르 쇠윈쥐 | K12: 1
A13: UCL | B13: 율리안 브란트 | C13: BVB | D13: 2 | I13: ATM | J13: 마르코스 요렌테 | K13: 1
A14: 2부리그 | B14: 손흥민 | C14: TOT | D14: 2 | I14: TOT | J14: 해리 케인 | K14: 1
A15: 1부리그 | B15: 로타어 마테우스 | C15: INT | D15: 2 | I15: LEV | J15: 율리안 브란트 | K15: 1
A16: 2부리그 | B16: 플로리안 비르츠 | C16: LEV | D16: 2
A17: 1부리그 | B17: 웨인 루니 | C17: MUN | D17: 2
A18: 2부리그 | B18: 앙투안 그리즈만 | C18: ATM | D18: 2
A19: UCL | B19: 베론 | C19: CHE | D19: 1
A20: UCL | B20: 해리 케인 | C20: TOT | D20: 1
A21: UCL | B21: 플로리안 비르츠 | C21: LEV | D21: 1
A22: UCL | B22: 사뮈엘 에토 | C22: CHE | D22: 1
A23: UCL | B23: M.카이세도 | C23: CHE | D23: 1
A24: UCL | B24: P.오바메양 | C24: BVB | D24: 1
A25: UCL | B25: 헨릭 라르손 | C25: MUN | D25: 1
A26: UCL | B26: 프랭크 램파드 | C26: CHE | D26: 1
A27: UCL | B27: 디디에 드로그바 | C27: CHE | D27: 1
... A51: UCL | B51: 모하메드 쿠두스 | C51: TOT | D51: 1

Sheet LOGO_DB
A1: 열1 | B1: 파일ID | C1: 함수용주소를 DIRECT주소로 변경 | D1: 팀약자 | E1: 팀명 | F1: 시즌
A2: https://drive.google.com/file/d/1M9fxr8vIra3-wxudAp0eIxc_vbVavLTI/view?usp=sharing | B2: =MID(시즌이미지12[[#This Row],[열1]],33,33) -> 1M9fxr8vIra3-wxudAp0eIxc_vbVavLTI | C2: ="https://lh3.googleusercontent.com/d/" & 시즌이미지12[[#This Row],[파일ID]] -> https://lh3.googleusercontent.com/d/1M9fxr8vIra3-wxudAp0eIxc_vbVavLTI | D2: INT | E2: 인테르 | F2: =_xlfn.IMAGE(시즌이미지12[[#This Row],[함수용주소를 DIRECT주소로 변경]],시즌이미지12[[#This Row],[팀약자]],3,30,30) -> #VALUE!
A3: https://drive.google.com/file/d/1Oe0BhCDjicyhK-IVGrtw6-ZPssH0P_fL/view?usp=drive_link | B3: =MID(시즌이미지12[[#This Row],[열1]],33,33) -> 1Oe0BhCDjicyhK-IVGrtw6-ZPssH0P_fL | C3: ="https://lh3.googleusercontent.com/d/" & 시즌이미지12[[#This Row],[파일ID]] -> https://lh3.googleusercontent.com/d/1Oe0BhCDjicyhK-IVGrtw6-ZPssH0P_fL | D3: MUN | E3: 맨체스터 유나이티드 | F3: =_xlfn.IMAGE(시즌이미지12[[#This Row],[함수용주소를 DIRECT주소로 변경]],시즌이미지12[[#This Row],[팀약자]],3,30,30) -> #VALUE! | Q3: 1 | R3: =Q3*37.8 -> 37.8
A4: https://drive.google.com/file/d/1ge87Wvv_Pnf5ZYWaeXGWOYysw8FtjQ7u/view?usp=drive_link | B4: =MID(시즌이미지12[[#This Row],[열1]],33,33) -> 1ge87Wvv_Pnf5ZYWaeXGWOYysw8FtjQ7u | C4: ="https://lh3.googleusercontent.com/d/" & 시즌이미지12[[#This Row],[파일ID]] -> https://lh3.googleusercontent.com/d/1ge87Wvv_Pnf5ZYWaeXGWOYysw8FtjQ7u | D4: VIL | E4: 비야레알 CF | F4: =_xlfn.IMAGE(시즌이미지12[[#This Row],[함수용주소를 DIRECT주소로 변경]],시즌이미지12[[#This Row],[팀약자]],3,30,30) -> #VALUE! | P4: 높이(세로) | Q4: 0.89 | R4: =Q4*37.8 -> 33.642
A5: https://drive.google.com/file/d/1HwPb8ze_CzGsa3OAt7rTCJvx3M1XEcXy/view?usp=drive_link | B5: =MID(시즌이미지12[[#This Row],[열1]],33,33) -> 1HwPb8ze_CzGsa3OAt7rTCJvx3M1XEcXy | C5: ="https://lh3.googleusercontent.com/d/" & 시즌이미지12[[#This Row],[파일ID]] -> https://lh3.googleusercontent.com/d/1HwPb8ze_CzGsa3OAt7rTCJvx3M1XEcXy | D5: BVB | E5: 도르트문트 | F5: =_xlfn.IMAGE(시즌이미지12[[#This Row],[함수용주소를 DIRECT주소로 변경]],시즌이미지12[[#This Row],[팀약자]],3,30,30) -> #VALUE! | P5: 넓이(가로) | Q5: 1.11 | R5: =Q5*37.8 -> 41.958
A6: https://drive.google.com/file/d/1519utytmvRS4xl2zaPa2g8Q1QmuqB8-6/view?usp=drive_link | B6: =MID(시즌이미지12[[#This Row],[열1]],33,33) -> 1519utytmvRS4xl2zaPa2g8Q1QmuqB8-6 | C6: ="https://lh3.googleusercontent.com/d/" & 시즌이미지12[[#This Row],[파일ID]] -> https://lh3.googleusercontent.com/d/1519utytmvRS4xl2zaPa2g8Q1QmuqB8-6 | D6: FCB | E6: 바이에른 뮌헨 | F6: =_xlfn.IMAGE(시즌이미지12[[#This Row],[함수용주소를 DIRECT주소로 변경]],시즌이미지12[[#This Row],[팀약자]],3,30,30) -> #VALUE!
A7: https://drive.google.com/file/d/1iFd6qnPGwIhKzVqy65GosRyat5ly6Sh7/view?usp=drive_link | B7: =MID(시즌이미지12[[#This Row],[열1]],33,33) -> 1iFd6qnPGwIhKzVqy65GosRyat5ly6Sh7 | C7: ="https://lh3.googleusercontent.com/d/" & 시즌이미지12[[#This Row],[파일ID]] -> https://lh3.googleusercontent.com/d/1iFd6qnPGwIhKzVqy65GosRyat5ly6Sh7 | D7: NEW | E7: 뉴캐슬 | F7: =_xlfn.IMAGE(시즌이미지12[[#This Row],[함수용주소를 DIRECT주소로 변경]],시즌이미지12[[#This Row],[팀약자]],3,30,30) -> #VALUE! | P7: 높이(세로) | Q7: 0.81 | R7: =Q7*37.8 -> 30.618
A8: https://drive.google.com/file/d/1L7R-AGwnnP2FAQTYR8p5FhP8Q2LEuOii/view?usp=drive_link | B8: =MID(시즌이미지12[[#This Row],[열1]],33,33) -> 1L7R-AGwnnP2FAQTYR8p5FhP8Q2LEuOii | C8: ="https://lh3.googleusercontent.com/d/" & 시즌이미지12[[#This Row],[파일ID]] -> https://lh3.googleusercontent.com/d/1L7R-AGwnnP2FAQTYR8p5FhP8Q2LEuOii | D8: JUV | E8: 유벤투스 | F8: =_xlfn.IMAGE(시즌이미지12[[#This Row],[함수용주소를 DIRECT주소로 변경]],시즌이미지12[[#This Row],[팀약자]],3,30,30) -> #VALUE! | P8: 넓이(가로) | Q8: 1.31 | R8: =Q8*37.8 -> 49.518
A9: https://drive.google.com/file/d/11c6WyuJLUdxz7mxUlQhrs7DgvFSWT0qP/view?usp=drive_link | B9: =MID(시즌이미지12[[#This Row],[열1]],33,33) -> 11c6WyuJLUdxz7mxUlQhrs7DgvFSWT0qP | C9: ="https://lh3.googleusercontent.com/d/" & 시즌이미지12[[#This Row],[파일ID]] -> https://lh3.googleusercontent.com/d/11c6WyuJLUdxz7mxUlQhrs7DgvFSWT0qP | D9: ATM | E9: 아틀레티코 마드리드 | F9: =_xlfn.IMAGE(시즌이미지12[[#This Row],[함수용주소를 DIRECT주소로 변경]],시즌이미지12[[#This Row],[팀약자]],3,30,30) -> #VALUE!
A10: https://drive.google.com/file/d/1SKe5OyMGBddKNxXQwIfpEz-m5Sugr9Wf/view?usp=drive_link | B10: =MID(시즌이미지12[[#This Row],[열1]],33,33) -> 1SKe5OyMGBddKNxXQwIfpEz-m5Sugr9Wf | C10: ="https://lh3.googleusercontent.com/d/" & 시즌이미지12[[#This Row],[파일ID]] -> https://lh3.googleusercontent.com/d/1SKe5OyMGBddKNxXQwIfpEz-m5Sugr9Wf | D10: FRA | E10: 프랑크푸르트 | F10: =_xlfn.IMAGE(시즌이미지12[[#This Row],[함수용주소를 DIRECT주소로 변경]],시즌이미지12[[#This Row],[팀약자]],3,30,30) -> #VALUE!
A11: https://drive.google.com/file/d/16Igzwna8V9A1zCIj2LH_SVzn_zyXUNou/view?usp=drive_link | B11: =MID(시즌이미지12[[#This Row],[열1]],33,33) -> 16Igzwna8V9A1zCIj2LH_SVzn_zyXUNou | C11: ="https://lh3.googleusercontent.com/d/" & 시즌이미지12[[#This Row],[파일ID]] -> https://lh3.googleusercontent.com/d/16Igzwna8V9A1zCIj2LH_SVzn_zyXUNou | D11: RMA | E11: 레알 마드리드 | F11: =_xlfn.IMAGE(시즌이미지12[[#This Row],[함수용주소를 DIRECT주소로 변경]],시즌이미지12[[#This Row],[팀약자]],3,30,30) -> #VALUE!
A12: https://drive.google.com/file/d/1-xM88c12LfhN6A_Kx3bVzMUA12_zaPIB/view?usp=drive_link | B12: =MID(시즌이미지12[[#This Row],[열1]],33,33) -> 1-xM88c12LfhN6A_Kx3bVzMUA12_zaPIB | C12: ="https://lh3.googleusercontent.com/d/" & 시즌이미지12[[#This Row],[파일ID]] -> https://lh3.googleusercontent.com/d/1-xM88c12LfhN6A_Kx3bVzMUA12_zaPIB | D12: LEV | E12: 레버쿠젠 | F12: =_xlfn.IMAGE(시즌이미지12[[#This Row],[함수용주소를 DIRECT주소로 변경]],시즌이미지12[[#This Row],[팀약자]],3,30,30) -> #VALUE!
A13: https://drive.google.com/file/d/1IUr8XVjhXjb8iRVpKQP5gbsU2h9bWVo-/view?usp=drive_link | B13: =MID(시즌이미지12[[#This Row],[열1]],33,33) -> 1IUr8XVjhXjb8iRVpKQP5gbsU2h9bWVo- | C13: ="https://lh3.googleusercontent.com/d/" & 시즌이미지12[[#This Row],[파일ID]] -> https://lh3.googleusercontent.com/d/1IUr8XVjhXjb8iRVpKQP5gbsU2h9bWVo- | D13: MAI | E13: 마인츠 | F13: =_xlfn.IMAGE(시즌이미지12[[#This Row],[함수용주소를 DIRECT주소로 변경]],시즌이미지12[[#This Row],[팀약자]],3,30,30) -> #VALUE!
A14: https://drive.google.com/file/d/1U2lyqdhQ8teY7GxDVjB4UxcoP8PlKZyL/view?usp=drive_link | B14: =MID(시즌이미지12[[#This Row],[열1]],33,33) -> 1U2lyqdhQ8teY7GxDVjB4UxcoP8PlKZyL | C14: ="https://lh3.googleusercontent.com/d/" & 시즌이미지12[[#This Row],[파일ID]] -> https://lh3.googleusercontent.com/d/1U2lyqdhQ8teY7GxDVjB4UxcoP8PlKZyL | D14: PSG | E14: 파리 생제르망 | F14: =_xlfn.IMAGE(시즌이미지12[[#This Row],[함수용주소를 DIRECT주소로 변경]],시즌이미지12[[#This Row],[팀약자]],3,30,30) -> #VALUE! | K14: 맨체스터 시티
A15: https://drive.google.com/file/d/1U2lyqdhQ8teY7GxDVjB4UxcoP8PlKZyL/view?usp=sharing | B15: =MID(시즌이미지12[[#This Row],[열1]],33,33) -> 1U2lyqdhQ8teY7GxDVjB4UxcoP8PlKZyL | C15: ="https://lh3.googleusercontent.com/d/" & 시즌이미지12[[#This Row],[파일ID]] -> https://lh3.googleusercontent.com/d/1U2lyqdhQ8teY7GxDVjB4UxcoP8PlKZyL | D15: PSV | E15: PSV | F15: =_xlfn.IMAGE(시즌이미지12[[#This Row],[함수용주소를 DIRECT주소로 변경]],시즌이미지12[[#This Row],[팀약자]],3,30,30) -> #VALUE! | K15: 빌바오
A16: https://drive.google.com/file/d/15Jk32I9lJNP8cC4KdRw58yytaI76oZE8/view?usp=sharing | B16: =MID(시즌이미지12[[#This Row],[열1]],33,33) -> 15Jk32I9lJNP8cC4KdRw58yytaI76oZE8 | C16: ="https://lh3.googleusercontent.com/d/" & 시즌이미지12[[#This Row],[파일ID]] -> https://lh3.googleusercontent.com/d/15Jk32I9lJNP8cC4KdRw58yytaI76oZE8 | D16: CHE | E16: 첼시 | F16: =_xlfn.IMAGE(시즌이미지12[[#This Row],[함수용주소를 DIRECT주소로 변경]],시즌이미지12[[#This Row],[팀약자]],3,30,30) -> #VALUE! | K16: 아탈란타
A17: https://drive.google.com/file/d/1bi38oQzJZmM_zgV9xrx2IhY2jEEggOfr/view?usp=sharing | B17: =MID(시즌이미지12[[#This Row],[열1]],33,33) -> 1bi38oQzJZmM_zgV9xrx2IhY2jEEggOfr | C17: ="https://lh3.googleusercontent.com/d/" & 시즌이미지12[[#This Row],[파일ID]] -> https://lh3.googleusercontent.com/d/1bi38oQzJZmM_zgV9xrx2IhY2jEEggOfr | D17: NAP | E17: 나폴리 | F17: =_xlfn.IMAGE(시즌이미지12[[#This Row],[함수용주소를 DIRECT주소로 변경]],시즌이미지12[[#This Row],[팀약자]],3,30,30) -> #VALUE! | K17: 에버튼
A18: https://drive.google.com/file/d/1AhfPLy_ylqn97PSBCvL9iCvaX24fE7-9/view?usp=sharing | B18: =MID(시즌이미지12[[#This Row],[열1]],33,33) -> 1AhfPLy_ylqn97PSBCvL9iCvaX24fE7-9 | C18: ="https://lh3.googleusercontent.com/d/" & 시즌이미지12[[#This Row],[파일ID]] -> https://lh3.googleusercontent.com/d/1AhfPLy_ylqn97PSBCvL9iCvaX24fE7-9 | D18: WOB | E18: 볼프스부르크 | F18: =_xlfn.IMAGE(시즌이미지12[[#This Row],[함수용주소를 DIRECT주소로 변경]],시즌이미지12[[#This Row],[팀약자]],3,30,30) -> #VALUE! | K18: 호펜하임
A19: https://drive.google.com/file/d/1p7TESxzO9TenjDKWF0FyntQCIjhlXDqq/view?usp=drive_link | B19: =MID(시즌이미지12[[#This Row],[열1]],33,33) -> 1p7TESxzO9TenjDKWF0FyntQCIjhlXDqq | C19: ="https://lh3.googleusercontent.com/d/" & 시즌이미지12[[#This Row],[파일ID]] -> https://lh3.googleusercontent.com/d/1p7TESxzO9TenjDKWF0FyntQCIjhlXDqq | D19: TOT | E19: 토트넘 | F19: =_xlfn.IMAGE(시즌이미지12[[#This Row],[함수용주소를 DIRECT주소로 변경]],시즌이미지12[[#This Row],[팀약자]],3,30,30) -> #VALUE! | K19: AS로마
A20: https://drive.google.com/file/d/1l0Z5EmFT0dhYHqxr4i7onuYaYidbPYQ5/view?usp=sharing | B20: =MID(시즌이미지12[[#This Row],[열1]],33,33) -> 1l0Z5EmFT0dhYHqxr4i7onuYaYidbPYQ5 | C20: ="https://lh3.googleusercontent.com/d/" & 시즌이미지12[[#This Row],[파일ID]] -> https://lh3.googleusercontent.com/d/1l0Z5EmFT0dhYHqxr4i7onuYaYidbPYQ5 | D20: MCI | E20: 맨체스터 시티 | F20: =_xlfn.IMAGE(시즌이미지12[[#This Row],[함수용주소를 DIRECT주소로 변경]],시즌이미지12[[#This Row],[팀약자]],3,30,30) -> #VALUE!
A21: https://drive.google.com/file/d/10nTzFsuuqP45hsk7Ru7EbXAGkwx1dWYV/view?usp=sharing | B21: =MID(시즌이미지12[[#This Row],[열1]],33,33) -> 10nTzFsuuqP45hsk7Ru7EbXAGkwx1dWYV | C21: ="https://lh3.googleusercontent.com/d/" & 시즌이미지12[[#This Row],[파일ID]] -> https://lh3.googleusercontent.com/d/10nTzFsuuqP45hsk7Ru7EbXAGkwx1dWYV | D21: ATH | E21: 빌바오 | F21: =_xlfn.IMAGE(시즌이미지12[[#This Row],[함수용주소를 DIRECT주소로 변경]],시즌이미지12[[#This Row],[팀약자]],3,30,30) -> #VALUE!
A22: https://drive.google.com/file/d/1jaLYu2wYSxHrioIdJfhNpJhC3NHxooDD/view?usp=sharing | B22: =MID(시즌이미지12[[#This Row],[열1]],33,33) -> 1jaLYu2wYSxHrioIdJfhNpJhC3NHxooDD | C22: ="https://lh3.googleusercontent.com/d/" & 시즌이미지12[[#This Row],[파일ID]] -> https://lh3.googleusercontent.com/d/1jaLYu2wYSxHrioIdJfhNpJhC3NHxooDD | D22: ATA | E22: 아탈란타 | F22: =_xlfn.IMAGE(시즌이미지12[[#This Row],[함수용주소를 DIRECT주소로 변경]],시즌이미지12[[#This Row],[팀약자]],3,30,30) -> #VALUE!
A23: https://drive.google.com/file/d/1SEQ-3xjDpyLjOCq14OvHaqkkehIcEIXQ/view?usp=sharing | B23: =MID(시즌이미지12[[#This Row],[열1]],33,33) -> 1SEQ-3xjDpyLjOCq14OvHaqkkehIcEIXQ | C23: ="https://lh3.googleusercontent.com/d/" & 시즌이미지12[[#This Row],[파일ID]] -> https://lh3.googleusercontent.com/d/1SEQ-3xjDpyLjOCq14OvHaqkkehIcEIXQ | D23: EVE | E23: 에버튼 | F23: =_xlfn.IMAGE(시즌이미지12[[#This Row],[함수용주소를 DIRECT주소로 변경]],시즌이미지12[[#This Row],[팀약자]],3,30,30) -> #VALUE!
A24: https://drive.google.com/file/d/1bvJGNIpwFr3OMgDX_ofijNsyhqsSff9T/view?usp=sharing | B24: =MID(시즌이미지12[[#This Row],[열1]],33,33) -> 1bvJGNIpwFr3OMgDX_ofijNsyhqsSff9T | C24: ="https://lh3.googleusercontent.com/d/" & 시즌이미지12[[#This Row],[파일ID]] -> https://lh3.googleusercontent.com/d/1bvJGNIpwFr3OMgDX_ofijNsyhqsSff9T | D24: TSG | E24: 호펜하임 | F24: =_xlfn.IMAGE(시즌이미지12[[#This Row],[함수용주소를 DIRECT주소로 변경]],시즌이미지12[[#This Row],[팀약자]],3,30,30) -> #VALUE!
A25: https://drive.google.com/file/d/1wrCMhbnPK2EPBliqfhhsRcXBGpSnyqE7/view?usp=sharing | B25: =MID(시즌이미지12[[#This Row],[열1]],33,33) -> 1wrCMhbnPK2EPBliqfhhsRcXBGpSnyqE7 | C25: ="https://lh3.googleusercontent.com/d/" & 시즌이미지12[[#This Row],[파일ID]] -> https://lh3.googleusercontent.com/d/1wrCMhbnPK2EPBliqfhhsRcXBGpSnyqE7 | D25: ROM | E25: AS로마 | F25: =_xlfn.IMAGE(시즌이미지12[[#This Row],[함수용주소를 DIRECT주소로 변경]],시즌이미지12[[#This Row],[팀약자]],3,30,30) -> #VALUE!
B26: =MID(시즌이미지12[[#This Row],[열1]],33,33) | C26: ="https://lh3.googleusercontent.com/d/" & 시즌이미지12[[#This Row],[파일ID]] -> https://lh3.googleusercontent.com/d/ | F26: =_xlfn.IMAGE(시즌이미지12[[#This Row],[함수용주소를 DIRECT주소로 변경]],시즌이미지12[[#This Row],[팀약자]],3,30,30) -> #VALUE!
B27: =MID(시즌이미지12[[#This Row],[열1]],33,33) | C27: ="https://lh3.googleusercontent.com/d/" & 시즌이미지12[[#This Row],[파일ID]] -> https://lh3.googleusercontent.com/d/ | F27: =_xlfn.IMAGE(시즌이미지12[[#This Row],[함수용주소를 DIRECT주소로 변경]],시즌이미지12[[#This Row],[팀약자]],3,30,30) -> #VALUE!
B28: =MID(시즌이미지12[[#This Row],[열1]],33,33) | C28: ="https://lh3.googleusercontent.com/d/" & 시즌이미지12[[#This Row],[파일ID]] -> https://lh3.googleusercontent.com/d/ | F28: =_xlfn.IMAGE(시즌이미지12[[#This Row],[함수용주소를 DIRECT주소로 변경]],시즌이미지12[[#This Row],[팀약자]],3,30,30) -> #VALUE!
B29: =MID(시즌이미지12[[#This Row],[열1]],33,33) | C29: ="https://lh3.googleusercontent.com/d/" & 시즌이미지12[[#This Row],[파일ID]] -> https://lh3.googleusercontent.com/d/ | F29: =_xlfn.IMAGE(시즌이미지12[[#This Row],[함수용주소를 DIRECT주소로 변경]],시즌이미지12[[#This Row],[팀약자]],3,30,30) -> #VALUE!
B30: =MID(시즌이미지12[[#This Row],[열1]],33,33) | C30: ="https://lh3.googleusercontent.com/d/" & 시즌이미지12[[#This Row],[파일ID]] -> https://lh3.googleusercontent.com/d/ | F30: =_xlfn.IMAGE(시즌이미지12[[#This Row],[함수용주소를 DIRECT주소로 변경]],시즌이미지12[[#This Row],[팀약자]],3,30,30) -> #VALUE!
B31: =MID(시즌이미지12[[#This Row],[열1]],33,33) | C31: ="https://lh3.googleusercontent.com/d/" & 시즌이미지12[[#This Row],[파일ID]] -> https://lh3.googleusercontent.com/d/ | F31: =_xlfn.IMAGE(시즌이미지12[[#This Row],[함수용주소를 DIRECT주소로 변경]],시즌이미지12[[#This Row],[팀약자]],3,30,30) -> #VALUE!
B32: =MID(시즌이미지12[[#This Row],[열1]],33,33) | C32: ="https://lh3.googleusercontent.com/d/" & 시즌이미지12[[#This Row],[파일ID]] -> https://lh3.googleusercontent.com/d/ | F32: =_xlfn.IMAGE(시즌이미지12[[#This Row],[함수용주소를 DIRECT주소로 변경]],시즌이미지12[[#This Row],[팀약자]],3,30,30) -> #VALUE!
B33: =MID(시즌이미지12[[#This Row],[열1]],33,33) | C33: ="https://lh3.googleusercontent.com/d/" & 시즌이미지12[[#This Row],[파일ID]] -> https://lh3.googleusercontent.com/d/ | F33: =_xlfn.IMAGE(시즌이미지12[[#This Row],[함수용주소를 DIRECT주소로 변경]],시즌이미지12[[#This Row],[팀약자]],3,30,30) -> #VALUE!
B34: =MID(시즌이미지12[[#This Row],[열1]],33,33) | C34: ="https://lh3.googleusercontent.com/d/" & 시즌이미지12[[#This Row],[파일ID]] -> https://lh3.googleusercontent.com/d/ | F34: =_xlfn.IMAGE(시즌이미지12[[#This Row],[함수용주소를 DIRECT주소로 변경]],시즌이미지12[[#This Row],[팀약자]],3,30,30) -> #VALUE!
B35: =MID(시즌이미지12[[#This Row],[열1]],33,33) | C35: ="https://lh3.googleusercontent.com/d/" & 시즌이미지12[[#This Row],[파일ID]] -> https://lh3.googleusercontent.com/d/ | F35: =_xlfn.IMAGE(시즌이미지12[[#This Row],[함수용주소를 DIRECT주소로 변경]],시즌이미지12[[#This Row],[팀약자]],3,30,30) -> #VALUE!
B36: =MID(시즌이미지12[[#This Row],[열1]],33,33) | C36: ="https://lh3.googleusercontent.com/d/" & 시즌이미지12[[#This Row],[파일ID]] -> https://lh3.googleusercontent.com/d/ | F36: =_xlfn.IMAGE(시즌이미지12[[#This Row],[함수용주소를 DIRECT주소로 변경]],시즌이미지12[[#This Row],[팀약자]],3,30,30) -> #VALUE!
B37: =MID(시즌이미지12[[#This Row],[열1]],33,33) | C37: ="https://lh3.googleusercontent.com/d/" & 시즌이미지12[[#This Row],[파일ID]] -> https://lh3.googleusercontent.com/d/ | F37: =_xlfn.IMAGE(시즌이미지12[[#This Row],[함수용주소를 DIRECT주소로 변경]],시즌이미지12[[#This Row],[팀약자]],3,30,30) -> #VALUE!
... B97: =MID(시즌이미지12[[#This Row],[열1]],33,33) | C97: ="https://lh3.googleusercontent.com/d/" & 시즌이미지12[[#This Row],[파일ID]] -> https://lh3.googleusercontent.com/d/ | F97: =_xlfn.IMAGE(시즌이미지12[[#This Row],[함수용주소를 DIRECT주소로 변경]],시즌이미지12[[#This Row],[팀약자]],3,30,30) -> #VALUE!

Sheet Sheet5
D2: MUN 웨인 루니
D3: MUN 마이클 오언
D4: MUN 로빈 반페르시
D5: MUN 조지 베스트
D6: MUN B.슈바인슈타이커
D7: MUN 마이클 캐릭
D8: MUN 루크 쇼
D9: MUN 리오 퍼디난드
D10: MUN 네마냐 비디치
D11: MUN 애슐리 영
D12: MUN 에드윈 반데르사르
D13: MUN 로이 킨
... D489: 도미닉 솔랑키 (OG)
