Workbook

Sheet 1부리그
D2: ALL-STAR LEAGUE - NATIONS 1ST
F4: LEAGUE TABLE | T4: TOP SCORERS
D5: POS | F5: TEAM | H5: P | I5: W | J5: D | K5: L | L5: G | M5: D | N5: GD | O5: PTS | S5: POS | U5: PLAYER | X5: GOAL
D6: 1 | F6: =IFERROR(VLOOKUP(G6,시즌이미지12[[팀명]:[사이즈30]],2,0),"") -> #VALUE! | G6: {=_xlfn._xlws.SORT(_xlfn.CHOOSECOLS(_xlfn._xlws.FILTER(리그순위표[], ISNUMBER(SEARCH("1부리그", 리그순위표[대회 종류]))), 2, 3, 4, 5, 6, 7, 8, 9, 10), {9,8}, {-1,-1})} -> 도르트문트 | H6: 10 | I6: 7 | J6: 0 | K6: 3 | L6: 31 | M6: 26 | N6: 5 | O6: 21 | S6: 1 | U6: =VLOOKUP(V6,LOGO_DB!$D:$F,3,0) -> #VALUE! | V6: {=_xlfn.TAKE(_xlfn._xlws.SORT(_xlfn.CHOOSECOLS(_xlfn._xlws.FILTER(득점데이터[], 득점데이터[대회종류]="1부리그"), 3, 2, 4), 3, -1), 10)} -> FCB | W6: 토마스 뮐러 | X6: 12
D7: 2 | F7: =IFERROR(VLOOKUP(G7,시즌이미지12[[팀명]:[사이즈30]],2,0),"") -> #VALUE! | G7: 바이에른 뮌헨 | H7: 10 | I7: 5 | J7: 1 | K7: 4 | L7: 29 | M7: 18 | N7: 11 | O7: 16 | S7: 2 | U7: =VLOOKUP(V7,LOGO_DB!$D:$F,3,0) -> #VALUE! | V7: INT | W7: 사뮈엘 에토 | X7: 10
D8: 3 | F8: =IFERROR(VLOOKUP(G8,시즌이미지12[[팀명]:[사이즈30]],2,0),"") -> #VALUE! | G8: 맨체스터 유나이티드 | H8: 10 | I8: 4 | J8: 3 | K8: 3 | L8: 22 | M8: 20 | N8: 2 | O8: 15 | S8: 3 | U8: =VLOOKUP(V8,LOGO_DB!$D:$F,3,0) -> #VALUE! | V8: FCB | W8: 해리 케인 | X8: 9
D9: 4 | F9: =IFERROR(VLOOKUP(G9,시즌이미지12[[팀명]:[사이즈30]],2,0),"") -> #VALUE! | G9: 인테르 | H9: 10 | I9: 3 | J9: 3 | K9: 4 | L9: 18 | M9: 20 | N9: -2 | O9: 12 | S9: 4 | U9: =VLOOKUP(V9,LOGO_DB!$D:$F,3,0) -> #VALUE! | V9: BVB | W9: P.오바메양 | X9: 9
D10: 5 | F10: =IFERROR(VLOOKUP(G10,시즌이미지12[[팀명]:[사이즈30]],2,0),"") -> #VALUE! | G10: 비야레알 | H10: 10 | I10: 3 | J10: 3 | K10: 4 | L10: 21 | M10: 27 | N10: -6 | O10: 12 | S10: 5 | U10: =VLOOKUP(V10,LOGO_DB!$D:$F,3,0) -> #VALUE! | V10: MUN | W10: 로빈 반페르시 | X10: 7
D11: 6 | F11: =IFERROR(VLOOKUP(G11,시즌이미지12[[팀명]:[사이즈30]],2,0),"") -> #VALUE! | G11: 뉴캐슬 유나이티드 | H11: 10 | I11: 3 | J11: 0 | K11: 7 | L11: 18 | M11: 28 | N11: -10 | O11: 9 | S11: 6 | U11: =VLOOKUP(V11,LOGO_DB!$D:$F,3,0) -> #VALUE! | V11: BVB | W11: 세루 기라시 | X11: 7
S12: 7 | U12: =VLOOKUP(V12,LOGO_DB!$D:$F,3,0) -> #VALUE! | V12: VIL | W12: 디에고 포를란 | X12: 7
S13: 8 | U13: =VLOOKUP(V13,LOGO_DB!$D:$F,3,0) -> #VALUE! | V13: VIL | W13: 티에르노 바리 | X13: 6
S14: 9 | U14: =VLOOKUP(V14,LOGO_DB!$D:$F,3,0) -> #VALUE! | V14: MUN | W14: 웨인 루니 | X14: 6
S15: 10 | U15: =VLOOKUP(V15,LOGO_DB!$D:$F,3,0) -> #VALUE! | V15: INT | W15: 로타어 마테우스 | X15: 5

Sheet 2부리그
D2: ALL-STAR LEAGUE - DIVISION 2
F4: LEAGUE TABLE | T4: TOP SCORERS
D5: POS | F5: TEAM | H5: P | I5: W | J5: D | K5: L | L5: G | M5: D | N5: GD | O5: PTS | S5: POS | U5: PLAYER | X5: GOAL
D6: 1 | F6: =VLOOKUP(G6,시즌이미지12[[팀명]:[사이즈30]],2,0) -> #VALUE! | G6: {=_xlfn._xlws.SORT(_xlfn.CHOOSECOLS(_xlfn._xlws.FILTER(리그순위표[], ISNUMBER(SEARCH("2부리그", 리그순위표[대회 종류]))), 2, 3, 4, 5, 6, 7, 8, 9, 10), {9,8}, {-1,-1})} -> 아틀레티코 마드리드 | H6: 14 | I6: 11 | J6: 0 | K6: 3 | L6: 43 | M6: 15 | N6: 28 | O6: 33 | S6: 1 | U6: =VLOOKUP(V6,LOGO_DB!$D:$F,3,0) -> #VALUE! | V6: {=_xlfn.TAKE(_xlfn._xlws.SORT(_xlfn.CHOOSECOLS(_xlfn._xlws.FILTER(득점데이터[], 득점데이터[대회종류]="2부리그"), 3, 2, 4), 3, -1), 10)} -> LEV | W6: 차범근 | X6: 18
D7: 2 | F7: =VLOOKUP(G7,시즌이미지12[[팀명]:[사이즈30]],2,0) -> #VALUE! | G7: 레버쿠젠 | H7: 14 | I7: 9 | J7: 3 | K7: 2 | L7: 39 | M7: 24 | N7: 15 | O7: 30 | S7: 2 | U7: =VLOOKUP(V7,LOGO_DB!$D:$F,3,0) -> #VALUE! | V7: RMA | W7: 크리스티아누 호날두 | X7: 15
D8: 3 | F8: =VLOOKUP(G8,시즌이미지12[[팀명]:[사이즈30]],2,0) -> #VALUE! | G8: 레알 마드리드 | H8: 14 | I8: 9 | J8: 1 | K8: 4 | L8: 35 | M8: 22 | N8: 13 | O8: 28 | S8: 3 | U8: =VLOOKUP(V8,LOGO_DB!$D:$F,3,0) -> #VALUE! | V8: ATM | W8: 모라타 | X8: 13
D9: 4 | F9: =VLOOKUP(G9,시즌이미지12[[팀명]:[사이즈30]],2,0) -> #VALUE! | G9: 첼시 | H9: 14 | I9: 6 | J9: 0 | K9: 8 | L9: 36 | M9: 33 | N9: 3 | O9: 18 | S9: 4 | U9: =VLOOKUP(V9,LOGO_DB!$D:$F,3,0) -> #VALUE! | V9: LEV | W9: 플로리안 비르츠 | X9: 13
D10: 5 | F10: =VLOOKUP(G10,시즌이미지12[[팀명]:[사이즈30]],2,0) -> #VALUE! | G10: PSV | H10: 10 | I10: 5 | J10: 2 | K10: 3 | L10: 31 | M10: 32 | N10: -1 | O10: 17 | S10: 5 | U10: =VLOOKUP(V10,LOGO_DB!$D:$F,3,0) -> #VALUE! | V10: ATM | W10: 앙헬 코레아 | X10: 12
D11: 6 | F11: =VLOOKUP(G11,시즌이미지12[[팀명]:[사이즈30]],2,0) -> #VALUE! | G11: 토트넘 | H11: 12 | I11: 4 | J11: 0 | K11: 8 | L11: 29 | M11: 37 | N11: -8 | O11: 12 | S11: 6 | U11: =VLOOKUP(V11,LOGO_DB!$D:$F,3,0) -> #VALUE! | V11: TOT | W11: 손흥민 | X11: 12
D12: 7 | F12: =VLOOKUP(G12,시즌이미지12[[팀명]:[사이즈30]],2,0) -> #VALUE! | G12: 유벤투스 | H12: 10 | I12: 2 | J12: 1 | K12: 7 | L12: 10 | M12: 29 | N12: -19 | O12: 7 | S12: 7 | U12: =VLOOKUP(V12,LOGO_DB!$D:$F,3,0) -> #VALUE! | V12: PSV | W12: 뤼트 반니스텔로이 | X12: 10
D13: 8 | F13: =VLOOKUP(G13,시즌이미지12[[팀명]:[사이즈30]],2,0) -> #VALUE! | G13: 아우크스부르크 | H13: 12 | I13: 0 | J13: 1 | K13: 11 | L13: 13 | M13: 44 | N13: -31 | O13: 1 | S13: 8 | U13: =VLOOKUP(V13,LOGO_DB!$D:$F,3,0) -> #VALUE! | V13: CHE | W13: 디디에 드로그바 | X13: 10
S14: 9 | U14: =VLOOKUP(V14,LOGO_DB!$D:$F,3,0) -> #VALUE! | V14: ATM | W14: 앙투안 그리즈만 | X14: 9
S15: 10 | U15: =VLOOKUP(V15,LOGO_DB!$D:$F,3,0) -> #VALUE! | V15: TOT | W15: 해리 케인 | X15: 8

Sheet UCL조별
U4: TOP SCORER
C5: All-Star CHAMPIONS LEAGUE
U6: POS | V6: PLAYER | Y6: 득점
U7: 1 | V7: =VLOOKUP(W7,LOGO_DB!$D:$F,3,0) -> #VALUE! | W7: {=_xlfn.TAKE(_xlfn._xlws.SORT(_xlfn.CHOOSECOLS(_xlfn._xlws.FILTER(득점데이터[], ISNUMBER(SEARCH("UCL", 득점데이터[대회종류]))), 3, 2, 4), 3, -1), 5)} -> BVB | X7: 세루 기라시 | Y7: 14
C8: [ GROUP STAGE ] | U8: 2 | V8: =VLOOKUP(W8,LOGO_DB!$D:$F,3,0) -> #VALUE! | W8: INT | X8: 사뮈엘 에토 | Y8: 12
U9: 3 | V9: =VLOOKUP(W9,LOGO_DB!$D:$F,3,0) -> #VALUE! | W9: ATM | X9: 모라타 | Y9: 9
U10: 4 | V10: =VLOOKUP(W10,LOGO_DB!$D:$F,3,0) -> #VALUE! | W10: ATM | X10: 앙헬 코레아 | Y10: 6
U11: 5 | V11: =VLOOKUP(W11,LOGO_DB!$D:$F,3,0) -> #VALUE! | W11: MUN | X11: 웨인 루니 | Y11: 6
B13: GROUP A | U13: GROUP B
AW14: UCL_A조
B16: POS | C16: TEAM | E16: P | F16: W | G16: D | H16: L | I16: G | J16: D | K16: GD | L16: PTS | U16: POS | W16: TEAM | Y16: P | Z16: W | AA16: D | AB16: L | AC16: G | AD16: D | AE16: GD | AF16: PTS | AW16: UCL_B조
B17: 1 | C17: =IFERROR(VLOOKUP(D17,시즌이미지12[[팀명]:[사이즈35]],3,0),"") -> #VALUE! | D17: {=_xlfn._xlws.SORT(_xlfn.CHOOSECOLS(_xlfn._xlws.FILTER(리그순위표[], ISNUMBER(SEARCH($AW$14, 리그순위표[대회 종류]))), 2, 3, 4, 5, 6, 7, 8, 9, 10), {9,8}, {-1,-1})} -> 레알 마드리드 | E17: 6 | F17: 3 | G17: 1 | H17: 2 | I17: 15 | J17: 13 | K17: 2 | L17: 10 | U17: 1 | V17: =IFERROR(VLOOKUP(X17,시즌이미지12[[팀명]:[사이즈35]],3,0),"") -> #VALUE! | X17: {=_xlfn._xlws.SORT(_xlfn.CHOOSECOLS(_xlfn._xlws.FILTER(리그순위표[], ISNUMBER(SEARCH($AW$16, 리그순위표[대회 종류]))), 2, 3, 4, 5, 6, 7, 8, 9, 10), {9,8}, {-1,-1})} -> 도르트문트 | Y17: 6 | Z17: 5 | AA17: 1 | AB17: 0 | AC17: 30 | AD17: 10 | AE17: 20 | AF17: 16 | AW17: UCL_C조
B18: 2 | C18: =IFERROR(VLOOKUP(D18,시즌이미지12[[팀명]:[사이즈35]],3,0),"") -> #VALUE! | D18: 아틀레티코 마드리드 | E18: 6 | F18: 3 | G18: 0 | H18: 3 | I18: 20 | J18: 16 | K18: 4 | L18: 9 | U18: 2 | V18: =IFERROR(VLOOKUP(X18,시즌이미지12[[팀명]:[사이즈35]],3,0),"") -> #VALUE! | X18: 맨체스터 유나이티드 | Y18: 6 | Z18: 3 | AA18: 1 | AB18: 2 | AC18: 19 | AD18: 13 | AE18: 6 | AF18: 10 | AW18: UCL_D조
B19: 3 | C19: =IFERROR(VLOOKUP(D19,시즌이미지12[[팀명]:[사이즈35]],3,0),"") -> #VALUE! | D19: 첼시 | E19: 6 | F19: 2 | G19: 2 | H19: 2 | I19: 17 | J19: 16 | K19: 1 | L19: 8 | U19: 3 | V19: =IFERROR(VLOOKUP(X19,시즌이미지12[[팀명]:[사이즈35]],3,0),"") -> #VALUE! | X19: 토트넘 | Y19: 6 | Z19: 2 | AA19: 1 | AB19: 3 | AC19: 10 | AD19: 19 | AE19: -9 | AF19: 7
B20: 4 | C20: =IFERROR(VLOOKUP(D20,시즌이미지12[[팀명]:[사이즈35]],3,0),"") -> #VALUE! | D20: 레버쿠젠 | E20: 6 | F20: 2 | G20: 1 | H20: 3 | I20: 9 | J20: 16 | K20: -7 | L20: 7 | U20: 4 | V20: =IFERROR(VLOOKUP(X20,시즌이미지12[[팀명]:[사이즈35]],3,0),"") -> #VALUE! | X20: 아우크스부르크 | Y20: 6 | Z20: 0 | AA20: 1 | AB20: 5 | AC20: 6 | AD20: 23 | AE20: -17 | AF20: 1
B23: GROUP C | U23: GROUP D
AW24: UCL_A조
B26: POS | C26: TEAM | E26: P | F26: W | G26: D | H26: L | I26: G | J26: D | K26: GD | L26: PTS | U26: POS | W26: TEAM | Y26: P | Z26: W | AA26: D | AB26: L | AC26: G | AD26: D | AE26: GD | AF26: PTS
B27: 1 | C27: =IFERROR(VLOOKUP(D27,시즌이미지12[[팀명]:[사이즈35]],3,0),"") -> #VALUE! | D27: {=_xlfn._xlws.SORT(_xlfn.CHOOSECOLS(_xlfn._xlws.FILTER(리그순위표[], ISNUMBER(SEARCH($AW$18, 리그순위표[대회 종류]))), 2, 3, 4, 5, 6, 7, 8, 9, 10), {9,8}, {-1,-1})} -> 비야레알 | E27: 4 | F27: 2 | G27: 2 | H27: 0 | I27: 9 | J27: 5 | K27: 4 | L27: 8 | U27: 1 | V27: =IFERROR(VLOOKUP(X27,시즌이미지12[[팀명]:[사이즈35]],3,0),"") -> #VALUE! | X27: {=_xlfn._xlws.SORT(_xlfn.CHOOSECOLS(_xlfn._xlws.FILTER(리그순위표[], ISNUMBER(SEARCH($AW$17, 리그순위표[대회 종류]))), 2, 3, 4, 5, 6, 7, 8, 9, 10), {9,8}, {-1,-1})} -> 인테르 | Y27: 4 | Z27: 4 | AA27: 0 | AB27: 0 | AC27: 15 | AD27: 7 | AE27: 8 | AF27: 12
B28: 2 | C28: =IFERROR(VLOOKUP(D28,시즌이미지12[[팀명]:[사이즈35]],3,0),"") -> #VALUE! | D28: 바이에른 뮌헨 | E28: 4 | F28: 1 | G28: 2 | H28: 1 | I28: 7 | J28: 6 | K28: 1 | L28: 5 | U28: 2 | V28: =IFERROR(VLOOKUP(X28,시즌이미지12[[팀명]:[사이즈35]],3,0),"") -> #VALUE! | X28: PSV | Y28: 4 | Z28: 0 | AA28: 2 | AB28: 2 | AC28: 12 | AD28: 15 | AE28: -3 | AF28: 2
B29: 3 | C29: =IFERROR(VLOOKUP(D29,시즌이미지12[[팀명]:[사이즈35]],3,0),"") -> #VALUE! | D29: 뉴캐슬 유나이티드 | E29: 4 | F29: 1 | G29: 0 | H29: 3 | I29: 7 | J29: 12 | K29: -5 | L29: 3 | U29: 3 | V29: =IFERROR(VLOOKUP(X29,시즌이미지12[[팀명]:[사이즈35]],3,0),"") -> #VALUE! | X29: 유벤투스 | Y29: 4 | Z29: 0 | AA29: 2 | AB29: 2 | AC29: 7 | AD29: 12 | AE29: -5 | AF29: 2
B30: 4 | C30: =IFERROR(VLOOKUP(D30,시즌이미지12[[팀명]:[사이즈35]],3,0),"") | U30: 4 | V30: =IFERROR(VLOOKUP(X30,시즌이미지12[[팀명]:[사이즈35]],3,0),"")

Sheet FA컵
D2: All-Star FA CUP Tournament
E5: =IF('FA컵 디자인'!B7="부전승","",VLOOKUP('FA컵 디자인'!B7,시즌이미지12[[팀명]:[사이즈125]],4,0)) -> #VALUE! | AL5: All-Star FA CUP | CF5: =IF('FA컵 디자인'!B15="부전승","",VLOOKUP('FA컵 디자인'!B15,시즌이미지12[[팀명]:[사이즈125]],4,0)) -> #VALUE!
K6: ='FA컵 디자인'!C7 | CB6: ='FA컵 디자인'!C15
N8: =IFERROR(VLOOKUP('FA컵 디자인'!D7,시즌이미지12[[팀명]:[사이즈125]],4,0),'FA컵 디자인'!D7) -> #VALUE! | AL8: WINNER | BW8: =IFERROR(VLOOKUP('FA컵 디자인'!D15,시즌이미지12[[팀명]:[사이즈125]],4,0),'FA컵 디자인'!D15) -> #VALUE!
T9: ='FA컵 디자인'!E7 -> 5 | BS9: ='FA컵 디자인'!E15 -> 7
E11: =IF('FA컵 디자인'!B8="부전승","",VLOOKUP('FA컵 디자인'!B8,시즌이미지12[[팀명]:[사이즈125]],4,0)) | CF11: =IF('FA컵 디자인'!B16="부전승","",VLOOKUP('FA컵 디자인'!B16,시즌이미지12[[팀명]:[사이즈125]],4,0))
K12: ='FA컵 디자인'!C8 | AN12: =IFERROR(VLOOKUP('FA컵 디자인'!J7,시즌이미지12[[팀명]:[사이즈125]],7,0),'FA컵 디자인'!J7) -> #VALUE! | CB12: ='FA컵 디자인'!C16
V13: =IFERROR(VLOOKUP('FA컵 디자인'!F7,시즌이미지12[[팀명]:[사이즈125]],5,0),'FA컵 디자인'!F7) -> #VALUE! | BM13: =IFERROR(VLOOKUP('FA컵 디자인'!F15,시즌이미지12[[팀명]:[사이즈125]],5,0),'FA컵 디자인'!F15) -> #VALUE!
AD15: ='FA컵 디자인'!G7 -> 0 | BI15: ='FA컵 디자인'!G15 -> 4
E17: =IF('FA컵 디자인'!B9="부전승","",VLOOKUP('FA컵 디자인'!B9,시즌이미지12[[팀명]:[사이즈125]],4,0)) -> #VALUE! | CF17: =IF('FA컵 디자인'!B17="부전승","",VLOOKUP('FA컵 디자인'!B17,시즌이미지12[[팀명]:[사이즈125]],4,0)) -> #VALUE!
K18: ='FA컵 디자인'!C9 -> 2 | CB18: ='FA컵 디자인'!C17 -> 0
N20: =IFERROR(VLOOKUP('FA컵 디자인'!D9,시즌이미지12[[팀명]:[사이즈125]],4,0),'FA컵 디자인'!D9) -> #VALUE! | BW20: =IFERROR(VLOOKUP('FA컵 디자인'!D17,시즌이미지12[[팀명]:[사이즈125]],4,0),'FA컵 디자인'!D17) -> #VALUE!
T21: ='FA컵 디자인'!E9 -> 4 | BS21: ='FA컵 디자인'!E17 -> 0
E23: =IF('FA컵 디자인'!B10="부전승","",VLOOKUP('FA컵 디자인'!B10,시즌이미지12[[팀명]:[사이즈125]],4,0)) -> #VALUE! | CF23: =IF('FA컵 디자인'!B18="부전승","",VLOOKUP('FA컵 디자인'!B18,시즌이미지12[[팀명]:[사이즈125]],4,0)) -> #VALUE!
K24: ='FA컵 디자인'!C10 -> 1 | CB24: ='FA컵 디자인'!C18 -> 3
AG25: =IFERROR(VLOOKUP('FA컵 디자인'!H7,시즌이미지12[[팀명]:[사이즈125]],6,0),'FA컵 디자인'!H7) -> #VALUE! | AM25: ='FA컵 디자인'!I7 -> 3 | AW25: ='FA컵 디자인'!I15 -> 2 | BB25: =IFERROR(VLOOKUP('FA컵 디자인'!H15,시즌이미지12[[팀명]:[사이즈125]],6,0),'FA컵 디자인'!H15) -> #VALUE!
E29: =IF('FA컵 디자인'!B11="부전승","",VLOOKUP('FA컵 디자인'!B11,시즌이미지12[[팀명]:[사이즈125]],4,0)) -> #VALUE! | CF29: =IF('FA컵 디자인'!B19="부전승","",VLOOKUP('FA컵 디자인'!B19,시즌이미지12[[팀명]:[사이즈125]],4,0)) -> #VALUE!
K30: ='FA컵 디자인'!C11 -> 0 | CB30: ='FA컵 디자인'!C19 -> 0
N32: =IFERROR(VLOOKUP('FA컵 디자인'!D11,시즌이미지12[[팀명]:[사이즈125]],4,0),'FA컵 디자인'!D11) -> #VALUE! | BW32: =IFERROR(VLOOKUP('FA컵 디자인'!D19,시즌이미지12[[팀명]:[사이즈125]],4,0),'FA컵 디자인'!D19) -> #VALUE!
T33: ='FA컵 디자인'!E11 -> 2 | BS33: ='FA컵 디자인'!E19 -> 4
E35: =IF('FA컵 디자인'!B12="부전승","",VLOOKUP('FA컵 디자인'!B12,시즌이미지12[[팀명]:[사이즈125]],4,0)) -> #VALUE! | CF35: =IF('FA컵 디자인'!B20="부전승","",VLOOKUP('FA컵 디자인'!B20,시즌이미지12[[팀명]:[사이즈125]],4,0)) -> #VALUE!
K36: ='FA컵 디자인'!C12 -> 4 | CB36: ='FA컵 디자인'!C20 -> 5
V37: =IFERROR(VLOOKUP('FA컵 디자인'!F11,시즌이미지12[[팀명]:[사이즈125]],5,0),'FA컵 디자인'!F11) -> #VALUE! | BM37: =IFERROR(VLOOKUP('FA컵 디자인'!F19,시즌이미지12[[팀명]:[사이즈125]],5,0),'FA컵 디자인'!F19) -> #VALUE!
AD39: ='FA컵 디자인'!G11 -> 3 | BI39: ='FA컵 디자인'!G19 -> 2
E41: =IF('FA컵 디자인'!B13="부전승","",VLOOKUP('FA컵 디자인'!B13,시즌이미지12[[팀명]:[사이즈125]],4,0)) -> #VALUE! | CF41: =IF('FA컵 디자인'!B21="부전승","",VLOOKUP('FA컵 디자인'!B21,시즌이미지12[[팀명]:[사이즈125]],4,0)) -> #VALUE!
K42: ='FA컵 디자인'!C13 -> 3 | CB42: ='FA컵 디자인'!C21 -> 2
N44: =IFERROR(VLOOKUP('FA컵 디자인'!D13,시즌이미지12[[팀명]:[사이즈125]],4,0),'FA컵 디자인'!D13) -> #VALUE! | BW44: =IFERROR(VLOOKUP('FA컵 디자인'!D21,시즌이미지12[[팀명]:[사이즈125]],4,0),'FA컵 디자인'!D21) -> #VALUE!
T45: ='FA컵 디자인'!E13 -> 1 | BS45: ='FA컵 디자인'!E21 -> 3
E47: =IF('FA컵 디자인'!B14="부전승","",VLOOKUP('FA컵 디자인'!B14,시즌이미지12[[팀명]:[사이즈125]],4,0)) -> #VALUE! | CF47: =IF('FA컵 디자인'!B22="부전승","",VLOOKUP('FA컵 디자인'!B22,시즌이미지12[[팀명]:[사이즈125]],4,0)) -> #VALUE!
K48: ='FA컵 디자인'!C14 -> 2 | CB48: ='FA컵 디자인'!C22 -> 0

Sheet FA컵 디자인
B6: 16강 | D6: 8강 | F6: 4강 | H6: 결승 | J6: 우승
B7: 바이에른 뮌헨 | C7: =IFERROR(VLOOKUP(B7,$L$8:$T$20,6,0),"") | D7: =IF(B7="부전승",B8,IF(B8="부전승",B7,IF(VLOOKUP(B7,$L$9:$N$20,3,0)=1,B7,B8))) -> 바이에른 뮌헨 | E7: =IFERROR(VLOOKUP(D7,$L$24:$T$32,6,0),"") -> 5 | F7: =IF(D7="부전승",D9,IF(D9="부전승",D7,IF(VLOOKUP(D7,$L$25:$N$32,3,0)=1,D7,D9))) -> 바이에른 뮌헨 | G7: =IFERROR(VLOOKUP(F7,$L$35:$T$39,6,0),"") -> 0 | H7: =IF(F7="부전승",F11,IF(F11="부전승",F7,IF(VLOOKUP(F7,$L$36:$N$39,3,0)=1,F7,F11))) -> 인테르 | I7: =IFERROR(VLOOKUP(H7,$L$42:$T$44,6,0),"") -> 3 | J7: =IF(H7="부전승",H15,IF(H15="부전승",H7,IF(VLOOKUP(H7,$L$43:$N$46,3,0)=1,H7,H15))) -> 인테르 | L7: FA컵_16강
B8: 부전승 | C8: =IFERROR(VLOOKUP(B8,$L$8:$T$20,6,0),"") | E8: =IFERROR(VLOOKUP(D8,$L$8:$T$20,6,0),"") | G8: =IFERROR(VLOOKUP(F8,$L$8:$T$20,6,0),"") | I8: =IFERROR(VLOOKUP(H8,$L$8:$T$20,6,0),"") | L8: 팀명 | M8: 경기 | N8: 승 | O8: 무 | P8: 패 | Q8: 득점 | R8: 실점 | S8: 득실 | T8: 승점
B9: 뉴캐슬 유나이티드 | C9: =IFERROR(VLOOKUP(B9,$L$8:$T$20,6,0),"") -> 2 | D9: =IF(B9="부전승",B10,IF(B10="부전승",B9,IF(VLOOKUP(B9,$L$9:$N$20,3,0)=1,B9,B10))) -> 뉴캐슬 유나이티드 | E9: =IFERROR(VLOOKUP(D9,$L$24:$T$32,6,0),"") -> 4 | G9: =IFERROR(VLOOKUP(F9,$L$24:$T$32,6,0),"") | I9: =IFERROR(VLOOKUP(H9,$L$24:$T$32,6,0),"") | L9: {=_xlfn._xlws.SORT(_xlfn.CHOOSECOLS(_xlfn._xlws.FILTER(리그순위표[], ISNUMBER(SEARCH(L7, 리그순위표[대회 종류]))), 2, 3, 4, 5, 6, 7, 8, 9, 10), {9,8}, {-1,-1})} -> 비야레알 | M9: 1 | N9: 1 | O9: 0 | P9: 0 | Q9: 5 | R9: 0 | S9: 5 | T9: 3
B10: 맨체스터 유나이티드 | C10: =IFERROR(VLOOKUP(B10,$L$8:$T$20,6,0),"") -> 1 | E10: =IFERROR(VLOOKUP(D10,$L$8:$T$20,6,0),"") | G10: =IFERROR(VLOOKUP(F10,$L$8:$T$20,6,0),"") | I10: =IFERROR(VLOOKUP(H10,$L$8:$T$20,6,0),"") | L10: 인테르 | M10: 1 | N10: 1 | O10: 0 | P10: 0 | Q10: 4 | R10: 0 | S10: 4 | T10: 3
B11: 레알 마드리드 | C11: =IFERROR(VLOOKUP(B11,$L$8:$T$20,6,0),"") -> 0 | D11: =IF(B11="부전승",B12,IF(B12="부전승",B11,IF(VLOOKUP(B11,$L$9:$N$20,3,0)=1,B11,B12))) -> 인테르 | E11: =IFERROR(VLOOKUP(D11,$L$24:$T$32,6,0),"") -> 2 | F11: =IF(D11="부전승",D13,IF(D13="부전승",D11,IF(VLOOKUP(D11,$L$25:$N$32,3,0)=1,D11,D13))) -> 인테르 | G11: =IFERROR(VLOOKUP(F11,$L$35:$T$39,6,0),"") -> 3 | I11: =IFERROR(VLOOKUP(H11,$L$35:$T$39,6,0),"") | L11: PSV | M11: 1 | N11: 1 | O11: 0 | P11: 0 | Q11: 3 | R11: 0 | S11: 3 | T11: 3
B12: 인테르 | C12: =IFERROR(VLOOKUP(B12,$L$8:$T$20,6,0),"") -> 4 | E12: =IFERROR(VLOOKUP(D12,$L$8:$T$20,6,0),"") | G12: =IFERROR(VLOOKUP(F12,$L$8:$T$20,6,0),"") | I12: =IFERROR(VLOOKUP(H12,$L$8:$T$20,6,0),"") | L12: 토트넘 | M12: 1 | N12: 1 | O12: 0 | P12: 0 | Q12: 2 | R12: 0 | S12: 2 | T12: 3
B13: 레버쿠젠 | C13: =IFERROR(VLOOKUP(B13,$L$8:$T$20,6,0),"") -> 3 | D13: =IF(B13="부전승",B14,IF(B14="부전승",B13,IF(VLOOKUP(B13,$L$9:$N$20,3,0)=1,B13,B14))) -> 레버쿠젠 | E13: =IFERROR(VLOOKUP(D13,$L$24:$T$32,6,0),"") -> 1 | G13: =IFERROR(VLOOKUP(F13,$L$24:$T$32,6,0),"") | I13: =IFERROR(VLOOKUP(H13,$L$24:$T$32,6,0),"") | L13: 레버쿠젠 | M13: 1 | N13: 1 | O13: 0 | P13: 0 | Q13: 3 | R13: 2 | S13: 1 | T13: 3
B14: 아우크스부르크 | C14: =IFERROR(VLOOKUP(B14,$L$8:$T$20,6,0),"") -> 2 | E14: =IFERROR(VLOOKUP(D14,$L$8:$T$20,6,0),"") | G14: =IFERROR(VLOOKUP(F14,$L$8:$T$20,6,0),"") | I14: =IFERROR(VLOOKUP(H14,$L$8:$T$20,6,0),"") | L14: 뉴캐슬 유나이티드 | M14: 1 | N14: 1 | O14: 0 | P14: 0 | Q14: 2 | R14: 1 | S14: 1 | T14: 3
B15: 도르트문트 | C15: =IFERROR(VLOOKUP(B15,$L$8:$T$20,6,0),"") | D15: =IF(B15="부전승",B16,IF(B16="부전승",B15,IF(VLOOKUP(B15,$L$9:$N$20,3,0)=1,B15,B16))) -> 도르트문트 | E15: =IFERROR(VLOOKUP(D15,$L$24:$T$32,6,0),"") -> 7 | F15: =IF(D15="부전승",D17,IF(D17="부전승",D15,IF(VLOOKUP(D15,$L$25:$N$32,3,0)=1,D15,D17))) -> 도르트문트 | G15: =IFERROR(VLOOKUP(F15,$L$35:$T$39,6,0),"") -> 4 | H15: =IF(F15="부전승",F19,IF(F19="부전승",F15,IF(VLOOKUP(F15,$L$36:$N$39,3,0)=1,F15,F19))) -> 도르트문트 | I15: =IFERROR(VLOOKUP(H15,$L$42:$T$44,6,0),"") -> 2 | L15: 맨체스터 유나이티드 | M15: 1 | N15: 0 | O15: 0 | P15: 1 | Q15: 1 | R15: 2 | S15: -1 | T15: 0
B16: 부전승 | C16: =IFERROR(VLOOKUP(B16,$L$8:$T$20,6,0),"") | E16: =IFERROR(VLOOKUP(D16,$L$8:$T$20,6,0),"") | G16: =IFERROR(VLOOKUP(F16,$L$8:$T$20,6,0),"") | I16: =IFERROR(VLOOKUP(H16,$L$8:$T$20,6,0),"") | L16: 아우크스부르크 | M16: 1 | N16: 0 | O16: 0 | P16: 1 | Q16: 2 | R16: 3 | S16: -1 | T16: 0
B17: 유벤투스 | C17: =IFERROR(VLOOKUP(B17,$L$8:$T$20,6,0),"") -> 0 | D17: =IF(B17="부전승",B18,IF(B18="부전승",B17,IF(VLOOKUP(B17,$L$9:$N$20,3,0)=1,B17,B18))) -> PSV | E17: =IFERROR(VLOOKUP(D17,$L$24:$T$32,6,0),"") -> 0 | G17: =IFERROR(VLOOKUP(F17,$L$24:$T$32,6,0),"") | I17: =IFERROR(VLOOKUP(H17,$L$24:$T$32,6,0),"") | L17: 첼시 | M17: 1 | N17: 0 | O17: 0 | P17: 1 | Q17: 0 | R17: 2 | S17: -2 | T17: 0
B18: PSV | C18: =IFERROR(VLOOKUP(B18,$L$8:$T$20,6,0),"") -> 3 | E18: =IFERROR(VLOOKUP(D18,$L$8:$T$20,6,0),"") | G18: =IFERROR(VLOOKUP(F18,$L$8:$T$20,6,0),"") | I18: =IFERROR(VLOOKUP(H18,$L$8:$T$20,6,0),"") | L18: 유벤투스 | M18: 1 | N18: 0 | O18: 0 | P18: 1 | Q18: 0 | R18: 3 | S18: -3 | T18: 0
B19: 아틀레티코 마드리드 | C19: =IFERROR(VLOOKUP(B19,$L$8:$T$20,6,0),"") -> 0 | D19: =IF(B19="부전승",B20,IF(B20="부전승",B19,IF(VLOOKUP(B19,$L$9:$N$20,3,0)=1,B19,B20))) -> 비야레알 | E19: =IFERROR(VLOOKUP(D19,$L$24:$T$32,6,0),"") -> 4 | F19: =IF(D19="부전승",D21,IF(D21="부전승",D19,IF(VLOOKUP(D19,$L$25:$N$32,3,0)=1,D19,D21))) -> 비야레알 | G19: =IFERROR(VLOOKUP(F19,$L$35:$T$39,6,0),"") -> 2 | I19: =IFERROR(VLOOKUP(H19,$L$35:$T$39,6,0),"") | L19: 레알 마드리드 | M19: 1 | N19: 0 | O19: 0 | P19: 1 | Q19: 0 | R19: 4 | S19: -4 | T19: 0
B20: 비야레알 | C20: =IFERROR(VLOOKUP(B20,$L$8:$T$20,6,0),"") -> 5 | E20: =IFERROR(VLOOKUP(D20,$L$8:$T$20,6,0),"") | G20: =IFERROR(VLOOKUP(F20,$L$8:$T$20,6,0),"") | I20: =IFERROR(VLOOKUP(H20,$L$8:$T$20,6,0),"") | L20: 아틀레티코 마드리드 | M20: 1 | N20: 0 | O20: 0 | P20: 1 | Q20: 0 | R20: 5 | S20: -5 | T20: 0
B21: 토트넘 | C21: =IFERROR(VLOOKUP(B21,$L$8:$T$20,6,0),"") -> 2 | D21: =IF(B21="부전승",B22,IF(B22="부전승",B21,IF(VLOOKUP(B21,$L$9:$N$20,3,0)=1,B21,B22))) -> 토트넘 | E21: =IFERROR(VLOOKUP(D21,$L$24:$T$32,6,0),"") -> 3 | G21: =IFERROR(VLOOKUP(F21,$L$24:$T$32,6,0),"") | I21: =IFERROR(VLOOKUP(H21,$L$24:$T$32,6,0),"")
B22: 첼시 | C22: =IFERROR(VLOOKUP(B22,$L$8:$T$20,6,0),"") -> 0 | E22: =IFERROR(VLOOKUP(D22,$L$8:$T$20,6,0),"") | G22: =IFERROR(VLOOKUP(F22,$L$8:$T$20,6,0),"") | I22: =IFERROR(VLOOKUP(H22,$L$8:$T$20,6,0),"")
L23: FA컵_8강
B24: 16강 | L24: 팀명 | M24: 경기 | N24: 승 | O24: 무 | P24: 패 | Q24: 득점 | R24: 실점 | S24: 득실 | T24: 승점
L25: {=_xlfn._xlws.SORT(_xlfn.CHOOSECOLS(_xlfn._xlws.FILTER(리그순위표[], ISNUMBER(SEARCH(L23, 리그순위표[대회 종류]))), 2, 3, 4, 5, 6, 7, 8, 9, 10), {9,8}, {-1,-1})} -> 도르트문트 | M25: 1 | N25: 1 | O25: 0 | P25: 0 | Q25: 7 | R25: 0 | S25: 7 | T25: 3
L26: 인테르 | M26: 1 | N26: 1 | O26: 0 | P26: 0 | Q26: 2 | R26: 1 | S26: 1 | T26: 3
L27: 비야레알 | M27: 1 | N27: 1 | O27: 0 | P27: 0 | Q27: 4 | R27: 3 | S27: 1 | T27: 3
L28: 바이에른 뮌헨 | M28: 1 | N28: 1 | O28: 0 | P28: 0 | Q28: 5 | R28: 4 | S28: 1 | T28: 3
L29: 레버쿠젠 | M29: 1 | N29: 0 | O29: 0 | P29: 1 | Q29: 1 | R29: 2 | S29: -1 | T29: 0
L30: 토트넘 | M30: 1 | N30: 0 | O30: 0 | P30: 1 | Q30: 3 | R30: 4 | S30: -1 | T30: 0
L31: 뉴캐슬 유나이티드 | M31: 1 | N31: 0 | O31: 0 | P31: 1 | Q31: 4 | R31: 5 | S31: -1 | T31: 0
L32: PSV | M32: 1 | N32: 0 | O32: 0 | P32: 1 | Q32: 0 | R32: 7 | S32: -7 | T32: 0
L34: FA컵_4강
L35: 팀명 | M35: 경기 | N35: 승 | O35: 무 | P35: 패 | Q35: 득점 | R35: 실점 | S35: 득실 | T35: 승점
L36: {=_xlfn._xlws.SORT(_xlfn.CHOOSECOLS(_xlfn._xlws.FILTER(리그순위표[], ISNUMBER(SEARCH(L34, 리그순위표[대회 종류]))), 2, 3, 4, 5, 6, 7, 8, 9, 10), {9,8}, {-1,-1})} -> 인테르 | M36: 1 | N36: 1 | O36: 0 | P36: 0 | Q36: 3 | R36: 0 | S36: 3 | T36: 3
L37: 도르트문트 | M37: 1 | N37: 1 | O37: 0 | P37: 0 | Q37: 4 | R37: 2 | S37: 2 | T37: 3
L38: 비야레알 | M38: 1 | N38: 0 | O38: 0 | P38: 1 | Q38: 2 | R38: 4 | S38: -2 | T38: 0
L39: 바이에른 뮌헨 | M39: 1 | N39: 0 | O39: 0 | P39: 1 | Q39: 0 | R39: 3 | S39: -3 | T39: 0
L41: FA컵_결승
L42: 팀명 | M42: 경기 | N42: 승 | O42: 무 | P42: 패 | Q42: 득점 | R42: 실점 | S42: 득실 | T42: 승점
L43: {=_xlfn._xlws.SORT(_xlfn.CHOOSECOLS(_xlfn._xlws.FILTER(리그순위표[], ISNUMBER(SEARCH(L41, 리그순위표[대회 종류]))), 2, 3, 4, 5, 6, 7, 8, 9, 10), {9,8}, {-1,-1})} -> 인테르 | M43: 1 | N43: 1 | O43: 0 | P43: 0 | Q43: 3 | R43: 2 | S43: 1 | T43: 3
L44: 도르트문트 | M44: 1 | N44: 0 | O44: 0 | P44: 1 | Q44: 2 | R44: 3 | S44: -1 | T44: 0

Sheet UCL 디자인
B2: 16강 | C2: 8강 | D2: 4강 | E2: 결승 | F2: 우승 | H2: UCL_결승
B3: 레알 마드리드 | C3: =IF(B3="부전승",B4,IF(B4="부전승",B3,IF(VLOOKUP(B3,#REF!,3,0)=1,B3,B4))) -> 레알 마드리드 | D3: =IF(VLOOKUP(C3,$H$15:$P$23,9,0)>VLOOKUP(C5,$H$15:$P$23,9,0),C3,IF(VLOOKUP(C3,$H$15:$P$23,9,0)<VLOOKUP(C5,$H$15:$P$23,9,0),C5,IF((VLOOKUP(C3,$H$15:$P$23,9,0)=VLOOKUP(C5,$H$15:$P$23,9,0))*(VLOOKUP(C3,$H$15:$P$23,8,0)>VLOOKUP(C5,$H$15:$P$23,8,0)),C3,C5))) -> 레알 마드리드 | E3: =IF(VLOOKUP(D3,$H$8:$P$12,9,0)>VLOOKUP(D7,$H$8:$P$12,9,0),D3,IF(VLOOKUP(D3,$H$8:$P$12,9,0)<VLOOKUP(D7,$H$8:$P$12,9,0),D7,IF((VLOOKUP(D3,$H$8:$P$12,9,0)=VLOOKUP(D7,$H$8:$P$12,9,0))*(VLOOKUP(D3,$H$8:$P$12,8,0)>VLOOKUP(D7,$H$8:$P$12,8,0)),D3,D7))) -> 레알 마드리드 | F3: =IF(E3="부전승",E11,IF(E11="부전승",E3,IF(VLOOKUP(E3,$H$4:$J$5,3,0)=1,E3,E11))) -> 레알 마드리드 | H3: 팀명 | I3: 경기 | J3: 승 | K3: 무 | L3: 패 | M3: 득점 | N3: 실점 | O3: 득실 | P3: 승점
B4: 부전승 | H4: {=_xlfn._xlws.SORT(_xlfn.CHOOSECOLS(_xlfn._xlws.FILTER(리그순위표[], ISNUMBER(SEARCH(H2, 리그순위표[대회 종류]))), 2, 3, 4, 5, 6, 7, 8, 9, 10), {9,8}, {-1,-1})} -> 레알 마드리드 | I4: 1 | J4: 1 | K4: 0 | L4: 0 | M4: 4 | N4: 2 | O4: 2 | P4: 3
B5: PSV | C5: =IF(B5="부전승",B6,IF(B6="부전승",B5,IF(VLOOKUP(B5,#REF!,3,0)=1,B5,B6))) -> PSV | H5: 인테르 | I5: 1 | J5: 0 | K5: 0 | L5: 1 | M5: 2 | N5: 4 | O5: -2 | P5: 0
B6: 부전승
B7: 도르트문트 | C7: =IF(B7="부전승",B8,IF(B8="부전승",B7,IF(VLOOKUP(B7,#REF!,3,0)=1,B7,B8))) -> 도르트문트 | D7: =IF(VLOOKUP(C7,$H$15:$P$23,9,0)>VLOOKUP(C9,$H$15:$P$23,9,0),C7,IF(VLOOKUP(C7,$H$15:$P$23,9,0)<VLOOKUP(C9,$H$15:$P$23,9,0),C9,IF((VLOOKUP(C7,$H$15:$P$23,9,0)=VLOOKUP(C9,$H$15:$P$23,9,0))*(VLOOKUP(C7,$H$15:$P$23,8,0)>VLOOKUP(C9,$H$15:$P$23,8,0)),C7,C9))) -> 맨체스터 유나이티드 | H7: UCL_4강
B8: 부전승 | H8: 팀명 | I8: 경기 | J8: 승 | K8: 무 | L8: 패 | M8: 득점 | N8: 실점 | O8: 득실 | P8: 승점
B9: 맨체스터 유나이티드 | C9: =IF(B9="부전승",B10,IF(B10="부전승",B9,IF(VLOOKUP(B9,#REF!,3,0)=1,B9,B10))) -> 맨체스터 유나이티드 | H9: {=_xlfn._xlws.SORT(_xlfn.CHOOSECOLS(_xlfn._xlws.FILTER(리그순위표[], ISNUMBER(SEARCH(H7, 리그순위표[대회 종류]))), 2, 3, 4, 5, 6, 7, 8, 9, 10), {9,8}, {-1,-1})} -> 레알 마드리드 | I9: 3 | J9: 2 | K9: 0 | L9: 1 | M9: 9 | N9: 6 | O9: 3 | P9: 6
B10: 부전승 | H10: 인테르 | I10: 2 | J10: 2 | K10: 0 | L10: 0 | M10: 5 | N10: 2 | O10: 3 | P10: 6
B11: 뉴캐슬 유나이티드 | C11: =IF(B11="부전승",B12,IF(B12="부전승",B11,IF(VLOOKUP(B11,#REF!,3,0)=1,B11,B12))) -> 뉴캐슬 유나이티드 | D11: =IF(VLOOKUP(C11,$H$15:$P$23,9,0)>VLOOKUP(C13,$H$15:$P$23,9,0),C11,IF(VLOOKUP(C11,$H$15:$P$23,9,0)<VLOOKUP(C13,$H$15:$P$23,9,0),C13,IF((VLOOKUP(C11,$H$15:$P$23,9,0)=VLOOKUP(C13,$H$15:$P$23,9,0))*(VLOOKUP(C11,$H$15:$P$23,8,0)>VLOOKUP(C13,$H$15:$P$23,8,0)),C11,C13))) -> 아틀레티코 마드리드 | E11: =IF(VLOOKUP(D11,$H$8:$P$12,9,0)>VLOOKUP(D15,$H$8:$P$12,9,0),D11,IF(VLOOKUP(D11,$H$8:$P$12,9,0)<VLOOKUP(D15,$H$8:$P$12,9,0),D15,IF((VLOOKUP(D11,$H$8:$P$12,9,0)=VLOOKUP(D15,$H$8:$P$12,9,0))*(VLOOKUP(D11,$H$8:$P$12,8,0)>VLOOKUP(D15,$H$8:$P$12,8,0)),D11,D15))) -> 인테르 | H11: 맨체스터 유나이티드 | I11: 3 | J11: 1 | K11: 0 | L11: 2 | M11: 6 | N11: 9 | O11: -3 | P11: 3
B12: 부전승 | H12: 아틀레티코 마드리드 | I12: 2 | J12: 0 | K12: 0 | L12: 2 | M12: 2 | N12: 5 | O12: -3 | P12: 0
B13: 아틀레티코 마드리드 | C13: =IF(B13="부전승",B14,IF(B14="부전승",B13,IF(VLOOKUP(B13,#REF!,3,0)=1,B13,B14))) -> 아틀레티코 마드리드
B14: 부전승 | H14: UCL_8강
B15: 인테르 | C15: =IF(B15="부전승",B16,IF(B16="부전승",B15,IF(VLOOKUP(B15,#REF!,3,0)=1,B15,B16))) -> 인테르 | D15: =IF(VLOOKUP(C15,$H$15:$P$23,9,0)>VLOOKUP(C17,$H$15:$P$23,9,0),C15,IF(VLOOKUP(C15,$H$15:$P$23,9,0)<VLOOKUP(C17,$H$15:$P$23,9,0),C17,IF((VLOOKUP(C15,$H$15:$P$23,9,0)=VLOOKUP(C17,$H$15:$P$23,9,0))*(VLOOKUP(C15,$H$15:$P$23,8,0)>VLOOKUP(C17,$H$15:$P$23,8,0)),C15,C17))) -> 인테르 | H15: 팀명 | I15: 경기 | J15: 승 | K15: 무 | L15: 패 | M15: 득점 | N15: 실점 | O15: 득실 | P15: 승점
B16: 부전승 | H16: {=_xlfn._xlws.SORT(_xlfn.CHOOSECOLS(_xlfn._xlws.FILTER(리그순위표[], ISNUMBER(SEARCH(H14, 리그순위표[대회 종류]))), 2, 3, 4, 5, 6, 7, 8, 9, 10), {9,8}, {-1,-1})} -> 레알 마드리드 | I16: 2 | J16: 2 | K16: 0 | L16: 0 | M16: 10 | N16: 3 | O16: 7 | P16: 6
B17: 비야레알 | C17: =IF(B17="부전승",B18,IF(B18="부전승",B17,IF(VLOOKUP(B17,#REF!,3,0)=1,B17,B18))) -> 비야레알 | H17: 맨체스터 유나이티드 | I17: 2 | J17: 2 | K17: 0 | L17: 0 | M17: 7 | N17: 4 | O17: 3 | P17: 6
B18: 부전승 | H18: 인테르 | I18: 3 | J18: 2 | K18: 0 | L18: 1 | M18: 8 | N18: 6 | O18: 2 | P18: 6
H19: 아틀레티코 마드리드 | I19: 2 | J19: 1 | K19: 1 | L19: 0 | M19: 6 | N19: 5 | O19: 1 | P19: 4
B20: 16강 | C20: 8강 | D20: 4강 | E20: 결승 | F20: 우승 | H20: 비야레알 | I20: 3 | J20: 1 | K20: 0 | L20: 2 | M20: 6 | N20: 8 | O20: -2 | P20: 3
B21: =IFERROR(VLOOKUP(B3,시즌이미지12[[팀명]:[사이즈35]],3,0),B3) -> #VALUE! | C21: =IF(B21="부전승",B22,IF(B22="부전승",B21,IF(VLOOKUP(B21,#REF!,3,0)=1,B21,B22))) -> #VALUE! | D21: =IFERROR(VLOOKUP(D3,시즌이미지12[[팀명]:[사이즈35]],3,0),D3) -> #VALUE! | E21: =IFERROR(VLOOKUP(E3,시즌이미지12[[팀명]:[사이즈35]],3,0),E3) -> #VALUE! | F21: =IFERROR(VLOOKUP(F3,시즌이미지12[[팀명]:[사이즈35]],3,0),F3) -> #VALUE! | H21: 뉴캐슬 유나이티드 | I21: 2 | J21: 0 | K21: 1 | L21: 1 | M21: 5 | N21: 6 | O21: -1 | P21: 1
B22: =IFERROR(VLOOKUP(B4,시즌이미지12[[팀명]:[사이즈35]],3,0),B4) -> 부전승 | D22: =IFERROR(VLOOKUP(D4,시즌이미지12[[팀명]:[사이즈35]],3,0),D4) -> 0 | E22: =IFERROR(VLOOKUP(E4,시즌이미지12[[팀명]:[사이즈35]],3,0),E4) -> 0 | F22: =IFERROR(VLOOKUP(F4,시즌이미지12[[팀명]:[사이즈35]],3,0),F4) -> 0 | H22: 도르트문트 | I22: 2 | J22: 0 | K22: 0 | L22: 2 | M22: 4 | N22: 7 | O22: -3 | P22: 0
B23: =IFERROR(VLOOKUP(B5,시즌이미지12[[팀명]:[사이즈35]],3,0),B5) -> #VALUE! | C23: =IF(B23="부전승",B24,IF(B24="부전승",B23,IF(VLOOKUP(B23,#REF!,3,0)=1,B23,B24))) -> #VALUE! | D23: =IFERROR(VLOOKUP(D5,시즌이미지12[[팀명]:[사이즈35]],3,0),D5) -> 0 | E23: =IFERROR(VLOOKUP(E5,시즌이미지12[[팀명]:[사이즈35]],3,0),E5) -> 0 | F23: =IFERROR(VLOOKUP(F5,시즌이미지12[[팀명]:[사이즈35]],3,0),F5) -> 0 | H23: PSV | I23: 2 | J23: 0 | K23: 0 | L23: 2 | M23: 3 | N23: 10 | O23: -7 | P23: 0
B24: =IFERROR(VLOOKUP(B6,시즌이미지12[[팀명]:[사이즈35]],3,0),B6) -> 부전승 | D24: =IFERROR(VLOOKUP(D6,시즌이미지12[[팀명]:[사이즈35]],3,0),D6) -> 0 | E24: =IFERROR(VLOOKUP(E6,시즌이미지12[[팀명]:[사이즈35]],3,0),E6) -> 0 | F24: =IFERROR(VLOOKUP(F6,시즌이미지12[[팀명]:[사이즈35]],3,0),F6) -> 0
B25: =IFERROR(VLOOKUP(B7,시즌이미지12[[팀명]:[사이즈35]],3,0),B7) -> #VALUE! | C25: =IF(B25="부전승",B26,IF(B26="부전승",B25,IF(VLOOKUP(B25,#REF!,3,0)=1,B25,B26))) -> #VALUE! | D25: =IFERROR(VLOOKUP(D7,시즌이미지12[[팀명]:[사이즈35]],3,0),D7) -> #VALUE! | E25: =IFERROR(VLOOKUP(E7,시즌이미지12[[팀명]:[사이즈35]],3,0),E7) -> 0 | F25: =IFERROR(VLOOKUP(F7,시즌이미지12[[팀명]:[사이즈35]],3,0),F7) -> 0 | H25: UCL_A조
B26: =IFERROR(VLOOKUP(B8,시즌이미지12[[팀명]:[사이즈35]],3,0),B8) -> 부전승 | D26: =IFERROR(VLOOKUP(D8,시즌이미지12[[팀명]:[사이즈35]],3,0),D8) -> 0 | E26: =IFERROR(VLOOKUP(E8,시즌이미지12[[팀명]:[사이즈35]],3,0),E8) -> 0 | F26: =IFERROR(VLOOKUP(F8,시즌이미지12[[팀명]:[사이즈35]],3,0),F8) -> 0 | H26: 팀명 | I26: 경기 | J26: 승 | K26: 무 | L26: 패 | M26: 득점 | N26: 실점 | O26: 득실 | P26: 승점
B27: =IFERROR(VLOOKUP(B9,시즌이미지12[[팀명]:[사이즈35]],3,0),B9) -> #VALUE! | C27: =IF(B27="부전승",B28,IF(B28="부전승",B27,IF(VLOOKUP(B27,#REF!,3,0)=1,B27,B28))) -> #VALUE! | D27: =IFERROR(VLOOKUP(D9,시즌이미지12[[팀명]:[사이즈35]],3,0),D9) -> 0 | E27: =IFERROR(VLOOKUP(E9,시즌이미지12[[팀명]:[사이즈35]],3,0),E9) -> 0 | F27: =IFERROR(VLOOKUP(F9,시즌이미지12[[팀명]:[사이즈35]],3,0),F9) -> 0 | H27: {=_xlfn._xlws.SORT(_xlfn.CHOOSECOLS(_xlfn._xlws.FILTER(리그순위표[], ISNUMBER(SEARCH(H25, 리그순위표[대회 종류]))), 2, 3, 4, 5, 6, 7, 8, 9, 10), {9,8}, {-1,-1})} -> 레알 마드리드 | I27: 6 | J27: 3 | K27: 1 | L27: 2 | M27: 15 | N27: 13 | O27: 2 | P27: 10
B28: =IFERROR(VLOOKUP(B10,시즌이미지12[[팀명]:[사이즈35]],3,0),B10) -> 부전승 | D28: =IFERROR(VLOOKUP(D10,시즌이미지12[[팀명]:[사이즈35]],3,0),D10) -> 0 | E28: =IFERROR(VLOOKUP(E10,시즌이미지12[[팀명]:[사이즈35]],3,0),E10) -> 0 | F28: =IFERROR(VLOOKUP(F10,시즌이미지12[[팀명]:[사이즈35]],3,0),F10) -> 0 | H28: 아틀레티코 마드리드 | I28: 6 | J28: 3 | K28: 0 | L28: 3 | M28: 20 | N28: 16 | O28: 4 | P28: 9
B29: =IFERROR(VLOOKUP(B11,시즌이미지12[[팀명]:[사이즈35]],3,0),B11) -> #VALUE! | C29: =IF(B29="부전승",B30,IF(B30="부전승",B29,IF(VLOOKUP(B29,#REF!,3,0)=1,B29,B30))) -> #VALUE! | D29: =IFERROR(VLOOKUP(D11,시즌이미지12[[팀명]:[사이즈35]],3,0),D11) -> #VALUE! | E29: =IFERROR(VLOOKUP(E11,시즌이미지12[[팀명]:[사이즈35]],3,0),E11) -> #VALUE! | F29: =IFERROR(VLOOKUP(F11,시즌이미지12[[팀명]:[사이즈35]],3,0),F11) -> 0 | H29: 첼시 | I29: 6 | J29: 2 | K29: 2 | L29: 2 | M29: 17 | N29: 16 | O29: 1 | P29: 8
B30: =IFERROR(VLOOKUP(B12,시즌이미지12[[팀명]:[사이즈35]],3,0),B12) -> 부전승 | D30: =IFERROR(VLOOKUP(D12,시즌이미지12[[팀명]:[사이즈35]],3,0),D12) -> 0 | E30: =IFERROR(VLOOKUP(E12,시즌이미지12[[팀명]:[사이즈35]],3,0),E12) -> 0 | F30: =IFERROR(VLOOKUP(F12,시즌이미지12[[팀명]:[사이즈35]],3,0),F12) -> 0 | H30: 레버쿠젠 | I30: 6 | J30: 2 | K30: 1 | L30: 3 | M30: 9 | N30: 16 | O30: -7 | P30: 7
B31: =IFERROR(VLOOKUP(B13,시즌이미지12[[팀명]:[사이즈35]],3,0),B13) -> #VALUE! | C31: =IF(B31="부전승",B32,IF(B32="부전승",B31,IF(VLOOKUP(B31,#REF!,3,0)=1,B31,B32))) -> #VALUE! | D31: =IFERROR(VLOOKUP(D13,시즌이미지12[[팀명]:[사이즈35]],3,0),D13) -> 0 | E31: =IFERROR(VLOOKUP(E13,시즌이미지12[[팀명]:[사이즈35]],3,0),E13) -> 0 | F31: =IFERROR(VLOOKUP(F13,시즌이미지12[[팀명]:[사이즈35]],3,0),F13) -> 0
B32: =IFERROR(VLOOKUP(B14,시즌이미지12[[팀명]:[사이즈35]],3,0),B14) -> 부전승 | D32: =IFERROR(VLOOKUP(D14,시즌이미지12[[팀명]:[사이즈35]],3,0),D14) -> 0 | E32: =IFERROR(VLOOKUP(E14,시즌이미지12[[팀명]:[사이즈35]],3,0),E14) -> 0 | F32: =IFERROR(VLOOKUP(F14,시즌이미지12[[팀명]:[사이즈35]],3,0),F14) -> 0 | H32: UCL_B조
B33: =IFERROR(VLOOKUP(B15,시즌이미지12[[팀명]:[사이즈35]],3,0),B15) -> #VALUE! | C33: =IF(B33="부전승",B34,IF(B34="부전승",B33,IF(VLOOKUP(B33,#REF!,3,0)=1,B33,B34))) -> #VALUE! | D33: =IFERROR(VLOOKUP(D15,시즌이미지12[[팀명]:[사이즈35]],3,0),D15) -> #VALUE! | E33: =IFERROR(VLOOKUP(E15,시즌이미지12[[팀명]:[사이즈35]],3,0),E15) -> 0 | F33: =IFERROR(VLOOKUP(F15,시즌이미지12[[팀명]:[사이즈35]],3,0),F15) -> 0 | H33: 팀명 | I33: 경기 | J33: 승 | K33: 무 | L33: 패 | M33: 득점 | N33: 실점 | O33: 득실 | P33: 승점
B34: =IFERROR(VLOOKUP(B16,시즌이미지12[[팀명]:[사이즈35]],3,0),B16) -> 부전승 | D34: =IFERROR(VLOOKUP(D16,시즌이미지12[[팀명]:[사이즈35]],3,0),D16) -> 0 | E34: =IFERROR(VLOOKUP(E16,시즌이미지12[[팀명]:[사이즈35]],3,0),E16) -> 0 | F34: =IFERROR(VLOOKUP(F16,시즌이미지12[[팀명]:[사이즈35]],3,0),F16) -> 0 | H34: {=_xlfn._xlws.SORT(_xlfn.CHOOSECOLS(_xlfn._xlws.FILTER(리그순위표[], ISNUMBER(SEARCH(H32, 리그순위표[대회 종류]))), 2, 3, 4, 5, 6, 7, 8, 9, 10), {9,8}, {-1,-1})} -> 도르트문트 | I34: 6 | J34: 5 | K34: 1 | L34: 0 | M34: 30 | N34: 10 | O34: 20 | P34: 16
B35: =IFERROR(VLOOKUP(B17,시즌이미지12[[팀명]:[사이즈35]],3,0),B17) -> #VALUE! | C35: =IF(B35="부전승",B36,IF(B36="부전승",B35,IF(VLOOKUP(B35,#REF!,3,0)=1,B35,B36))) -> #VALUE! | D35: =IFERROR(VLOOKUP(D17,시즌이미지12[[팀명]:[사이즈35]],3,0),D17) -> 0 | E35: =IFERROR(VLOOKUP(E17,시즌이미지12[[팀명]:[사이즈35]],3,0),E17) -> 0 | F35: =IFERROR(VLOOKUP(F17,시즌이미지12[[팀명]:[사이즈35]],3,0),F17) -> 0 | H35: 맨체스터 유나이티드 | I35: 6 | J35: 3 | K35: 1 | L35: 2 | M35: 19 | N35: 13 | O35: 6 | P35: 10
B36: =IFERROR(VLOOKUP(B18,시즌이미지12[[팀명]:[사이즈35]],3,0),B18) -> 부전승 | D36: =IFERROR(VLOOKUP(D18,시즌이미지12[[팀명]:[사이즈35]],3,0),D18) -> 0 | E36: =IFERROR(VLOOKUP(E18,시즌이미지12[[팀명]:[사이즈35]],3,0),E18) -> 0 | F36: =IFERROR(VLOOKUP(F18,시즌이미지12[[팀명]:[사이즈35]],3,0),F18) -> 0 | H36: 토트넘 | I36: 6 | J36: 2 | K36: 1 | L36: 3 | M36: 10 | N36: 19 | O36: -9 | P36: 7
H37: 아우크스부르크 | I37: 6 | J37: 0 | K37: 1 | L37: 5 | M37: 6 | N37: 23 | O37: -17 | P37: 1
H39: UCL_C조
H40: 팀명 | I40: 경기 | J40: 승 | K40: 무 | L40: 패 | M40: 득점 | N40: 실점 | O40: 득실 | P40: 승점
H41: {=_xlfn._xlws.SORT(_xlfn.CHOOSECOLS(_xlfn._xlws.FILTER(리그순위표[], ISNUMBER(SEARCH(H39, 리그순위표[대회 종류]))), 2, 3, 4, 5, 6, 7, 8, 9, 10), {9,8}, {-1,-1})} -> 인테르 | I41: 4 | J41: 4 | K41: 0 | L41: 0 | M41: 15 | N41: 7 | O41: 8 | P41: 12
H42: PSV | I42: 4 | J42: 0 | K42: 2 | L42: 2 | M42: 12 | N42: 15 | O42: -3 | P42: 2
...

Sheet 리그테이블DB
A1: 대회 종류 | B1: 팀명 | C1: 경기 | D1: 승 | E1: 무 | F1: 패 | G1: 득점 | H1: 실점 | I1: 득실 | J1: 승점
A2: 1부리그 | B2: 맨체스터 유나이티드 | C2: 10 | D2: 4 | E2: 3 | F2: 3 | G2: 22 | H2: 20 | I2: 2 | J2: 15 | L2: UCL_A조 | X2: {=_xlfn.UNIQUE(리그순위표[대회 종류])} -> 1부리그
A3: 1부리그 | B3: 도르트문트 | C3: 10 | D3: 7 | E3: 0 | F3: 3 | G3: 31 | H3: 26 | I3: 5 | J3: 21 | L3: 팀명 | M3: 경기 | N3: 승 | O3: 무 | P3: 패 | Q3: 득점 | R3: 실점 | S3: 득실 | T3: 승점 | X3: 2부리그
A4: 1부리그 | B4: 바이에른 뮌헨 | C4: 10 | D4: 5 | E4: 1 | F4: 4 | G4: 29 | H4: 18 | I4: 11 | J4: 16 | L4: {=_xlfn._xlws.SORT(_xlfn.CHOOSECOLS(_xlfn._xlws.FILTER(리그순위표[], ISNUMBER(SEARCH(L2, 리그순위표[대회 종류]))), 2, 3, 4, 5, 6, 7, 8, 9, 10), {9,8}, {-1,-1})} -> 레알 마드리드 | M4: 6 | N4: 3 | O4: 1 | P4: 2 | Q4: 15 | R4: 13 | S4: 2 | T4: 10 | X4: FA컵_16강
A5: 1부리그 | B5: 인테르 | C5: 10 | D5: 3 | E5: 3 | F5: 4 | G5: 18 | H5: 20 | I5: -2 | J5: 12 | L5: 아틀레티코 마드리드 | M5: 6 | N5: 3 | O5: 0 | P5: 3 | Q5: 20 | R5: 16 | S5: 4 | T5: 9 | X5: FA컵_4강
A6: 1부리그 | B6: 비야레알 | C6: 10 | D6: 3 | E6: 3 | F6: 4 | G6: 21 | H6: 27 | I6: -6 | J6: 12 | L6: 첼시 | M6: 6 | N6: 2 | O6: 2 | P6: 2 | Q6: 17 | R6: 16 | S6: 1 | T6: 8 | X6: FA컵_8강
A7: 1부리그 | B7: 뉴캐슬 유나이티드 | C7: 10 | D7: 3 | E7: 0 | F7: 7 | G7: 18 | H7: 28 | I7: -10 | J7: 9 | L7: 레버쿠젠 | M7: 6 | N7: 2 | O7: 1 | P7: 3 | Q7: 9 | R7: 16 | S7: -7 | T7: 7 | X7: FA컵_결승전
A8: 2부리그 | B8: 첼시 | C8: 14 | D8: 6 | E8: 0 | F8: 8 | G8: 36 | H8: 33 | I8: 3 | J8: 18 | X8: UCL_4강
A9: 2부리그 | B9: 아우크스부르크 | C9: 12 | D9: 0 | E9: 1 | F9: 11 | G9: 13 | H9: 44 | I9: -31 | J9: 1 | X9: UCL_8강
A10: 2부리그 | B10: 아틀레티코 마드리드 | C10: 14 | D10: 11 | E10: 0 | F10: 3 | G10: 43 | H10: 15 | I10: 28 | J10: 33 | L10: UCL_B조 | X10: UCL_A조
A11: 2부리그 | B11: 유벤투스 | C11: 10 | D11: 2 | E11: 1 | F11: 7 | G11: 10 | H11: 29 | I11: -19 | J11: 7 | L11: 팀명 | M11: 경기 | N11: 승 | O11: 무 | P11: 패 | Q11: 득점 | R11: 실점 | S11: 득실 | T11: 승점 | X11: UCL_B조
A12: 2부리그 | B12: 레알 마드리드 | C12: 14 | D12: 9 | E12: 1 | F12: 4 | G12: 35 | H12: 22 | I12: 13 | J12: 28 | L12: {=_xlfn._xlws.SORT(_xlfn.CHOOSECOLS(_xlfn._xlws.FILTER(리그순위표[], ISNUMBER(SEARCH(L10, 리그순위표[대회 종류]))), 2, 3, 4, 5, 6, 7, 8, 9, 10), {9,8}, {-1,-1})} -> 도르트문트 | M12: 6 | N12: 5 | O12: 1 | P12: 0 | Q12: 30 | R12: 10 | S12: 20 | T12: 16 | X12: UCL_C조
A13: 2부리그 | B13: PSV | C13: 10 | D13: 5 | E13: 2 | F13: 3 | G13: 31 | H13: 32 | I13: -1 | J13: 17 | L13: 맨체스터 유나이티드 | M13: 6 | N13: 3 | O13: 1 | P13: 2 | Q13: 19 | R13: 13 | S13: 6 | T13: 10 | X13: UCL_D조
A14: 2부리그 | B14: 토트넘 | C14: 12 | D14: 4 | E14: 0 | F14: 8 | G14: 29 | H14: 37 | I14: -8 | J14: 12 | L14: 토트넘 | M14: 6 | N14: 2 | O14: 1 | P14: 3 | Q14: 10 | R14: 19 | S14: -9 | T14: 7 | X14: UCL_결승전
A15: 2부리그 | B15: 레버쿠젠 | C15: 14 | D15: 9 | E15: 3 | F15: 2 | G15: 39 | H15: 24 | I15: 15 | J15: 30 | L15: 아우크스부르크 | M15: 6 | N15: 0 | O15: 1 | P15: 5 | Q15: 6 | R15: 23 | S15: -17 | T15: 1 | X15: 승강PO
A16: FA컵_16강 | B16: 맨체스터 유나이티드 | C16: 1 | D16: 0 | E16: 0 | F16: 1 | G16: 1 | H16: 2 | I16: -1 | J16: 0
A17: FA컵_16강 | B17: 토트넘 | C17: 1 | D17: 1 | E17: 0 | F17: 0 | G17: 2 | H17: 0 | I17: 2 | J17: 3
A18: FA컵_16강 | B18: 레버쿠젠 | C18: 1 | D18: 1 | E18: 0 | F18: 0 | G18: 3 | H18: 2 | I18: 1 | J18: 3 | L18: UCL_C조
A19: FA컵_16강 | B19: PSV | C19: 1 | D19: 1 | E19: 0 | F19: 0 | G19: 3 | H19: 0 | I19: 3 | J19: 3 | L19: 팀명 | M19: 경기 | N19: 승 | O19: 무 | P19: 패 | Q19: 득점 | R19: 실점 | S19: 득실 | T19: 승점
A20: FA컵_16강 | B20: 인테르 | C20: 1 | D20: 1 | E20: 0 | F20: 0 | G20: 4 | H20: 0 | I20: 4 | J20: 3 | L20: {=_xlfn._xlws.SORT(_xlfn.CHOOSECOLS(_xlfn._xlws.FILTER(리그순위표[], ISNUMBER(SEARCH(L18, 리그순위표[대회 종류]))), 2, 3, 4, 5, 6, 7, 8, 9, 10), {9,8}, {-1,-1})} -> 인테르 | M20: 4 | N20: 4 | O20: 0 | P20: 0 | Q20: 15 | R20: 7 | S20: 8 | T20: 12
A21: FA컵_16강 | B21: 비야레알 | C21: 1 | D21: 1 | E21: 0 | F21: 0 | G21: 5 | H21: 0 | I21: 5 | J21: 3 | L21: PSV | M21: 4 | N21: 0 | O21: 2 | P21: 2 | Q21: 12 | R21: 15 | S21: -3 | T21: 2
A22: FA컵_16강 | B22: 뉴캐슬 유나이티드 | C22: 1 | D22: 1 | E22: 0 | F22: 0 | G22: 2 | H22: 1 | I22: 1 | J22: 3 | L22: 유벤투스 | M22: 4 | N22: 0 | O22: 2 | P22: 2 | Q22: 7 | R22: 12 | S22: -5 | T22: 2
A23: FA컵_16강 | B23: 첼시 | C23: 1 | D23: 0 | E23: 0 | F23: 1 | G23: 0 | H23: 2 | I23: -2 | J23: 0
A24: FA컵_16강 | B24: 아우크스부르크 | C24: 1 | D24: 0 | E24: 0 | F24: 1 | G24: 2 | H24: 3 | I24: -1 | J24: 0
A25: FA컵_16강 | B25: 유벤투스 | C25: 1 | D25: 0 | E25: 0 | F25: 1 | G25: 0 | H25: 3 | I25: -3 | J25: 0
A26: FA컵_16강 | B26: 레알 마드리드 | C26: 1 | D26: 0 | E26: 0 | F26: 1 | G26: 0 | H26: 4 | I26: -4 | J26: 0 | L26: UCL_D조
A27: FA컵_16강 | B27: 아틀레티코 마드리드 | C27: 1 | D27: 0 | E27: 0 | F27: 1 | G27: 0 | H27: 5 | I27: -5 | J27: 0 | L27: 팀명 | M27: 경기 | N27: 승 | O27: 무 | P27: 패 | Q27: 득점 | R27: 실점 | S27: 득실 | T27: 승점
A28: FA컵_4강 | B28: 인테르 | C28: 1 | D28: 1 | E28: 0 | F28: 0 | G28: 3 | H28: 0 | I28: 3 | J28: 3 | L28: {=_xlfn._xlws.SORT(_xlfn.CHOOSECOLS(_xlfn._xlws.FILTER(리그순위표[], ISNUMBER(SEARCH(L26, 리그순위표[대회 종류]))), 2, 3, 4, 5, 6, 7, 8, 9, 10), {9,8}, {-1,-1})} -> 비야레알 | M28: 4 | N28: 2 | O28: 2 | P28: 0 | Q28: 9 | R28: 5 | S28: 4 | T28: 8
A29: FA컵_4강 | B29: 도르트문트 | C29: 1 | D29: 1 | E29: 0 | F29: 0 | G29: 4 | H29: 2 | I29: 2 | J29: 3 | L29: 바이에른 뮌헨 | M29: 4 | N29: 1 | O29: 2 | P29: 1 | Q29: 7 | R29: 6 | S29: 1 | T29: 5
A30: FA컵_4강 | B30: 바이에른 뮌헨 | C30: 1 | D30: 0 | E30: 0 | F30: 1 | G30: 0 | H30: 3 | I30: -3 | J30: 0 | L30: 뉴캐슬 유나이티드 | M30: 4 | N30: 1 | O30: 0 | P30: 3 | Q30: 7 | R30: 12 | S30: -5 | T30: 3
A31: FA컵_4강 | B31: 비야레알 | C31: 1 | D31: 0 | E31: 0 | F31: 1 | G31: 2 | H31: 4 | I31: -2 | J31: 0
A32: FA컵_8강 | B32: 인테르 | C32: 1 | D32: 1 | E32: 0 | F32: 0 | G32: 2 | H32: 1 | I32: 1 | J32: 3
A33: FA컵_8강 | B33: 비야레알 | C33: 1 | D33: 1 | E33: 0 | F33: 0 | G33: 4 | H33: 3 | I33: 1 | J33: 3
A34: FA컵_8강 | B34: 바이에른 뮌헨 | C34: 1 | D34: 1 | E34: 0 | F34: 0 | G34: 5 | H34: 4 | I34: 1 | J34: 3
A35: FA컵_8강 | B35: 도르트문트 | C35: 1 | D35: 1 | E35: 0 | F35: 0 | G35: 7 | H35: 0 | I35: 7 | J35: 3
A36: FA컵_8강 | B36: 레버쿠젠 | C36: 1 | D36: 0 | E36: 0 | F36: 1 | G36: 1 | H36: 2 | I36: -1 | J36: 0
A37: FA컵_8강 | B37: 토트넘 | C37: 1 | D37: 0 | E37: 0 | F37: 1 | G37: 3 | H37: 4 | I37: -1 | J37: 0
A38: FA컵_8강 | B38: 뉴캐슬 유나이티드 | C38: 1 | D38: 0 | E38: 0 | F38: 1 | G38: 4 | H38: 5 | I38: -1 | J38: 0
A39: FA컵_8강 | B39: PSV | C39: 1 | D39: 0 | E39: 0 | F39: 1 | G39: 0 | H39: 7 | I39: -7 | J39: 0 | L39: {=_xlfn.UNIQUE(리그순위표[대회 종류])} -> 1부리그
A40: FA컵_결승전 | B40: 인테르 | C40: 1 | D40: 1 | E40: 0 | F40: 0 | G40: 3 | H40: 2 | I40: 1 | J40: 3 | L40: 2부리그
...

Sheet 득점왕DB
A1: 대회종류 | B1: 득점선수 | C1: 팀약자 | D1: 총득점
A2: 1부리그 | B2: 해리 케인 | C2: FCB | D2: 9
A3: 1부리그 | B3: 토마스 뮐러 | C3: FCB | D3: 12
A4: 1부리그 | B4: 티에르노 바리 | C4: VIL | D4: 6
A5: 1부리그 | B5: 살렘 알도사리 | C5: VIL | D5: 3 | F5: 1부리그 | J5: 2부리그 | N5: UCL | R5: FA컵
A6: 1부리그 | B6: 마르셀 자비처 | C6: BVB | D6: 1 | F6: {=_xlfn.TAKE(_xlfn._xlws.SORT(_xlfn.CHOOSECOLS(_xlfn._xlws.FILTER(득점데이터[], ISNUMBER(SEARCH("1부리그", 득점데이터[대회종류]))), 3, 2, 4), 3, -1), 10)} -> FCB | G6: 토마스 뮐러 | H6: 12 | J6: {=_xlfn.TAKE(_xlfn._xlws.SORT(_xlfn.CHOOSECOLS(_xlfn._xlws.FILTER(득점데이터[], ISNUMBER(SEARCH("2부리그", 득점데이터[대회종류]))), 3, 2, 4), 3, -1), 10)} -> LEV | K6: 차범근 | L6: 18 | N6: {=_xlfn.TAKE(_xlfn._xlws.SORT(_xlfn.CHOOSECOLS(_xlfn._xlws.FILTER(득점데이터[], ISNUMBER(SEARCH("UCL", 득점데이터[대회종류]))), 3, 2, 4), 3, -1), 5)} -> BVB | O6: 세루 기라시 | P6: 14 | R6: {=_xlfn.TAKE(_xlfn._xlws.SORT(_xlfn.CHOOSECOLS(_xlfn._xlws.FILTER(득점데이터[], ISNUMBER(SEARCH("FA", 득점데이터[대회종류]))), 3, 2, 4), 3, -1), 10)} -> BVB | S6: 세루 기라시 | T6: 5
A7: 1부리그 | B7: P.오바메양 | C7: BVB | D7: 9 | F7: INT | G7: 사뮈엘 에토 | H7: 10 | J7: RMA | K7: 크리스티아누 호날두 | L7: 15 | N7: INT | O7: 사뮈엘 에토 | P7: 12 | R7: INT | S7: 사뮈엘 에토 | T7: 4
A8: 1부리그 | B8: 로빈 반페르시 | C8: MUN | D8: 7 | F8: FCB | G8: 해리 케인 | H8: 9 | J8: ATM | K8: 모라타 | L8: 13 | N8: ATM | O8: 모라타 | P8: 9 | R8: VIL | S8: 잠보 앙기사 | T8: 3
A9: 1부리그 | B9: 웨인 루니 | C9: MUN | D9: 6 | F9: BVB | G9: P.오바메양 | H9: 9 | J9: LEV | K9: 플로리안 비르츠 | L9: 13 | N9: ATM | O9: 앙헬 코레아 | P9: 6 | R9: BVB | S9: P.오바메양 | T9: 3
A10: 1부리그 | B10: 조지 베스트 | C10: MUN | D10: 2 | F10: MUN | G10: 로빈 반페르시 | H10: 7 | J10: ATM | K10: 앙헬 코레아 | L10: 12 | N10: MUN | O10: 웨인 루니 | P10: 6 | R10: FCB | S10: 해리 케인 | T10: 3
A11: 1부리그 | B11: 카를로스 테베스 | C11: MUN | D11: 2 | F11: BVB | G11: 세루 기라시 | H11: 7 | J11: TOT | K11: 손흥민 | L11: 12 | R11: INT | S11: 사뮈엘 에토 | T11: 2
A12: 1부리그 | B12: 율리안 브란트 | C12: BVB | D12: 4 | F12: VIL | G12: 디에고 포를란 | H12: 7 | J12: PSV | K12: 뤼트 반니스텔로이 | L12: 10 | R12: NEW | S12: 앤서니 고든 | T12: 2
A13: 1부리그 | B13: 세루 기라시 | C13: BVB | D13: 7 | F13: VIL | G13: 티에르노 바리 | H13: 6 | J13: CHE | K13: 디디에 드로그바 | L13: 10 | R13: VIL | S13: 살렘 알도사리 | T13: 2
A14: 1부리그 | B14: A.크나우프 | C14: BVB | D14: 1 | F14: MUN | G14: 웨인 루니 | H14: 6 | J14: ATM | K14: 앙투안 그리즈만 | L14: 9 | R14: INT | S14: 마이콘 | T14: 2
A15: 1부리그 | B15: 사뮈엘 에토 | C15: INT | D15: 10 | F15: INT | G15: 로타어 마테우스 | H15: 5 | J15: TOT | K15: 해리 케인 | L15: 8 | R15: INT | S15: 하칸 찰하놀루 | T15: 2
A16: 1부리그 | B16: 로타어 마테우스 | C16: INT | D16: 5
A17: 1부리그 | B17: 케빈 캄플 | C17: BVB | D17: 1
A18: 1부리그 | B18: 요주아 키미히 | C18: FCB | D18: 2
A19: 1부리그 | B19: 디에고 포를란 | C19: VIL | D19: 7
A20: 1부리그 | B20: B.슈바인슈타이커 | C20: MUN | D20: 1
A21: 1부리그 | B21: 요안 위사 | C21: NEW | D21: 3
A22: 1부리그 | B22: 알렉산데르 이사크 | C22: NEW | D22: 4
A23: 1부리그 | B23: 알렉시스 산체스 | C23: MUN | D23: 1
A24: 1부리그 | B24: 애슐리 영 | C24: MUN | D24: 2
A25: 1부리그 | B25: 산드로 토날리 | C25: NEW | D25: 1
A26: 1부리그 | B26: 프랑크 리베리 | C26: FCB | D26: 4
A27: 1부리그 | B27: 헨릭 라르손 | C27: MUN | D27: 1
... A255: 승강PO | B255: 살렘 알도사리 | C255: VIL | D255: 2

Sheet LOGO_DB
A1: 열1 | B1: 파일ID | C1: 함수용주소를 DIRECT주소로 변경 | D1: 팀약자 | E1: 팀명 | F1: 사이즈30 | G1: 사이즈35 | H1: 사이즈60 | I1: 사이즈75 | J1: 사이즈85 | K1: 사이즈125
A2: https://drive.google.com/file/d/1M9fxr8vIra3-wxudAp0eIxc_vbVavLTI/view?usp=sharing | B2: =MID(시즌이미지12[[#This Row],[열1]],33,33) -> 1M9fxr8vIra3-wxudAp0eIxc_vbVavLTI | C2: ="https://lh3.googleusercontent.com/d/" & 시즌이미지12[[#This Row],[파일ID]] -> https://lh3.googleusercontent.com/d/1M9fxr8vIra3-wxudAp0eIxc_vbVavLTI | D2: INT | E2: 인테르 | F2: =_xlfn.IMAGE(시즌이미지12[[#This Row],[함수용주소를 DIRECT주소로 변경]],시즌이미지12[[#This Row],[팀약자]],3,30,30) -> #VALUE! | G2: =_xlfn.IMAGE(시즌이미지12[[#This Row],[함수용주소를 DIRECT주소로 변경]],시즌이미지12[[#This Row],[팀약자]],3,35,35) -> #VALUE! | H2: =_xlfn.IMAGE(시즌이미지12[[#This Row],[함수용주소를 DIRECT주소로 변경]],시즌이미지12[[#This Row],[팀약자]],3,60,60) -> #VALUE! | I2: =_xlfn.IMAGE(시즌이미지12[[#This Row],[함수용주소를 DIRECT주소로 변경]],시즌이미지12[[#This Row],[팀약자]],3,75,75) -> #VALUE! | J2: =_xlfn.IMAGE(시즌이미지12[[#This Row],[함수용주소를 DIRECT주소로 변경]],시즌이미지12[[#This Row],[팀약자]],3,85,85) -> #VALUE! | K2: =_xlfn.IMAGE(시즌이미지12[[#This Row],[함수용주소를 DIRECT주소로 변경]],시즌이미지12[[#This Row],[팀약자]],3,125,125) -> #VALUE!
A3: https://drive.google.com/file/d/1Oe0BhCDjicyhK-IVGrtw6-ZPssH0P_fL/view?usp=drive_link | B3: =MID(시즌이미지12[[#This Row],[열1]],33,33) -> 1Oe0BhCDjicyhK-IVGrtw6-ZPssH0P_fL | C3: ="https://lh3.googleusercontent.com/d/" & 시즌이미지12[[#This Row],[파일ID]] -> https://lh3.googleusercontent.com/d/1Oe0BhCDjicyhK-IVGrtw6-ZPssH0P_fL | D3: MUN | E3: 맨체스터 유나이티드 | F3: =_xlfn.IMAGE(시즌이미지12[[#This Row],[함수용주소를 DIRECT주소로 변경]],시즌이미지12[[#This Row],[팀약자]],3,30,30) -> #VALUE! | G3: =_xlfn.IMAGE(시즌이미지12[[#This Row],[함수용주소를 DIRECT주소로 변경]],시즌이미지12[[#This Row],[팀약자]],3,35,35) -> #VALUE! | H3: =_xlfn.IMAGE(시즌이미지12[[#This Row],[함수용주소를 DIRECT주소로 변경]],시즌이미지12[[#This Row],[팀약자]],3,60,60) -> #VALUE! | I3: =_xlfn.IMAGE(시즌이미지12[[#This Row],[함수용주소를 DIRECT주소로 변경]],시즌이미지12[[#This Row],[팀약자]],3,75,75) -> #VALUE! | J3: =_xlfn.IMAGE(시즌이미지12[[#This Row],[함수용주소를 DIRECT주소로 변경]],시즌이미지12[[#This Row],[팀약자]],3,85,85) -> #VALUE! | K3: =_xlfn.IMAGE(시즌이미지12[[#This Row],[함수용주소를 DIRECT주소로 변경]],시즌이미지12[[#This Row],[팀약자]],3,125,125) -> #VALUE! | Q3: 1 | R3: =Q3*37.8 -> 37.8
A4: https://drive.google.com/file/d/1ge87Wvv_Pnf5ZYWaeXGWOYysw8FtjQ7u/view?usp=sharing | B4: =MID(시즌이미지12[[#This Row],[열1]],33,33) -> 1ge87Wvv_Pnf5ZYWaeXGWOYysw8FtjQ7u | C4: ="https://lh3.googleusercontent.com/d/" & 시즌이미지12[[#This Row],[파일ID]] -> https://lh3.googleusercontent.com/d/1ge87Wvv_Pnf5ZYWaeXGWOYysw8FtjQ7u | D4: VIL | E4: 비야레알 | F4: =_xlfn.IMAGE(시즌이미지12[[#This Row],[함수용주소를 DIRECT주소로 변경]],시즌이미지12[[#This Row],[팀약자]],3,30,30) -> #VALUE! | G4: =_xlfn.IMAGE(시즌이미지12[[#This Row],[함수용주소를 DIRECT주소로 변경]],시즌이미지12[[#This Row],[팀약자]],3,35,35) -> #VALUE! | H4: =_xlfn.IMAGE(시즌이미지12[[#This Row],[함수용주소를 DIRECT주소로 변경]],시즌이미지12[[#This Row],[팀약자]],3,60,60) -> #VALUE! | I4: =_xlfn.IMAGE(시즌이미지12[[#This Row],[함수용주소를 DIRECT주소로 변경]],시즌이미지12[[#This Row],[팀약자]],3,75,75) -> #VALUE! | J4: =_xlfn.IMAGE(시즌이미지12[[#This Row],[함수용주소를 DIRECT주소로 변경]],시즌이미지12[[#This Row],[팀약자]],3,85,85) -> #VALUE! | K4: =_xlfn.IMAGE(시즌이미지12[[#This Row],[함수용주소를 DIRECT주소로 변경]],시즌이미지12[[#This Row],[팀약자]],3,125,125) -> #VALUE! | O4: 인테르 | P4: =VLOOKUP(O4,$E:$G,2,0) -> #VALUE! | Q4: 0.89 | R4: =Q4*37.8 -> 33.642
A5: https://drive.google.com/file/d/1HwPb8ze_CzGsa3OAt7rTCJvx3M1XEcXy/view?usp=drive_link | B5: =MID(시즌이미지12[[#This Row],[열1]],33,33) -> 1HwPb8ze_CzGsa3OAt7rTCJvx3M1XEcXy | C5: ="https://lh3.googleusercontent.com/d/" & 시즌이미지12[[#This Row],[파일ID]] -> https://lh3.googleusercontent.com/d/1HwPb8ze_CzGsa3OAt7rTCJvx3M1XEcXy | D5: BVB | E5: 도르트문트 | F5: =_xlfn.IMAGE(시즌이미지12[[#This Row],[함수용주소를 DIRECT주소로 변경]],시즌이미지12[[#This Row],[팀약자]],3,30,30) -> #VALUE! | G5: =_xlfn.IMAGE(시즌이미지12[[#This Row],[함수용주소를 DIRECT주소로 변경]],시즌이미지12[[#This Row],[팀약자]],3,35,35) -> #VALUE! | H5: =_xlfn.IMAGE(시즌이미지12[[#This Row],[함수용주소를 DIRECT주소로 변경]],시즌이미지12[[#This Row],[팀약자]],3,60,60) -> #VALUE! | I5: =_xlfn.IMAGE(시즌이미지12[[#This Row],[함수용주소를 DIRECT주소로 변경]],시즌이미지12[[#This Row],[팀약자]],3,75,75) -> #VALUE! | J5: =_xlfn.IMAGE(시즌이미지12[[#This Row],[함수용주소를 DIRECT주소로 변경]],시즌이미지12[[#This Row],[팀약자]],3,85,85) -> #VALUE! | K5: =_xlfn.IMAGE(시즌이미지12[[#This Row],[함수용주소를 DIRECT주소로 변경]],시즌이미지12[[#This Row],[팀약자]],3,125,125) -> #VALUE! | O5: 뉴캐슬 유나이티드 | P5: =VLOOKUP(O5,$E:$G,2,0) -> #VALUE! | Q5: 1.11 | R5: =Q5*37.8 -> 41.958
A6: https://drive.google.com/file/d/1519utytmvRS4xl2zaPa2g8Q1QmuqB8-6/view?usp=drive_link | B6: =MID(시즌이미지12[[#This Row],[열1]],33,33) -> 1519utytmvRS4xl2zaPa2g8Q1QmuqB8-6 | C6: ="https://lh3.googleusercontent.com/d/" & 시즌이미지12[[#This Row],[파일ID]] -> https://lh3.googleusercontent.com/d/1519utytmvRS4xl2zaPa2g8Q1QmuqB8-6 | D6: FCB | E6: 바이에른 뮌헨 | F6: =_xlfn.IMAGE(시즌이미지12[[#This Row],[함수용주소를 DIRECT주소로 변경]],시즌이미지12[[#This Row],[팀약자]],3,30,30) -> #VALUE! | G6: =_xlfn.IMAGE(시즌이미지12[[#This Row],[함수용주소를 DIRECT주소로 변경]],시즌이미지12[[#This Row],[팀약자]],3,35,35) -> #VALUE! | H6: =_xlfn.IMAGE(시즌이미지12[[#This Row],[함수용주소를 DIRECT주소로 변경]],시즌이미지12[[#This Row],[팀약자]],3,60,60) -> #VALUE! | I6: =_xlfn.IMAGE(시즌이미지12[[#This Row],[함수용주소를 DIRECT주소로 변경]],시즌이미지12[[#This Row],[팀약자]],3,75,75) -> #VALUE! | J6: =_xlfn.IMAGE(시즌이미지12[[#This Row],[함수용주소를 DIRECT주소로 변경]],시즌이미지12[[#This Row],[팀약자]],3,85,85) -> #VALUE! | K6: =_xlfn.IMAGE(시즌이미지12[[#This Row],[함수용주소를 DIRECT주소로 변경]],시즌이미지12[[#This Row],[팀약자]],3,125,125) -> #VALUE! | O6: 레버쿠젠 | P6: =VLOOKUP(O6,$E:$G,2,0) -> #VALUE!
A7: https://drive.google.com/file/d/1iFd6qnPGwIhKzVqy65GosRyat5ly6Sh7/view?usp=drive_link | B7: =MID(시즌이미지12[[#This Row],[열1]],33,33) -> 1iFd6qnPGwIhKzVqy65GosRyat5ly6Sh7 | C7: ="https://lh3.googleusercontent.com/d/" & 시즌이미지12[[#This Row],[파일ID]] -> https://lh3.googleusercontent.com/d/1iFd6qnPGwIhKzVqy65GosRyat5ly6Sh7 | D7: NEW | E7: 뉴캐슬 유나이티드 | F7: =_xlfn.IMAGE(시즌이미지12[[#This Row],[함수용주소를 DIRECT주소로 변경]],시즌이미지12[[#This Row],[팀약자]],3,30,30) -> #VALUE! | G7: =_xlfn.IMAGE(시즌이미지12[[#This Row],[함수용주소를 DIRECT주소로 변경]],시즌이미지12[[#This Row],[팀약자]],3,35,35) -> #VALUE! | H7: =_xlfn.IMAGE(시즌이미지12[[#This Row],[함수용주소를 DIRECT주소로 변경]],시즌이미지12[[#This Row],[팀약자]],3,60,60) -> #VALUE! | I7: =_xlfn.IMAGE(시즌이미지12[[#This Row],[함수용주소를 DIRECT주소로 변경]],시즌이미지12[[#This Row],[팀약자]],3,75,75) -> #VALUE! | J7: =_xlfn.IMAGE(시즌이미지12[[#This Row],[함수용주소를 DIRECT주소로 변경]],시즌이미지12[[#This Row],[팀약자]],3,85,85) -> #VALUE! | K7: =_xlfn.IMAGE(시즌이미지12[[#This Row],[함수용주소를 DIRECT주소로 변경]],시즌이미지12[[#This Row],[팀약자]],3,125,125) -> #VALUE! | O7: 레알 마드리드 | P7: =VLOOKUP(O7,$E:$G,2,0) -> #VALUE! | Q7: 0.81 | R7: =Q7*37.8 -> 30.618
A8: https://drive.google.com/file/d/1L7R-AGwnnP2FAQTYR8p5FhP8Q2LEuOii/view?usp=drive_link | B8: =MID(시즌이미지12[[#This Row],[열1]],33,33) -> 1L7R-AGwnnP2FAQTYR8p5FhP8Q2LEuOii | C8: ="https://lh3.googleusercontent.com/d/" & 시즌이미지12[[#This Row],[파일ID]] -> https://lh3.googleusercontent.com/d/1L7R-AGwnnP2FAQTYR8p5FhP8Q2LEuOii | D8: JUV | E8: 유벤투스 | F8: =_xlfn.IMAGE(시즌이미지12[[#This Row],[함수용주소를 DIRECT주소로 변경]],시즌이미지12[[#This Row],[팀약자]],3,30,30) -> #VALUE! | G8: =_xlfn.IMAGE(시즌이미지12[[#This Row],[함수용주소를 DIRECT주소로 변경]],시즌이미지12[[#This Row],[팀약자]],3,35,35) -> #VALUE! | H8: =_xlfn.IMAGE(시즌이미지12[[#This Row],[함수용주소를 DIRECT주소로 변경]],시즌이미지12[[#This Row],[팀약자]],3,60,60) -> #VALUE! | I8: =_xlfn.IMAGE(시즌이미지12[[#This Row],[함수용주소를 DIRECT주소로 변경]],시즌이미지12[[#This Row],[팀약자]],3,75,75) -> #VALUE! | J8: =_xlfn.IMAGE(시즌이미지12[[#This Row],[함수용주소를 DIRECT주소로 변경]],시즌이미지12[[#This Row],[팀약자]],3,85,85) -> #VALUE! | K8: =_xlfn.IMAGE(시즌이미지12[[#This Row],[함수용주소를 DIRECT주소로 변경]],시즌이미지12[[#This Row],[팀약자]],3,125,125) -> #VALUE! | O8: 맨체스터 시티 | P8: =VLOOKUP(O8,$E:$G,2,0) -> #VALUE! | Q8: 1.31 | R8: =Q8*37.8 -> 49.518
A9: https://drive.google.com/file/d/11c6WyuJLUdxz7mxUlQhrs7DgvFSWT0qP/view?usp=drive_link | B9: =MID(시즌이미지12[[#This Row],[열1]],33,33) -> 11c6WyuJLUdxz7mxUlQhrs7DgvFSWT0qP | C9: ="https://lh3.googleusercontent.com/d/" & 시즌이미지12[[#This Row],[파일ID]] -> https://lh3.googleusercontent.com/d/11c6WyuJLUdxz7mxUlQhrs7DgvFSWT0qP | D9: ATM | E9: 아틀레티코 마드리드 | F9: =_xlfn.IMAGE(시즌이미지12[[#This Row],[함수용주소를 DIRECT주소로 변경]],시즌이미지12[[#This Row],[팀약자]],3,30,30) -> #VALUE! | G9: =_xlfn.IMAGE(시즌이미지12[[#This Row],[함수용주소를 DIRECT주소로 변경]],시즌이미지12[[#This Row],[팀약자]],3,35,35) -> #VALUE! | H9: =_xlfn.IMAGE(시즌이미지12[[#This Row],[함수용주소를 DIRECT주소로 변경]],시즌이미지12[[#This Row],[팀약자]],3,60,60) -> #VALUE! | I9: =_xlfn.IMAGE(시즌이미지12[[#This Row],[함수용주소를 DIRECT주소로 변경]],시즌이미지12[[#This Row],[팀약자]],3,75,75) -> #VALUE! | J9: =_xlfn.IMAGE(시즌이미지12[[#This Row],[함수용주소를 DIRECT주소로 변경]],시즌이미지12[[#This Row],[팀약자]],3,85,85) -> #VALUE! | K9: =_xlfn.IMAGE(시즌이미지12[[#This Row],[함수용주소를 DIRECT주소로 변경]],시즌이미지12[[#This Row],[팀약자]],3,125,125) -> #VALUE! | O9: 바이에른 뮌헨 | P9: =VLOOKUP(O9,$E:$G,2,0) -> #VALUE!
A10: https://drive.google.com/file/d/1SKe5OyMGBddKNxXQwIfpEz-m5Sugr9Wf/view?usp=drive_link | B10: =MID(시즌이미지12[[#This Row],[열1]],33,33) -> 1SKe5OyMGBddKNxXQwIfpEz-m5Sugr9Wf | C10: ="https://lh3.googleusercontent.com/d/" & 시즌이미지12[[#This Row],[파일ID]] -> https://lh3.googleusercontent.com/d/1SKe5OyMGBddKNxXQwIfpEz-m5Sugr9Wf | D10: FRA | E10: 프랑크푸르트 | F10: =_xlfn.IMAGE(시즌이미지12[[#This Row],[함수용주소를 DIRECT주소로 변경]],시즌이미지12[[#This Row],[팀약자]],3,30,30) -> #VALUE! | G10: =_xlfn.IMAGE(시즌이미지12[[#This Row],[함수용주소를 DIRECT주소로 변경]],시즌이미지12[[#This Row],[팀약자]],3,35,35) -> #VALUE! | H10: =_xlfn.IMAGE(시즌이미지12[[#This Row],[함수용주소를 DIRECT주소로 변경]],시즌이미지12[[#This Row],[팀약자]],3,60,60) -> #VALUE! | I10: =_xlfn.IMAGE(시즌이미지12[[#This Row],[함수용주소를 DIRECT주소로 변경]],시즌이미지12[[#This Row],[팀약자]],3,75,75) -> #VALUE! | J10: =_xlfn.IMAGE(시즌이미지12[[#This Row],[함수용주소를 DIRECT주소로 변경]],시즌이미지12[[#This Row],[팀약자]],3,85,85) -> #VALUE! | K10: =_xlfn.IMAGE(시즌이미지12[[#This Row],[함수용주소를 DIRECT주소로 변경]],시즌이미지12[[#This Row],[팀약자]],3,125,125) -> #VALUE! | O10: 에버튼 | P10: =VLOOKUP(O10,$E:$G,2,0) -> #VALUE!
A11: https://drive.google.com/file/d/16Igzwna8V9A1zCIj2LH_SVzn_zyXUNou/view?usp=drive_link | B11: =MID(시즌이미지12[[#This Row],[열1]],33,33) -> 16Igzwna8V9A1zCIj2LH_SVzn_zyXUNou | C11: ="https://lh3.googleusercontent.com/d/" & 시즌이미지12[[#This Row],[파일ID]] -> https://lh3.googleusercontent.com/d/16Igzwna8V9A1zCIj2LH_SVzn_zyXUNou | D11: RMA | E11: 레알 마드리드 | F11: =_xlfn.IMAGE(시즌이미지12[[#This Row],[함수용주소를 DIRECT주소로 변경]],시즌이미지12[[#This Row],[팀약자]],3,30,30) -> #VALUE! | G11: =_xlfn.IMAGE(시즌이미지12[[#This Row],[함수용주소를 DIRECT주소로 변경]],시즌이미지12[[#This Row],[팀약자]],3,35,35) -> #VALUE! | H11: =_xlfn.IMAGE(시즌이미지12[[#This Row],[함수용주소를 DIRECT주소로 변경]],시즌이미지12[[#This Row],[팀약자]],3,60,60) -> #VALUE! | I11: =_xlfn.IMAGE(시즌이미지12[[#This Row],[함수용주소를 DIRECT주소로 변경]],시즌이미지12[[#This Row],[팀약자]],3,75,75) -> #VALUE! | J11: =_xlfn.IMAGE(시즌이미지12[[#This Row],[함수용주소를 DIRECT주소로 변경]],시즌이미지12[[#This Row],[팀약자]],3,85,85) -> #VALUE! | K11: =_xlfn.IMAGE(시즌이미지12[[#This Row],[함수용주소를 DIRECT주소로 변경]],시즌이미지12[[#This Row],[팀약자]],3,125,125) -> #VALUE! | O11: 첼시 | P11: =VLOOKUP(O11,$E:$G,2,0) -> #VALUE!
A12: https://drive.google.com/file/d/1-xM88c12LfhN6A_Kx3bVzMUA12_zaPIB/view?usp=drive_link | B12: =MID(시즌이미지12[[#This Row],[열1]],33,33) -> 1-xM88c12LfhN6A_Kx3bVzMUA12_zaPIB | C12: ="https://lh3.googleusercontent.com/d/" & 시즌이미지12[[#This Row],[파일ID]] -> https://lh3.googleusercontent.com/d/1-xM88c12LfhN6A_Kx3bVzMUA12_zaPIB | D12: LEV | E12: 레버쿠젠 | F12: =_xlfn.IMAGE(시즌이미지12[[#This Row],[함수용주소를 DIRECT주소로 변경]],시즌이미지12[[#This Row],[팀약자]],3,30,30) -> #VALUE! | G12: =_xlfn.IMAGE(시즌이미지12[[#This Row],[함수용주소를 DIRECT주소로 변경]],시즌이미지12[[#This Row],[팀약자]],3,35,35) -> #VALUE! | H12: =_xlfn.IMAGE(시즌이미지12[[#This Row],[함수용주소를 DIRECT주소로 변경]],시즌이미지12[[#This Row],[팀약자]],3,60,60) -> #VALUE! | I12: =_xlfn.IMAGE(시즌이미지12[[#This Row],[함수용주소를 DIRECT주소로 변경]],시즌이미지12[[#This Row],[팀약자]],3,75,75) -> #VALUE! | J12: =_xlfn.IMAGE(시즌이미지12[[#This Row],[함수용주소를 DIRECT주소로 변경]],시즌이미지12[[#This Row],[팀약자]],3,85,85) -> #VALUE! | K12: =_xlfn.IMAGE(시즌이미지12[[#This Row],[함수용주소를 DIRECT주소로 변경]],시즌이미지12[[#This Row],[팀약자]],3,125,125) -> #VALUE! | O12: 토트넘 | P12: =VLOOKUP(O12,$E:$G,2,0) -> #VALUE!
A13: https://drive.google.com/file/d/1IUr8XVjhXjb8iRVpKQP5gbsU2h9bWVo-/view?usp=drive_link | B13: =MID(시즌이미지12[[#This Row],[열1]],33,33) -> 1IUr8XVjhXjb8iRVpKQP5gbsU2h9bWVo- | C13: ="https://lh3.googleusercontent.com/d/" & 시즌이미지12[[#This Row],[파일ID]] -> https://lh3.googleusercontent.com/d/1IUr8XVjhXjb8iRVpKQP5gbsU2h9bWVo- | D13: MAI | E13: 마인츠 | F13: =_xlfn.IMAGE(시즌이미지12[[#This Row],[함수용주소를 DIRECT주소로 변경]],시즌이미지12[[#This Row],[팀약자]],3,30,30) -> #VALUE! | G13: =_xlfn.IMAGE(시즌이미지12[[#This Row],[함수용주소를 DIRECT주소로 변경]],시즌이미지12[[#This Row],[팀약자]],3,35,35) -> #VALUE! | H13: =_xlfn.IMAGE(시즌이미지12[[#This Row],[함수용주소를 DIRECT주소로 변경]],시즌이미지12[[#This Row],[팀약자]],3,60,60) -> #VALUE! | I13: =_xlfn.IMAGE(시즌이미지12[[#This Row],[함수용주소를 DIRECT주소로 변경]],시즌이미지12[[#This Row],[팀약자]],3,75,75) -> #VALUE! | J13: =_xlfn.IMAGE(시즌이미지12[[#This Row],[함수용주소를 DIRECT주소로 변경]],시즌이미지12[[#This Row],[팀약자]],3,85,85) -> #VALUE! | K13: =_xlfn.IMAGE(시즌이미지12[[#This Row],[함수용주소를 DIRECT주소로 변경]],시즌이미지12[[#This Row],[팀약자]],3,125,125) -> #VALUE! | O13: 프랑크푸르트 | P13: =VLOOKUP(O13,$E:$G,2,0) -> #VALUE!
A14: https://drive.google.com/file/d/1U2lyqdhQ8teY7GxDVjB4UxcoP8PlKZyL/view?usp=drive_link | B14: =MID(시즌이미지12[[#This Row],[열1]],33,33) -> 1U2lyqdhQ8teY7GxDVjB4UxcoP8PlKZyL | C14: ="https://lh3.googleusercontent.com/d/" & 시즌이미지12[[#This Row],[파일ID]] -> https://lh3.googleusercontent.com/d/1U2lyqdhQ8teY7GxDVjB4UxcoP8PlKZyL | D14: PSG | E14: 파리 생제르망 | F14: =_xlfn.IMAGE(시즌이미지12[[#This Row],[함수용주소를 DIRECT주소로 변경]],시즌이미지12[[#This Row],[팀약자]],3,30,30) -> #VALUE! | G14: =_xlfn.IMAGE(시즌이미지12[[#This Row],[함수용주소를 DIRECT주소로 변경]],시즌이미지12[[#This Row],[팀약자]],3,35,35) -> #VALUE! | H14: =_xlfn.IMAGE(시즌이미지12[[#This Row],[함수용주소를 DIRECT주소로 변경]],시즌이미지12[[#This Row],[팀약자]],3,60,60) -> #VALUE! | I14: =_xlfn.IMAGE(시즌이미지12[[#This Row],[함수용주소를 DIRECT주소로 변경]],시즌이미지12[[#This Row],[팀약자]],3,75,75) -> #VALUE! | J14: =_xlfn.IMAGE(시즌이미지12[[#This Row],[함수용주소를 DIRECT주소로 변경]],시즌이미지12[[#This Row],[팀약자]],3,85,85) -> #VALUE! | K14: =_xlfn.IMAGE(시즌이미지12[[#This Row],[함수용주소를 DIRECT주소로 변경]],시즌이미지12[[#This Row],[팀약자]],3,125,125) -> #VALUE! | O14: 호펜하임 | P14: =VLOOKUP(O14,$E:$G,2,0) -> #VALUE!
A15: https://drive.google.com/file/d/1U2lyqdhQ8teY7GxDVjB4UxcoP8PlKZyL/view?usp=sharing | B15: =MID(시즌이미지12[[#This Row],[열1]],33,33) -> 1U2lyqdhQ8teY7GxDVjB4UxcoP8PlKZyL | C15: ="https://lh3.googleusercontent.com/d/" & 시즌이미지12[[#This Row],[파일ID]] -> https://lh3.googleusercontent.com/d/1U2lyqdhQ8teY7GxDVjB4UxcoP8PlKZyL | D15: PSV | E15: PSV | F15: =_xlfn.IMAGE(시즌이미지12[[#This Row],[함수용주소를 DIRECT주소로 변경]],시즌이미지12[[#This Row],[팀약자]],3,30,30) -> #VALUE! | G15: =_xlfn.IMAGE(시즌이미지12[[#This Row],[함수용주소를 DIRECT주소로 변경]],시즌이미지12[[#This Row],[팀약자]],3,35,35) -> #VALUE! | H15: =_xlfn.IMAGE(시즌이미지12[[#This Row],[함수용주소를 DIRECT주소로 변경]],시즌이미지12[[#This Row],[팀약자]],3,60,60) -> #VALUE! | I15: =_xlfn.IMAGE(시즌이미지12[[#This Row],[함수용주소를 DIRECT주소로 변경]],시즌이미지12[[#This Row],[팀약자]],3,75,75) -> #VALUE! | J15: =_xlfn.IMAGE(시즌이미지12[[#This Row],[함수용주소를 DIRECT주소로 변경]],시즌이미지12[[#This Row],[팀약자]],3,85,85) -> #VALUE! | K15: =_xlfn.IMAGE(시즌이미지12[[#This Row],[함수용주소를 DIRECT주소로 변경]],시즌이미지12[[#This Row],[팀약자]],3,125,125) -> #VALUE! | O15: AS로마 | P15: =VLOOKUP(O15,$E:$G,2,0) -> #VALUE!
A16: https://drive.google.com/file/d/15Jk32I9lJNP8cC4KdRw58yytaI76oZE8/view?usp=sharing | B16: =MID(시즌이미지12[[#This Row],[열1]],33,33) -> 15Jk32I9lJNP8cC4KdRw58yytaI76oZE8 | C16: ="https://lh3.googleusercontent.com/d/" & 시즌이미지12[[#This Row],[파일ID]] -> https://lh3.googleusercontent.com/d/15Jk32I9lJNP8cC4KdRw58yytaI76oZE8 | D16: CHE | E16: 첼시 | F16: =_xlfn.IMAGE(시즌이미지12[[#This Row],[함수용주소를 DIRECT주소로 변경]],시즌이미지12[[#This Row],[팀약자]],3,30,30) -> #VALUE! | G16: =_xlfn.IMAGE(시즌이미지12[[#This Row],[함수용주소를 DIRECT주소로 변경]],시즌이미지12[[#This Row],[팀약자]],3,35,35) -> #VALUE! | H16: =_xlfn.IMAGE(시즌이미지12[[#This Row],[함수용주소를 DIRECT주소로 변경]],시즌이미지12[[#This Row],[팀약자]],3,60,60) -> #VALUE! | I16: =_xlfn.IMAGE(시즌이미지12[[#This Row],[함수용주소를 DIRECT주소로 변경]],시즌이미지12[[#This Row],[팀약자]],3,75,75) -> #VALUE! | J16: =_xlfn.IMAGE(시즌이미지12[[#This Row],[함수용주소를 DIRECT주소로 변경]],시즌이미지12[[#This Row],[팀약자]],3,85,85) -> #VALUE! | K16: =_xlfn.IMAGE(시즌이미지12[[#This Row],[함수용주소를 DIRECT주소로 변경]],시즌이미지12[[#This Row],[팀약자]],3,125,125) -> #VALUE! | O16: 아틀레티코 마드리드 | P16: =VLOOKUP(O16,$E:$G,2,0) -> #VALUE!
A17: https://drive.google.com/file/d/1bi38oQzJZmM_zgV9xrx2IhY2jEEggOfr/view?usp=sharing | B17: =MID(시즌이미지12[[#This Row],[열1]],33,33) -> 1bi38oQzJZmM_zgV9xrx2IhY2jEEggOfr | C17: ="https://lh3.googleusercontent.com/d/" & 시즌이미지12[[#This Row],[파일ID]] -> https://lh3.googleusercontent.com/d/1bi38oQzJZmM_zgV9xrx2IhY2jEEggOfr | D17: NAP | E17: 나폴리 | F17: =_xlfn.IMAGE(시즌이미지12[[#This Row],[함수용주소를 DIRECT주소로 변경]],시즌이미지12[[#This Row],[팀약자]],3,30,30) -> #VALUE! | G17: =_xlfn.IMAGE(시즌이미지12[[#This Row],[함수용주소를 DIRECT주소로 변경]],시즌이미지12[[#This Row],[팀약자]],3,35,35) -> #VALUE! | H17: =_xlfn.IMAGE(시즌이미지12[[#This Row],[함수용주소를 DIRECT주소로 변경]],시즌이미지12[[#This Row],[팀약자]],3,60,60) -> #VALUE! | I17: =_xlfn.IMAGE(시즌이미지12[[#This Row],[함수용주소를 DIRECT주소로 변경]],시즌이미지12[[#This Row],[팀약자]],3,75,75) -> #VALUE! | J17: =_xlfn.IMAGE(시즌이미지12[[#This Row],[함수용주소를 DIRECT주소로 변경]],시즌이미지12[[#This Row],[팀약자]],3,85,85) -> #VALUE! | K17: =_xlfn.IMAGE(시즌이미지12[[#This Row],[함수용주소를 DIRECT주소로 변경]],시즌이미지12[[#This Row],[팀약자]],3,125,125) -> #VALUE! | O17: 유벤투스 | P17: =VLOOKUP(O17,$E:$G,2,0) -> #VALUE!
A18: https://drive.google.com/file/d/1AhfPLy_ylqn97PSBCvL9iCvaX24fE7-9/view?usp=sharing | B18: =MID(시즌이미지12[[#This Row],[열1]],33,33) -> 1AhfPLy_ylqn97PSBCvL9iCvaX24fE7-9 | C18: ="https://lh3.googleusercontent.com/d/" & 시즌이미지12[[#This Row],[파일ID]] -> https://lh3.googleusercontent.com/d/1AhfPLy_ylqn97PSBCvL9iCvaX24fE7-9 | D18: WOB | E18: 볼프스부르크 | F18: =_xlfn.IMAGE(시즌이미지12[[#This Row],[함수용주소를 DIRECT주소로 변경]],시즌이미지12[[#This Row],[팀약자]],3,30,30) -> #VALUE! | G18: =_xlfn.IMAGE(시즌이미지12[[#This Row],[함수용주소를 DIRECT주소로 변경]],시즌이미지12[[#This Row],[팀약자]],3,35,35) -> #VALUE! | H18: =_xlfn.IMAGE(시즌이미지12[[#This Row],[함수용주소를 DIRECT주소로 변경]],시즌이미지12[[#This Row],[팀약자]],3,60,60) -> #VALUE! | I18: =_xlfn.IMAGE(시즌이미지12[[#This Row],[함수용주소를 DIRECT주소로 변경]],시즌이미지12[[#This Row],[팀약자]],3,75,75) -> #VALUE! | J18: =_xlfn.IMAGE(시즌이미지12[[#This Row],[함수용주소를 DIRECT주소로 변경]],시즌이미지12[[#This Row],[팀약자]],3,85,85) -> #VALUE! | K18: =_xlfn.IMAGE(시즌이미지12[[#This Row],[함수용주소를 DIRECT주소로 변경]],시즌이미지12[[#This Row],[팀약자]],3,125,125) -> #VALUE! | O18: 나폴리 | P18: =VLOOKUP(O18,$E:$G,2,0) -> #VALUE!
