Workbook
Name 슬라이서_상대팀: #N/A
Name 슬라이서_상대팀1: #N/A
Name 슬라이서_팀: #N/A
Name 슬라이서_팀1: #N/A

Sheet 내경기 진행상황
B2: ☆ 1부리그 ☆ | E2: ☆ 챔피언스 리그 ☆ | J2: ☆ FA컵 ☆
B4: 팀명 | C4: 1경기 | E4: C조 | F4: 1경기 | G4: 2경기
B5: 도르트문트 | C5: ='1부리그'!Q11 -> 패 | E5: 유벤투스 | F5: =UCL!T57 -> 승 | G5: =UCL!T58 -> 승 | J5: [14강] 레알 마드리드 | K5: 4:0 승
B6: 도르트문트 | C6: ='1부리그'!Q12 -> 패 | E6: PSV | F6: =UCL!O61 -> 승 | G6: =UCL!O62 -> 승 | J6: [8강] 레버쿠젠 | K6: 2:1 승
B7: 뉴캐슬 | C7: ='1부리그'!Q13 -> 승 | E7: [8강] | J7: [4강]
B8: 뉴캐슬 | C8: ='1부리그'!Q14 -> 패 | E8: [4강] | J8: [결승]
B9: 맨유 | C9: ='1부리그'!Q15 -> 무 | E9: [결승]
B10: 맨유 | C10: ='1부리그'!Q16 -> 승
B11: 비야레알 | C11: ='1부리그'!Q17 -> 패
B12: 비야레알 | C12: ='1부리그'!Q18 -> 무
B13: 뮌헨 | C13: ='1부리그'!Q19 -> 무
B14: 뮌헨 | C14: ='1부리그'!Q20 -> 승

Sheet 1부리그
B2: 순위 | C2: 팀명 | D2: 승 점 | E2: 경기 | F2: 승 | G2: 무 | H2: 패 | I2: 득점 | J2: 실점 | K2: 득실 | M2: 경기당 승점 | N2: 최대 승점
B3: 1 | C3: {=_xlfn._xlws.SORT(_xlfn._xlws.SORT(_xlfn._xlws.SORT(_xlfn._xlws.SORT((_xlfn._xlws.FILTER(표1부리그[],표1부리그[경기]>(-1),)),9,-1),7,-1),8,1),2,-1)} -> 도르트문트 | D3: 21 | E3: 10 | F3: 7 | G3: 0 | H3: 3 | I3: 31 | J3: 26 | K3: 5 | M3: =IFERROR(D3/E3,0) -> 2.1 | N3: =(10-E3)*3+D3 -> 21
B4: 2 | C4: 비야레알 | D4: 15 | E4: 8 | F4: 4 | G4: 3 | H4: 1 | I4: 20 | J4: 15 | K4: 5 | M4: =IFERROR(D4/E4,0) -> 1.875 | N4: =(10-E4)*3+D4 -> 21
B5: 3 | C5: 맨유 | D5: 12 | E5: 8 | F5: 3 | G5: 3 | H5: 2 | I5: 17 | J5: 15 | K5: 2 | M5: =IFERROR(D5/E5,0) -> 1.5 | N5: =(10-E5)*3+D5 -> 18
B6: 4 | C6: 인테르 | D6: 12 | E6: 10 | F6: 3 | G6: 3 | H6: 4 | I6: 18 | J6: 20 | K6: -2 | M6: =IFERROR(D6/E6,0) -> 1.2 | N6: =(10-E6)*3+D6 -> 12
B7: 5 | C7: 뮌헨 | D7: 4 | E7: 4 | F7: 1 | G7: 1 | H7: 2 | I7: 7 | J7: 8 | K7: -1 | M7: =IFERROR(D7/E7,0) -> 1 | N7: =(10-E7)*3+D7 -> 22
B8: 6 | C8: 뉴캐슬 | D8: 3 | E8: 8 | F8: 1 | G8: 0 | H8: 7 | I8: 14 | J8: 23 | K8: -9 | M8: =IFERROR(D8/E8,0) -> 0.375 | N8: =(10-E8)*3+D8 -> 9
P10: NO | Q10: 결과 | R10: 팀 | S10: 득점 | T10: 실점 | U10: 상대팀
P11: 1 | Q11: =IF(표1부리그경기결과[[#This Row],[득점]]="","미진행",IF(표1부리그경기결과[[#This Row],[득점]]>표1부리그경기결과[[#This Row],[실점]],"승",IF(표1부리그경기결과[[#This Row],[득점]]=표1부리그경기결과[[#This Row],[실점]],"무",IF(표1부리그경기결과[[#This Row],[득점]]<표1부리그경기결과[[#This Row],[실점]],"패","미진행")))) -> 패 | R11: 인테르 | S11: 2 | T11: 4 | U11: 도르트문트
P12: 2 | Q12: =IF(표1부리그경기결과[[#This Row],[득점]]="","미진행",IF(표1부리그경기결과[[#This Row],[득점]]>표1부리그경기결과[[#This Row],[실점]],"승",IF(표1부리그경기결과[[#This Row],[득점]]=표1부리그경기결과[[#This Row],[실점]],"무",IF(표1부리그경기결과[[#This Row],[득점]]<표1부리그경기결과[[#This Row],[실점]],"패","미진행")))) -> 패 | R12: 인테르 | S12: 2 | T12: 3 | U12: 도르트문트
P13: 3 | Q13: =IF(표1부리그경기결과[[#This Row],[득점]]="","미진행",IF(표1부리그경기결과[[#This Row],[득점]]>표1부리그경기결과[[#This Row],[실점]],"승",IF(표1부리그경기결과[[#This Row],[득점]]=표1부리그경기결과[[#This Row],[실점]],"무",IF(표1부리그경기결과[[#This Row],[득점]]<표1부리그경기결과[[#This Row],[실점]],"패","미진행")))) -> 승 | R13: 인테르 | S13: 2 | T13: 0 | U13: 뉴캐슬
P14: 4 | Q14: =IF(표1부리그경기결과[[#This Row],[득점]]="","미진행",IF(표1부리그경기결과[[#This Row],[득점]]>표1부리그경기결과[[#This Row],[실점]],"승",IF(표1부리그경기결과[[#This Row],[득점]]=표1부리그경기결과[[#This Row],[실점]],"무",IF(표1부리그경기결과[[#This Row],[득점]]<표1부리그경기결과[[#This Row],[실점]],"패","미진행")))) -> 패 | R14: 인테르 | S14: 1 | T14: 3 | U14: 뉴캐슬
P15: 5 | Q15: =IF(표1부리그경기결과[[#This Row],[득점]]="","미진행",IF(표1부리그경기결과[[#This Row],[득점]]>표1부리그경기결과[[#This Row],[실점]],"승",IF(표1부리그경기결과[[#This Row],[득점]]=표1부리그경기결과[[#This Row],[실점]],"무",IF(표1부리그경기결과[[#This Row],[득점]]<표1부리그경기결과[[#This Row],[실점]],"패","미진행")))) -> 무 | R15: 인테르 | S15: 2 | T15: 2 | U15: 맨유
P16: 6 | Q16: =IF(표1부리그경기결과[[#This Row],[득점]]="","미진행",IF(표1부리그경기결과[[#This Row],[득점]]>표1부리그경기결과[[#This Row],[실점]],"승",IF(표1부리그경기결과[[#This Row],[득점]]=표1부리그경기결과[[#This Row],[실점]],"무",IF(표1부리그경기결과[[#This Row],[득점]]<표1부리그경기결과[[#This Row],[실점]],"패","미진행")))) -> 승 | R16: 인테르 | S16: 1 | T16: 0 | U16: 맨유
P17: 7 | Q17: =IF(표1부리그경기결과[[#This Row],[득점]]="","미진행",IF(표1부리그경기결과[[#This Row],[득점]]>표1부리그경기결과[[#This Row],[실점]],"승",IF(표1부리그경기결과[[#This Row],[득점]]=표1부리그경기결과[[#This Row],[실점]],"무",IF(표1부리그경기결과[[#This Row],[득점]]<표1부리그경기결과[[#This Row],[실점]],"패","미진행")))) -> 패 | R17: 인테르 | S17: 1 | T17: 3 | U17: 비야레알
P18: 8 | Q18: =IF(표1부리그경기결과[[#This Row],[득점]]="","미진행",IF(표1부리그경기결과[[#This Row],[득점]]>표1부리그경기결과[[#This Row],[실점]],"승",IF(표1부리그경기결과[[#This Row],[득점]]=표1부리그경기결과[[#This Row],[실점]],"무",IF(표1부리그경기결과[[#This Row],[득점]]<표1부리그경기결과[[#This Row],[실점]],"패","미진행")))) -> 무 | R18: 인테르 | S18: 3 | T18: 3 | U18: 비야레알
P19: 9 | Q19: =IF(표1부리그경기결과[[#This Row],[득점]]="","미진행",IF(표1부리그경기결과[[#This Row],[득점]]>표1부리그경기결과[[#This Row],[실점]],"승",IF(표1부리그경기결과[[#This Row],[득점]]=표1부리그경기결과[[#This Row],[실점]],"무",IF(표1부리그경기결과[[#This Row],[득점]]<표1부리그경기결과[[#This Row],[실점]],"패","미진행")))) -> 무 | R19: 인테르 | S19: 2 | T19: 2 | U19: 뮌헨
P20: 10 | Q20: =IF(표1부리그경기결과[[#This Row],[득점]]="","미진행",IF(표1부리그경기결과[[#This Row],[득점]]>표1부리그경기결과[[#This Row],[실점]],"승",IF(표1부리그경기결과[[#This Row],[득점]]=표1부리그경기결과[[#This Row],[실점]],"무",IF(표1부리그경기결과[[#This Row],[득점]]<표1부리그경기결과[[#This Row],[실점]],"패","미진행")))) -> 승 | R20: 인테르 | S20: 2 | T20: 0 | U20: 뮌헨
P21: 11 | Q21: =IF(표1부리그경기결과[[#This Row],[득점]]="","미진행",IF(표1부리그경기결과[[#This Row],[득점]]>표1부리그경기결과[[#This Row],[실점]],"승",IF(표1부리그경기결과[[#This Row],[득점]]=표1부리그경기결과[[#This Row],[실점]],"무",IF(표1부리그경기결과[[#This Row],[득점]]<표1부리그경기결과[[#This Row],[실점]],"패","미진행")))) -> 패 | R21: 뉴캐슬 | S21: 3 | T21: 4 | U21: 도르트문트
P22: 12 | Q22: =IF(표1부리그경기결과[[#This Row],[득점]]="","미진행",IF(표1부리그경기결과[[#This Row],[득점]]>표1부리그경기결과[[#This Row],[실점]],"승",IF(표1부리그경기결과[[#This Row],[득점]]=표1부리그경기결과[[#This Row],[실점]],"무",IF(표1부리그경기결과[[#This Row],[득점]]<표1부리그경기결과[[#This Row],[실점]],"패","미진행")))) -> 패 | R22: 뉴캐슬 | S22: 3 | T22: 4 | U22: 도르트문트
... P28: 18 | Q28: =IF(표1부리그경기결과[[#This Row],[득점]]="","미진행",IF(표1부리그경기결과[[#This Row],[득점]]>표1부리그경기결과[[#This Row],[실점]],"승",IF(표1부리그경기결과[[#This Row],[득점]]=표1부리그경기결과[[#This Row],[실점]],"무",IF(표1부리그경기결과[[#This Row],[득점]]<표1부리그경기결과[[#This Row],[실점]],"패","미진행")))) -> 패 | R28: 뉴캐슬 | S28: 1 | T28: 2 | U28: 비야레알
P29: 19 | Q29: =IF(표1부리그경기결과[[#This Row],[득점]]="","미진행",IF(표1부리그경기결과[[#This Row],[득점]]>표1부리그경기결과[[#This Row],[실점]],"승",IF(표1부리그경기결과[[#This Row],[득점]]=표1부리그경기결과[[#This Row],[실점]],"무",IF(표1부리그경기결과[[#This Row],[득점]]<표1부리그경기결과[[#This Row],[실점]],"패","미진행")))) -> 미진행 | R29: 뉴캐슬 | U29: 뮌헨
P30: 20 | Q30: =IF(표1부리그경기결과[[#This Row],[득점]]="","미진행",IF(표1부리그경기결과[[#This Row],[득점]]>표1부리그경기결과[[#This Row],[실점]],"승",IF(표1부리그경기결과[[#This Row],[득점]]=표1부리그경기결과[[#This Row],[실점]],"무",IF(표1부리그경기결과[[#This Row],[득점]]<표1부리그경기결과[[#This Row],[실점]],"패","미진행")))) -> 미진행 | R30: 뉴캐슬 | U30: 뮌헨
P31: 21 | Q31: =IF(표1부리그경기결과[[#This Row],[득점]]="","미진행",IF(표1부리그경기결과[[#This Row],[득점]]>표1부리그경기결과[[#This Row],[실점]],"승",IF(표1부리그경기결과[[#This Row],[득점]]=표1부리그경기결과[[#This Row],[실점]],"무",IF(표1부리그경기결과[[#This Row],[득점]]<표1부리그경기결과[[#This Row],[실점]],"패","미진행")))) -> 패 | R31: 맨유 | S31: 0 | T31: 4 | U31: 도르트문트
P32: 22 | Q32: =IF(표1부리그경기결과[[#This Row],[득점]]="","미진행",IF(표1부리그경기결과[[#This Row],[득점]]>표1부리그경기결과[[#This Row],[실점]],"승",IF(표1부리그경기결과[[#This Row],[득점]]=표1부리그경기결과[[#This Row],[실점]],"무",IF(표1부리그경기결과[[#This Row],[득점]]<표1부리그경기결과[[#This Row],[실점]],"패","미진행")))) -> 승 | R32: 맨유 | S32: 5 | T32: 2 | U32: 도르트문트
P33: 23 | Q33: =IF(표1부리그경기결과[[#This Row],[득점]]="","미진행",IF(표1부리그경기결과[[#This Row],[득점]]>표1부리그경기결과[[#This Row],[실점]],"승",IF(표1부리그경기결과[[#This Row],[득점]]=표1부리그경기결과[[#This Row],[실점]],"무",IF(표1부리그경기결과[[#This Row],[득점]]<표1부리그경기결과[[#This Row],[실점]],"패","미진행")))) -> 승 | R33: 맨유 | S33: 3 | T33: 2 | U33: 뉴캐슬
P34: 24 | Q34: =IF(표1부리그경기결과[[#This Row],[득점]]="","미진행",IF(표1부리그경기결과[[#This Row],[득점]]>표1부리그경기결과[[#This Row],[실점]],"승",IF(표1부리그경기결과[[#This Row],[득점]]=표1부리그경기결과[[#This Row],[실점]],"무",IF(표1부리그경기결과[[#This Row],[득점]]<표1부리그경기결과[[#This Row],[실점]],"패","미진행")))) -> 승 | R34: 맨유 | S34: 4 | T34: 1 | U34: 뉴캐슬
P35: 25 | Q35: =IF(표1부리그경기결과[[#This Row],[득점]]="","미진행",IF(표1부리그경기결과[[#This Row],[득점]]>표1부리그경기결과[[#This Row],[실점]],"승",IF(표1부리그경기결과[[#This Row],[득점]]=표1부리그경기결과[[#This Row],[실점]],"무",IF(표1부리그경기결과[[#This Row],[득점]]<표1부리그경기결과[[#This Row],[실점]],"패","미진행")))) -> 무 | R35: 맨유 | S35: 2 | T35: 2 | U35: 인테르
P36: 26 | Q36: =IF(표1부리그경기결과[[#This Row],[득점]]="","미진행",IF(표1부리그경기결과[[#This Row],[득점]]>표1부리그경기결과[[#This Row],[실점]],"승",IF(표1부리그경기결과[[#This Row],[득점]]=표1부리그경기결과[[#This Row],[실점]],"무",IF(표1부리그경기결과[[#This Row],[득점]]<표1부리그경기결과[[#This Row],[실점]],"패","미진행")))) -> 패 | R36: 맨유 | S36: 0 | T36: 1 | U36: 인테르
P37: 27 | Q37: =IF(표1부리그경기결과[[#This Row],[득점]]="","미진행",IF(표1부리그경기결과[[#This Row],[득점]]>표1부리그경기결과[[#This Row],[실점]],"승",IF(표1부리그경기결과[[#This Row],[득점]]=표1부리그경기결과[[#This Row],[실점]],"무",IF(표1부리그경기결과[[#This Row],[득점]]<표1부리그경기결과[[#This Row],[실점]],"패","미진행")))) -> 무 | R37: 맨유 | S37: 2 | T37: 2 | U37: 비야레알
P38: 28 | Q38: =IF(표1부리그경기결과[[#This Row],[득점]]="","미진행",IF(표1부리그경기결과[[#This Row],[득점]]>표1부리그경기결과[[#This Row],[실점]],"승",IF(표1부리그경기결과[[#This Row],[득점]]=표1부리그경기결과[[#This Row],[실점]],"무",IF(표1부리그경기결과[[#This Row],[득점]]<표1부리그경기결과[[#This Row],[실점]],"패","미진행")))) -> 무 | R38: 맨유 | S38: 1 | T38: 1 | U38: 비야레알
P39: 29 | Q39: =IF(표1부리그경기결과[[#This Row],[득점]]="","미진행",IF(표1부리그경기결과[[#This Row],[득점]]>표1부리그경기결과[[#This Row],[실점]],"승",IF(표1부리그경기결과[[#This Row],[득점]]=표1부리그경기결과[[#This Row],[실점]],"무",IF(표1부리그경기결과[[#This Row],[득점]]<표1부리그경기결과[[#This Row],[실점]],"패","미진행")))) -> 미진행 | R39: 맨유 | U39: 뮌헨
P40: 30 | Q40: =IF(표1부리그경기결과[[#This Row],[득점]]="","미진행",IF(표1부리그경기결과[[#This Row],[득점]]>표1부리그경기결과[[#This Row],[실점]],"승",IF(표1부리그경기결과[[#This Row],[득점]]=표1부리그경기결과[[#This Row],[실점]],"무",IF(표1부리그경기결과[[#This Row],[득점]]<표1부리그경기결과[[#This Row],[실점]],"패","미진행")))) -> 미진행 | R40: 맨유 | U40: 뮌헨
P41: 31 | Q41: =IF(표1부리그경기결과[[#This Row],[득점]]="","미진행",IF(표1부리그경기결과[[#This Row],[득점]]>표1부리그경기결과[[#This Row],[실점]],"승",IF(표1부리그경기결과[[#This Row],[득점]]=표1부리그경기결과[[#This Row],[실점]],"무",IF(표1부리그경기결과[[#This Row],[득점]]<표1부리그경기결과[[#This Row],[실점]],"패","미진행")))) -> 승 | R41: 도르트문트 | S41: 4 | T41: 3 | U41: 뉴캐슬
P42: 32 | Q42: =IF(표1부리그경기결과[[#This Row],[득점]]="","미진행",IF(표1부리그경기결과[[#This Row],[득점]]>표1부리그경기결과[[#This Row],[실점]],"승",IF(표1부리그경기결과[[#This Row],[득점]]=표1부리그경기결과[[#This Row],[실점]],"무",IF(표1부리그경기결과[[#This Row],[득점]]<표1부리그경기결과[[#This Row],[실점]],"패","미진행")))) -> 승 | R42: 도르트문트 | S42: 4 | T42: 3 | U42: 뉴캐슬
P43: 33 | Q43: =IF(표1부리그경기결과[[#This Row],[득점]]="","미진행",IF(표1부리그경기결과[[#This Row],[득점]]>표1부리그경기결과[[#This Row],[실점]],"승",IF(표1부리그경기결과[[#This Row],[득점]]=표1부리그경기결과[[#This Row],[실점]],"무",IF(표1부리그경기결과[[#This Row],[득점]]<표1부리그경기결과[[#This Row],[실점]],"패","미진행")))) -> 승 | R43: 도르트문트 | S43: 4 | T43: 0 | U43: 맨유
P44: 34 | Q44: =IF(표1부리그경기결과[[#This Row],[득점]]="","미진행",IF(표1부리그경기결과[[#This Row],[득점]]>표1부리그경기결과[[#This Row],[실점]],"승",IF(표1부리그경기결과[[#This Row],[득점]]=표1부리그경기결과[[#This Row],[실점]],"무",IF(표1부리그경기결과[[#This Row],[득점]]<표1부리그경기결과[[#This Row],[실점]],"패","미진행")))) -> 패 | R44: 도르트문트 | S44: 2 | T44: 5 | U44: 맨유
P45: 35 | Q45: =IF(표1부리그경기결과[[#This Row],[득점]]="","미진행",IF(표1부리그경기결과[[#This Row],[득점]]>표1부리그경기결과[[#This Row],[실점]],"승",IF(표1부리그경기결과[[#This Row],[득점]]=표1부리그경기결과[[#This Row],[실점]],"무",IF(표1부리그경기결과[[#This Row],[득점]]<표1부리그경기결과[[#This Row],[실점]],"패","미진행")))) -> 승 | R45: 도르트문트 | S45: 4 | T45: 2 | U45: 인테르
P46: 36 | Q46: =IF(표1부리그경기결과[[#This Row],[득점]]="","미진행",IF(표1부리그경기결과[[#This Row],[득점]]>표1부리그경기결과[[#This Row],[실점]],"승",IF(표1부리그경기결과[[#This Row],[득점]]=표1부리그경기결과[[#This Row],[실점]],"무",IF(표1부리그경기결과[[#This Row],[득점]]<표1부리그경기결과[[#This Row],[실점]],"패","미진행")))) -> 승 | R46: 도르트문트 | S46: 3 | T46: 2 | U46: 인테르
P47: 37 | Q47: =IF(표1부리그경기결과[[#This Row],[득점]]="","미진행",IF(표1부리그경기결과[[#This Row],[득점]]>표1부리그경기결과[[#This Row],[실점]],"승",IF(표1부리그경기결과[[#This Row],[득점]]=표1부리그경기결과[[#This Row],[실점]],"무",IF(표1부리그경기결과[[#This Row],[득점]]<표1부리그경기결과[[#This Row],[실점]],"패","미진행")))) -> 패 | R47: 도르트문트 | S47: 2 | T47: 3 | U47: 비야레알
...

Sheet 2부리그
B2: 순위 | C2: 팀명 | D2: 승 점 | E2: 경기 | F2: 승 | G2: 무 | H2: 패 | I2: 득점 | J2: 실점 | K2: 득실 | M2: 경기당 승점 | N2: 최대 승점
B3: 1 | C3: {=_xlfn._xlws.SORT(_xlfn._xlws.SORT(_xlfn._xlws.SORT(_xlfn._xlws.SORT((_xlfn._xlws.FILTER(표2부리그[],표2부리그[경기]>(-1),)),9,-1),7,-1),8,1),2,-1)} -> 레버쿠젠 | D3: 28 | E3: 12 | F3: 9 | G3: 1 | H3: 2 | I3: 34 | J3: 15 | K3: 19 | M3: =IFERROR(D3/E3,0) -> 2.3333333 | N3: =(18-E3)*3+D3 -> 46
B4: 2 | C4: ATM | D4: 15 | E4: 8 | F4: 5 | G4: 0 | H4: 3 | I4: 22 | J4: 10 | K4: 12 | M4: =IFERROR(D4/E4,0) -> 1.875 | N4: =(18-E4)*3+D4 -> 45
B5: 3 | C5: 첼시 | D5: 12 | E5: 8 | F5: 4 | G5: 0 | H5: 4 | I5: 25 | J5: 20 | K5: 5 | M5: =IFERROR(D5/E5,0) -> 1.5 | N5: =(18-E5)*3+D5 -> 42
B6: 4 | C6: PSV | D6: 6 | E6: 2 | F6: 2 | G6: 0 | H6: 0 | I6: 9 | J6: 6 | K6: 3 | M6: =IFERROR(D6/E6,0) -> 3 | N6: =(18-E6)*3+D6 -> 54
B7: 5 | C7: 레알 마드리드 | D7: 4 | E7: 2 | F7: 1 | G7: 1 | H7: 0 | I7: 2 | J7: 1 | K7: 1 | M7: =IFERROR(D7/E7,0) -> 2 | N7: =(18-E7)*3+D7 -> 52
B8: 6 | C8: 유벤투스 | D8: 4 | E8: 4 | F8: 1 | G8: 1 | H8: 2 | I8: 4 | J8: 10 | K8: -6 | M8: =IFERROR(D8/E8,0) -> 1 | N8: =(18-E8)*3+D8 -> 46
B9: 7 | C9: 아우크스부르크 | D9: 1 | E9: 8 | F9: 0 | G9: 1 | H9: 7 | I9: 9 | J9: 31 | K9: -22 | M9: =IFERROR(D9/E9,0) -> 0.125 | N9: =(18-E9)*3+D9 -> 31
B10: 8 | C10: 비야레알 | D10: 0 | E10: 0 | F10: 0 | G10: 0 | H10: 0 | I10: 0 | J10: 0 | K10: 0 | M10: =IFERROR(D10/E10,0) -> 0 | N10: =(18-E10)*3+D10 -> 54
B11: 9 | C11: 도르트문트 | D11: 0 | E11: 0 | F11: 0 | G11: 0 | H11: 0 | I11: 0 | J11: 0 | K11: 0 | M11: =IFERROR(D11/E11,0) -> 0 | N11: =(18-E11)*3+D11 -> 54
B12: 10 | C12: 토트넘 | D12: 0 | E12: 4 | F12: 0 | G12: 0 | H12: 4 | I12: 5 | J12: 17 | K12: -12 | M12: =IFERROR(D12/E12,0) -> 0 | N12: =(18-E12)*3+D12 -> 42
P14: NO | Q14: 결과 | R14: 팀 | S14: 득점 | T14: 실점 | U14: 상대팀
P15: 1 | Q15: =IF(표100[[#This Row],[득점]]="","미진행",IF(표100[[#This Row],[득점]]>표100[[#This Row],[실점]],"승",IF(표100[[#This Row],[득점]]=표100[[#This Row],[실점]],"무",IF(표100[[#This Row],[득점]]<표100[[#This Row],[실점]],"패","미진행")))) -> 미진행 | R15: 레버쿠젠 | U15: 비야레알
P16: 2 | Q16: =IF(표100[[#This Row],[득점]]="","미진행",IF(표100[[#This Row],[득점]]>표100[[#This Row],[실점]],"승",IF(표100[[#This Row],[득점]]=표100[[#This Row],[실점]],"무",IF(표100[[#This Row],[득점]]<표100[[#This Row],[실점]],"패","미진행")))) -> 미진행 | R16: 레버쿠젠 | U16: 비야레알
P17: 3 | Q17: =IF(표100[[#This Row],[득점]]="","미진행",IF(표100[[#This Row],[득점]]>표100[[#This Row],[실점]],"승",IF(표100[[#This Row],[득점]]=표100[[#This Row],[실점]],"무",IF(표100[[#This Row],[득점]]<표100[[#This Row],[실점]],"패","미진행")))) -> 미진행 | R17: 레버쿠젠 | U17: 도르트문트
P18: 4 | Q18: =IF(표100[[#This Row],[득점]]="","미진행",IF(표100[[#This Row],[득점]]>표100[[#This Row],[실점]],"승",IF(표100[[#This Row],[득점]]=표100[[#This Row],[실점]],"무",IF(표100[[#This Row],[득점]]<표100[[#This Row],[실점]],"패","미진행")))) -> 미진행 | R18: 레버쿠젠 | U18: 도르트문트
P19: 5 | Q19: =IF(표100[[#This Row],[득점]]="","미진행",IF(표100[[#This Row],[득점]]>표100[[#This Row],[실점]],"승",IF(표100[[#This Row],[득점]]=표100[[#This Row],[실점]],"무",IF(표100[[#This Row],[득점]]<표100[[#This Row],[실점]],"패","미진행")))) -> 승 | R19: 레버쿠젠 | S19: 2 | T19: 1 | U19: ATM
P20: 6 | Q20: =IF(표100[[#This Row],[득점]]="","미진행",IF(표100[[#This Row],[득점]]>표100[[#This Row],[실점]],"승",IF(표100[[#This Row],[득점]]=표100[[#This Row],[실점]],"무",IF(표100[[#This Row],[득점]]<표100[[#This Row],[실점]],"패","미진행")))) -> 패 | R20: 레버쿠젠 | S20: 0 | T20: 4 | U20: ATM
P21: 7 | Q21: =IF(표100[[#This Row],[득점]]="","미진행",IF(표100[[#This Row],[득점]]>표100[[#This Row],[실점]],"승",IF(표100[[#This Row],[득점]]=표100[[#This Row],[실점]],"무",IF(표100[[#This Row],[득점]]<표100[[#This Row],[실점]],"패","미진행")))) -> 승 | R21: 레버쿠젠 | S21: 3 | T21: 0 | U21: 첼시
P22: 8 | Q22: =IF(표100[[#This Row],[득점]]="","미진행",IF(표100[[#This Row],[득점]]>표100[[#This Row],[실점]],"승",IF(표100[[#This Row],[득점]]=표100[[#This Row],[실점]],"무",IF(표100[[#This Row],[득점]]<표100[[#This Row],[실점]],"패","미진행")))) -> 승 | R22: 레버쿠젠 | S22: 3 | T22: 2 | U22: 첼시
P23: 9 | Q23: =IF(표100[[#This Row],[득점]]="","미진행",IF(표100[[#This Row],[득점]]>표100[[#This Row],[실점]],"승",IF(표100[[#This Row],[득점]]=표100[[#This Row],[실점]],"무",IF(표100[[#This Row],[득점]]<표100[[#This Row],[실점]],"패","미진행")))) -> 승 | R23: 레버쿠젠 | S23: 4 | T23: 1 | U23: 토트넘
P24: 10 | Q24: =IF(표100[[#This Row],[득점]]="","미진행",IF(표100[[#This Row],[득점]]>표100[[#This Row],[실점]],"승",IF(표100[[#This Row],[득점]]=표100[[#This Row],[실점]],"무",IF(표100[[#This Row],[득점]]<표100[[#This Row],[실점]],"패","미진행")))) -> 승 | R24: 레버쿠젠 | S24: 3 | T24: 1 | U24: 토트넘
P25: 11 | Q25: =IF(표100[[#This Row],[득점]]="","미진행",IF(표100[[#This Row],[득점]]>표100[[#This Row],[실점]],"승",IF(표100[[#This Row],[득점]]=표100[[#This Row],[실점]],"무",IF(표100[[#This Row],[득점]]<표100[[#This Row],[실점]],"패","미진행")))) -> 미진행 | R25: 레버쿠젠 | U25: PSV
P26: 12 | Q26: =IF(표100[[#This Row],[득점]]="","미진행",IF(표100[[#This Row],[득점]]>표100[[#This Row],[실점]],"승",IF(표100[[#This Row],[득점]]=표100[[#This Row],[실점]],"무",IF(표100[[#This Row],[득점]]<표100[[#This Row],[실점]],"패","미진행")))) -> 미진행 | R26: 레버쿠젠 | U26: PSV
P27: 13 | Q27: =IF(표100[[#This Row],[득점]]="","미진행",IF(표100[[#This Row],[득점]]>표100[[#This Row],[실점]],"승",IF(표100[[#This Row],[득점]]=표100[[#This Row],[실점]],"무",IF(표100[[#This Row],[득점]]<표100[[#This Row],[실점]],"패","미진행")))) -> 무 | R27: 레버쿠젠 | S27: 1 | T27: 1 | U27: 레알 마드리드
P28: 14 | Q28: =IF(표100[[#This Row],[득점]]="","미진행",IF(표100[[#This Row],[득점]]>표100[[#This Row],[실점]],"승",IF(표100[[#This Row],[득점]]=표100[[#This Row],[실점]],"무",IF(표100[[#This Row],[득점]]<표100[[#This Row],[실점]],"패","미진행")))) -> 패 | R28: 레버쿠젠 | S28: 0 | T28: 1 | U28: 레알 마드리드
P29: 15 | Q29: =IF(표100[[#This Row],[득점]]="","미진행",IF(표100[[#This Row],[득점]]>표100[[#This Row],[실점]],"승",IF(표100[[#This Row],[득점]]=표100[[#This Row],[실점]],"무",IF(표100[[#This Row],[득점]]<표100[[#This Row],[실점]],"패","미진행")))) -> 승 | R29: 레버쿠젠 | S29: 3 | T29: 0 | U29: 유벤투스
P30: 16 | Q30: =IF(표100[[#This Row],[득점]]="","미진행",IF(표100[[#This Row],[득점]]>표100[[#This Row],[실점]],"승",IF(표100[[#This Row],[득점]]=표100[[#This Row],[실점]],"무",IF(표100[[#This Row],[득점]]<표100[[#This Row],[실점]],"패","미진행")))) -> 승 | R30: 레버쿠젠 | S30: 5 | T30: 1 | U30: 유벤투스
P31: 17 | Q31: =IF(표100[[#This Row],[득점]]="","미진행",IF(표100[[#This Row],[득점]]>표100[[#This Row],[실점]],"승",IF(표100[[#This Row],[득점]]=표100[[#This Row],[실점]],"무",IF(표100[[#This Row],[득점]]<표100[[#This Row],[실점]],"패","미진행")))) -> 승 | R31: 레버쿠젠 | S31: 3 | T31: 1 | U31: 아우크스부르크
P32: 18 | Q32: =IF(표100[[#This Row],[득점]]="","미진행",IF(표100[[#This Row],[득점]]>표100[[#This Row],[실점]],"승",IF(표100[[#This Row],[득점]]=표100[[#This Row],[실점]],"무",IF(표100[[#This Row],[득점]]<표100[[#This Row],[실점]],"패","미진행")))) -> 승 | R32: 레버쿠젠 | S32: 7 | T32: 2 | U32: 아우크스부르크
P33: 19 | Q33: =IF(표100[[#This Row],[득점]]="","미진행",IF(표100[[#This Row],[득점]]>표100[[#This Row],[실점]],"승",IF(표100[[#This Row],[득점]]=표100[[#This Row],[실점]],"무",IF(표100[[#This Row],[득점]]<표100[[#This Row],[실점]],"패","미진행")))) -> 미진행 | R33: 비야레알 | U33: 레버쿠젠
P34: 20 | Q34: =IF(표100[[#This Row],[득점]]="","미진행",IF(표100[[#This Row],[득점]]>표100[[#This Row],[실점]],"승",IF(표100[[#This Row],[득점]]=표100[[#This Row],[실점]],"무",IF(표100[[#This Row],[득점]]<표100[[#This Row],[실점]],"패","미진행")))) -> 미진행 | R34: 비야레알 | U34: 레버쿠젠
P35: 21 | Q35: =IF(표100[[#This Row],[득점]]="","미진행",IF(표100[[#This Row],[득점]]>표100[[#This Row],[실점]],"승",IF(표100[[#This Row],[득점]]=표100[[#This Row],[실점]],"무",IF(표100[[#This Row],[득점]]<표100[[#This Row],[실점]],"패","미진행")))) -> 미진행 | R35: 비야레알 | U35: 도르트문트
P36: 22 | Q36: =IF(표100[[#This Row],[득점]]="","미진행",IF(표100[[#This Row],[득점]]>표100[[#This Row],[실점]],"승",IF(표100[[#This Row],[득점]]=표100[[#This Row],[실점]],"무",IF(표100[[#This Row],[득점]]<표100[[#This Row],[실점]],"패","미진행")))) -> 미진행 | R36: 비야레알 | U36: 도르트문트
P37: 23 | Q37: =IF(표100[[#This Row],[득점]]="","미진행",IF(표100[[#This Row],[득점]]>표100[[#This Row],[실점]],"승",IF(표100[[#This Row],[득점]]=표100[[#This Row],[실점]],"무",IF(표100[[#This Row],[득점]]<표100[[#This Row],[실점]],"패","미진행")))) -> 미진행 | R37: 비야레알 | U37: ATM
P38: 24 | Q38: =IF(표100[[#This Row],[득점]]="","미진행",IF(표100[[#This Row],[득점]]>표100[[#This Row],[실점]],"승",IF(표100[[#This Row],[득점]]=표100[[#This Row],[실점]],"무",IF(표100[[#This Row],[득점]]<표100[[#This Row],[실점]],"패","미진행")))) -> 미진행 | R38: 비야레알 | U38: ATM
P39: 25 | Q39: =IF(표100[[#This Row],[득점]]="","미진행",IF(표100[[#This Row],[득점]]>표100[[#This Row],[실점]],"승",IF(표100[[#This Row],[득점]]=표100[[#This Row],[실점]],"무",IF(표100[[#This Row],[득점]]<표100[[#This Row],[실점]],"패","미진행")))) -> 미진행 | R39: 비야레알 | U39: 첼시
P40: 26 | Q40: =IF(표100[[#This Row],[득점]]="","미진행",IF(표100[[#This Row],[득점]]>표100[[#This Row],[실점]],"승",IF(표100[[#This Row],[득점]]=표100[[#This Row],[실점]],"무",IF(표100[[#This Row],[득점]]<표100[[#This Row],[실점]],"패","미진행")))) -> 미진행 | R40: 비야레알 | U40: 첼시
P41: 27 | Q41: =IF(표100[[#This Row],[득점]]="","미진행",IF(표100[[#This Row],[득점]]>표100[[#This Row],[실점]],"승",IF(표100[[#This Row],[득점]]=표100[[#This Row],[실점]],"무",IF(표100[[#This Row],[득점]]<표100[[#This Row],[실점]],"패","미진행")))) -> 미진행 | R41: 비야레알 | U41: 토트넘
P42: 28 | Q42: =IF(표100[[#This Row],[득점]]="","미진행",IF(표100[[#This Row],[득점]]>표100[[#This Row],[실점]],"승",IF(표100[[#This Row],[득점]]=표100[[#This Row],[실점]],"무",IF(표100[[#This Row],[득점]]<표100[[#This Row],[실점]],"패","미진행")))) -> 미진행 | R42: 비야레알 | U42: 토트넘
...

Sheet 리그테이블 DB
L2: 승 | M2: 무 | N2: 패
C3: 팀 | D3: 승점점수 | E3: 경기 | F3: 승 | G3: 무 | H3: 패 | I3: 득점 | J3: 실점 | K3: 득실 | M3: 팀 | N3: 승점점수 | O3: 경기 | P3: 승 | Q3: 무 | R3: 패 | S3: 득점 | T3: 실점 | U3: 득실
C4: 도르트문트 | D4: =표1부리그[[#This Row],[승]]*3+표1부리그[[#This Row],[무]] -> 21 | E4: =표1부리그[[#This Row],[승]]+표1부리그[[#This Row],[무]]+표1부리그[[#This Row],[패]] -> 10 | F4: =COUNTIFS(표1부리그경기결과[팀],표1부리그[[#This Row],[팀]],표1부리그경기결과[결과],$L$2) -> 7 | G4: =COUNTIFS(표1부리그경기결과[팀],표1부리그[[#This Row],[팀]],표1부리그경기결과[결과],$M$2) -> 0 | H4: =COUNTIFS(표1부리그경기결과[팀],표1부리그[[#This Row],[팀]],표1부리그경기결과[결과],$N$2) -> 3 | I4: =SUMIFS(표1부리그경기결과[득점],표1부리그경기결과[팀],표1부리그[[#This Row],[팀]]) -> 31 | J4: =SUMIFS(표1부리그경기결과[실점],표1부리그경기결과[팀],표1부리그[[#This Row],[팀]]) -> 26 | K4: =표1부리그[[#This Row],[득점]]-표1부리그[[#This Row],[실점]] -> 5 | M4: 레버쿠젠 | N4: =표2부리그[[#This Row],[승]]*3+표2부리그[[#This Row],[무]] -> 28 | O4: =표2부리그[[#This Row],[승]]+표2부리그[[#This Row],[무]]+표2부리그[[#This Row],[패]] -> 12 | P4: =COUNTIFS(표100[팀],표2부리그[[#This Row],[팀]],표100[결과],$L$2) -> 9 | Q4: =COUNTIFS(표100[팀],표2부리그[[#This Row],[팀]],표100[결과],$M$2) -> 1 | R4: =COUNTIFS(표100[팀],표2부리그[[#This Row],[팀]],표100[결과],$N$2) -> 2 | S4: =SUMIFS(표100[득점],표100[팀],표2부리그[[#This Row],[팀]]) -> 34 | T4: =SUMIFS(표100[실점],표100[팀],표2부리그[[#This Row],[팀]]) -> 15 | U4: =표2부리그[[#This Row],[득점]]-표2부리그[[#This Row],[실점]] -> 19
C5: 뉴캐슬 | D5: =표1부리그[[#This Row],[승]]*3+표1부리그[[#This Row],[무]] -> 3 | E5: =표1부리그[[#This Row],[승]]+표1부리그[[#This Row],[무]]+표1부리그[[#This Row],[패]] -> 8 | F5: =COUNTIFS(표1부리그경기결과[팀],표1부리그[[#This Row],[팀]],표1부리그경기결과[결과],$L$2) -> 1 | G5: =COUNTIFS(표1부리그경기결과[팀],표1부리그[[#This Row],[팀]],표1부리그경기결과[결과],$M$2) -> 0 | H5: =COUNTIFS(표1부리그경기결과[팀],표1부리그[[#This Row],[팀]],표1부리그경기결과[결과],$N$2) -> 7 | I5: =SUMIFS(표1부리그경기결과[득점],표1부리그경기결과[팀],표1부리그[[#This Row],[팀]]) -> 14 | J5: =SUMIFS(표1부리그경기결과[실점],표1부리그경기결과[팀],표1부리그[[#This Row],[팀]]) -> 23 | K5: =표1부리그[[#This Row],[득점]]-표1부리그[[#This Row],[실점]] -> -9 | M5: 비야레알 | N5: =표2부리그[[#This Row],[승]]*3+표2부리그[[#This Row],[무]] -> 0 | O5: =표2부리그[[#This Row],[승]]+표2부리그[[#This Row],[무]]+표2부리그[[#This Row],[패]] -> 0 | P5: =COUNTIFS(표100[팀],표2부리그[[#This Row],[팀]],표100[결과],$L$2) -> 0 | Q5: =COUNTIFS(표100[팀],표2부리그[[#This Row],[팀]],표100[결과],$M$2) -> 0 | R5: =COUNTIFS(표100[팀],표2부리그[[#This Row],[팀]],표100[결과],$N$2) -> 0 | S5: =SUMIFS(표100[득점],표100[팀],표2부리그[[#This Row],[팀]]) -> 0 | T5: =SUMIFS(표100[실점],표100[팀],표2부리그[[#This Row],[팀]]) -> 0 | U5: =표2부리그[[#This Row],[득점]]-표2부리그[[#This Row],[실점]] -> 0
C6: 맨유 | D6: =표1부리그[[#This Row],[승]]*3+표1부리그[[#This Row],[무]] -> 12 | E6: =표1부리그[[#This Row],[승]]+표1부리그[[#This Row],[무]]+표1부리그[[#This Row],[패]] -> 8 | F6: =COUNTIFS(표1부리그경기결과[팀],표1부리그[[#This Row],[팀]],표1부리그경기결과[결과],$L$2) -> 3 | G6: =COUNTIFS(표1부리그경기결과[팀],표1부리그[[#This Row],[팀]],표1부리그경기결과[결과],$M$2) -> 3 | H6: =COUNTIFS(표1부리그경기결과[팀],표1부리그[[#This Row],[팀]],표1부리그경기결과[결과],$N$2) -> 2 | I6: =SUMIFS(표1부리그경기결과[득점],표1부리그경기결과[팀],표1부리그[[#This Row],[팀]]) -> 17 | J6: =SUMIFS(표1부리그경기결과[실점],표1부리그경기결과[팀],표1부리그[[#This Row],[팀]]) -> 15 | K6: =표1부리그[[#This Row],[득점]]-표1부리그[[#This Row],[실점]] -> 2 | M6: 도르트문트 | N6: =표2부리그[[#This Row],[승]]*3+표2부리그[[#This Row],[무]] -> 0 | O6: =표2부리그[[#This Row],[승]]+표2부리그[[#This Row],[무]]+표2부리그[[#This Row],[패]] -> 0 | P6: =COUNTIFS(표100[팀],표2부리그[[#This Row],[팀]],표100[결과],$L$2) -> 0 | Q6: =COUNTIFS(표100[팀],표2부리그[[#This Row],[팀]],표100[결과],$M$2) -> 0 | R6: =COUNTIFS(표100[팀],표2부리그[[#This Row],[팀]],표100[결과],$N$2) -> 0 | S6: =SUMIFS(표100[득점],표100[팀],표2부리그[[#This Row],[팀]]) -> 0 | T6: =SUMIFS(표100[실점],표100[팀],표2부리그[[#This Row],[팀]]) -> 0 | U6: =표2부리그[[#This Row],[득점]]-표2부리그[[#This Row],[실점]] -> 0
C7: 인테르 | D7: =표1부리그[[#This Row],[승]]*3+표1부리그[[#This Row],[무]] -> 12 | E7: =표1부리그[[#This Row],[승]]+표1부리그[[#This Row],[무]]+표1부리그[[#This Row],[패]] -> 10 | F7: =COUNTIFS(표1부리그경기결과[팀],표1부리그[[#This Row],[팀]],표1부리그경기결과[결과],$L$2) -> 3 | G7: =COUNTIFS(표1부리그경기결과[팀],표1부리그[[#This Row],[팀]],표1부리그경기결과[결과],$M$2) -> 3 | H7: =COUNTIFS(표1부리그경기결과[팀],표1부리그[[#This Row],[팀]],표1부리그경기결과[결과],$N$2) -> 4 | I7: =SUMIFS(표1부리그경기결과[득점],표1부리그경기결과[팀],표1부리그[[#This Row],[팀]]) -> 18 | J7: =SUMIFS(표1부리그경기결과[실점],표1부리그경기결과[팀],표1부리그[[#This Row],[팀]]) -> 20 | K7: =표1부리그[[#This Row],[득점]]-표1부리그[[#This Row],[실점]] -> -2 | M7: ATM | N7: =표2부리그[[#This Row],[승]]*3+표2부리그[[#This Row],[무]] -> 15 | O7: =표2부리그[[#This Row],[승]]+표2부리그[[#This Row],[무]]+표2부리그[[#This Row],[패]] -> 8 | P7: =COUNTIFS(표100[팀],표2부리그[[#This Row],[팀]],표100[결과],$L$2) -> 5 | Q7: =COUNTIFS(표100[팀],표2부리그[[#This Row],[팀]],표100[결과],$M$2) -> 0 | R7: =COUNTIFS(표100[팀],표2부리그[[#This Row],[팀]],표100[결과],$N$2) -> 3 | S7: =SUMIFS(표100[득점],표100[팀],표2부리그[[#This Row],[팀]]) -> 22 | T7: =SUMIFS(표100[실점],표100[팀],표2부리그[[#This Row],[팀]]) -> 10 | U7: =표2부리그[[#This Row],[득점]]-표2부리그[[#This Row],[실점]] -> 12
C8: 비야레알 | D8: =표1부리그[[#This Row],[승]]*3+표1부리그[[#This Row],[무]] -> 15 | E8: =표1부리그[[#This Row],[승]]+표1부리그[[#This Row],[무]]+표1부리그[[#This Row],[패]] -> 8 | F8: =COUNTIFS(표1부리그경기결과[팀],표1부리그[[#This Row],[팀]],표1부리그경기결과[결과],$L$2) -> 4 | G8: =COUNTIFS(표1부리그경기결과[팀],표1부리그[[#This Row],[팀]],표1부리그경기결과[결과],$M$2) -> 3 | H8: =COUNTIFS(표1부리그경기결과[팀],표1부리그[[#This Row],[팀]],표1부리그경기결과[결과],$N$2) -> 1 | I8: =SUMIFS(표1부리그경기결과[득점],표1부리그경기결과[팀],표1부리그[[#This Row],[팀]]) -> 20 | J8: =SUMIFS(표1부리그경기결과[실점],표1부리그경기결과[팀],표1부리그[[#This Row],[팀]]) -> 15 | K8: =표1부리그[[#This Row],[득점]]-표1부리그[[#This Row],[실점]] -> 5 | M8: 첼시 | N8: =표2부리그[[#This Row],[승]]*3+표2부리그[[#This Row],[무]] -> 12 | O8: =표2부리그[[#This Row],[승]]+표2부리그[[#This Row],[무]]+표2부리그[[#This Row],[패]] -> 8 | P8: =COUNTIFS(표100[팀],표2부리그[[#This Row],[팀]],표100[결과],$L$2) -> 4 | Q8: =COUNTIFS(표100[팀],표2부리그[[#This Row],[팀]],표100[결과],$M$2) -> 0 | R8: =COUNTIFS(표100[팀],표2부리그[[#This Row],[팀]],표100[결과],$N$2) -> 4 | S8: =SUMIFS(표100[득점],표100[팀],표2부리그[[#This Row],[팀]]) -> 25 | T8: =SUMIFS(표100[실점],표100[팀],표2부리그[[#This Row],[팀]]) -> 20 | U8: =표2부리그[[#This Row],[득점]]-표2부리그[[#This Row],[실점]] -> 5
C9: 뮌헨 | D9: =표1부리그[[#This Row],[승]]*3+표1부리그[[#This Row],[무]] -> 4 | E9: =표1부리그[[#This Row],[승]]+표1부리그[[#This Row],[무]]+표1부리그[[#This Row],[패]] -> 4 | F9: =COUNTIFS(표1부리그경기결과[팀],표1부리그[[#This Row],[팀]],표1부리그경기결과[결과],$L$2) -> 1 | G9: =COUNTIFS(표1부리그경기결과[팀],표1부리그[[#This Row],[팀]],표1부리그경기결과[결과],$M$2) -> 1 | H9: =COUNTIFS(표1부리그경기결과[팀],표1부리그[[#This Row],[팀]],표1부리그경기결과[결과],$N$2) -> 2 | I9: =SUMIFS(표1부리그경기결과[득점],표1부리그경기결과[팀],표1부리그[[#This Row],[팀]]) -> 7 | J9: =SUMIFS(표1부리그경기결과[실점],표1부리그경기결과[팀],표1부리그[[#This Row],[팀]]) -> 8 | K9: =표1부리그[[#This Row],[득점]]-표1부리그[[#This Row],[실점]] -> -1 | M9: 토트넘 | N9: =표2부리그[[#This Row],[승]]*3+표2부리그[[#This Row],[무]] -> 0 | O9: =표2부리그[[#This Row],[승]]+표2부리그[[#This Row],[무]]+표2부리그[[#This Row],[패]] -> 4 | P9: =COUNTIFS(표100[팀],표2부리그[[#This Row],[팀]],표100[결과],$L$2) -> 0 | Q9: =COUNTIFS(표100[팀],표2부리그[[#This Row],[팀]],표100[결과],$M$2) -> 0 | R9: =COUNTIFS(표100[팀],표2부리그[[#This Row],[팀]],표100[결과],$N$2) -> 4 | S9: =SUMIFS(표100[득점],표100[팀],표2부리그[[#This Row],[팀]]) -> 5 | T9: =SUMIFS(표100[실점],표100[팀],표2부리그[[#This Row],[팀]]) -> 17 | U9: =표2부리그[[#This Row],[득점]]-표2부리그[[#This Row],[실점]] -> -12
M10: PSV | N10: =표2부리그[[#This Row],[승]]*3+표2부리그[[#This Row],[무]] -> 6 | O10: =표2부리그[[#This Row],[승]]+표2부리그[[#This Row],[무]]+표2부리그[[#This Row],[패]] -> 2 | P10: =COUNTIFS(표100[팀],표2부리그[[#This Row],[팀]],표100[결과],$L$2) -> 2 | Q10: =COUNTIFS(표100[팀],표2부리그[[#This Row],[팀]],표100[결과],$M$2) -> 0 | R10: =COUNTIFS(표100[팀],표2부리그[[#This Row],[팀]],표100[결과],$N$2) -> 0 | S10: =SUMIFS(표100[득점],표100[팀],표2부리그[[#This Row],[팀]]) -> 9 | T10: =SUMIFS(표100[실점],표100[팀],표2부리그[[#This Row],[팀]]) -> 6 | U10: =표2부리그[[#This Row],[득점]]-표2부리그[[#This Row],[실점]] -> 3
M11: 레알 마드리드 | N11: =표2부리그[[#This Row],[승]]*3+표2부리그[[#This Row],[무]] -> 4 | O11: =표2부리그[[#This Row],[승]]+표2부리그[[#This Row],[무]]+표2부리그[[#This Row],[패]] -> 2 | P11: =COUNTIFS(표100[팀],표2부리그[[#This Row],[팀]],표100[결과],$L$2) -> 1 | Q11: =COUNTIFS(표100[팀],표2부리그[[#This Row],[팀]],표100[결과],$M$2) -> 1 | R11: =COUNTIFS(표100[팀],표2부리그[[#This Row],[팀]],표100[결과],$N$2) -> 0 | S11: =SUMIFS(표100[득점],표100[팀],표2부리그[[#This Row],[팀]]) -> 2 | T11: =SUMIFS(표100[실점],표100[팀],표2부리그[[#This Row],[팀]]) -> 1 | U11: =표2부리그[[#This Row],[득점]]-표2부리그[[#This Row],[실점]] -> 1
M12: 유벤투스 | N12: =표2부리그[[#This Row],[승]]*3+표2부리그[[#This Row],[무]] -> 4 | O12: =표2부리그[[#This Row],[승]]+표2부리그[[#This Row],[무]]+표2부리그[[#This Row],[패]] -> 4 | P12: =COUNTIFS(표100[팀],표2부리그[[#This Row],[팀]],표100[결과],$L$2) -> 1 | Q12: =COUNTIFS(표100[팀],표2부리그[[#This Row],[팀]],표100[결과],$M$2) -> 1 | R12: =COUNTIFS(표100[팀],표2부리그[[#This Row],[팀]],표100[결과],$N$2) -> 2 | S12: =SUMIFS(표100[득점],표100[팀],표2부리그[[#This Row],[팀]]) -> 4 | T12: =SUMIFS(표100[실점],표100[팀],표2부리그[[#This Row],[팀]]) -> 10 | U12: =표2부리그[[#This Row],[득점]]-표2부리그[[#This Row],[실점]] -> -6
M13: 아우크스부르크 | N13: =표2부리그[[#This Row],[승]]*3+표2부리그[[#This Row],[무]] -> 1 | O13: =표2부리그[[#This Row],[승]]+표2부리그[[#This Row],[무]]+표2부리그[[#This Row],[패]] -> 8 | P13: =COUNTIFS(표100[팀],표2부리그[[#This Row],[팀]],표100[결과],$L$2) -> 0 | Q13: =COUNTIFS(표100[팀],표2부리그[[#This Row],[팀]],표100[결과],$M$2) -> 1 | R13: =COUNTIFS(표100[팀],표2부리그[[#This Row],[팀]],표100[결과],$N$2) -> 7 | S13: =SUMIFS(표100[득점],표100[팀],표2부리그[[#This Row],[팀]]) -> 9 | T13: =SUMIFS(표100[실점],표100[팀],표2부리그[[#This Row],[팀]]) -> 31 | U13: =표2부리그[[#This Row],[득점]]-표2부리그[[#This Row],[실점]] -> -22

Sheet UCL
D2: 챔피언스리그 GROUP STAGE
B4: A | D4: 순위 | E4: 팀명 | F4: 경기 | G4: 승 | H4: 무 | I4: 패 | J4: 득점 | K4: 실점 | L4: 득실 | M4: 승 점
D5: 1 | E5: {=_xlfn._xlws.SORT(_xlfn._xlws.SORT(_xlfn._xlws.SORT(_xlfn._xlws.SORT((_xlfn._xlws.FILTER(표2_4[],표2_4[경기]>(-1),)),7,1),6,-1),8,-1),9,-1)} -> 첼시 | F5: 6 | G5: 3 | H5: 2 | I5: 1 | J5: 18 | K5: 15 | L5: 3 | M5: 11
D6: 2 | E6: ATM | F6: 6 | G6: 3 | H6: 0 | I6: 3 | J6: 20 | K6: 16 | L6: 4 | M6: 9
D7: 3 | E7: 레알 마드리드 | F7: 6 | G7: 2 | H7: 1 | I7: 3 | J7: 14 | K7: 14 | L7: 0 | M7: 7
D8: 4 | E8: 레버쿠젠 | F8: 6 | G8: 2 | H8: 1 | I8: 3 | J8: 9 | K8: 16 | L8: -7 | M8: 7
B10: B | D10: R | E10: 팀명 | F10: 경기 | G10: 승 | H10: 무 | I10: 패 | J10: 득점 | K10: 실점 | L10: 득실 | M10: 승 점
D11: 1 | E11: {=_xlfn._xlws.SORT(_xlfn._xlws.SORT(_xlfn._xlws.SORT(_xlfn._xlws.SORT((_xlfn._xlws.FILTER(표2_46[],표2_46[경기]>(-1),)),7,1),6,-1),8,-1),9,-1)} -> 도르트문트 | F11: 6 | G11: 5 | H11: 1 | I11: 0 | J11: 30 | K11: 10 | L11: 20 | M11: 16
D12: 2 | E12: 맨유 | F12: 6 | G12: 3 | H12: 1 | I12: 2 | J12: 19 | K12: 13 | L12: 6 | M12: 10
D13: 3 | E13: 토트넘 | F13: 6 | G13: 2 | H13: 1 | I13: 3 | J13: 10 | K13: 18 | L13: -8 | M13: 7
D14: 4 | E14: 아우크스부르크 | F14: 6 | G14: 0 | H14: 1 | I14: 5 | J14: 5 | K14: 23 | L14: -18 | M14: 1
B16: ` | D16: 순위 | E16: 팀명 | F16: 경기 | G16: 승 | H16: 무 | I16: 패 | J16: 득점 | K16: 실점 | L16: 득실 | M16: 승 점
D17: 1 | E17: {=_xlfn._xlws.SORT(_xlfn._xlws.SORT(_xlfn._xlws.SORT(_xlfn._xlws.SORT((_xlfn._xlws.FILTER(표2_4681015[],표2_4681015[경기]>(-1),)),7,1),6,-1),8,-1),9,-1)} -> 인테르 | F17: 4 | G17: 4 | H17: 0 | I17: 0 | J17: 15 | K17: 7 | L17: 8 | M17: 12
D18: 2 | E18: PSV | F18: 2 | G18: 0 | H18: 0 | I18: 2 | J18: 6 | K18: 9 | L18: -3 | M18: 0
D19: 3 | E19: 유벤투스 | F19: 2 | G19: 0 | H19: 0 | I19: 2 | J19: 1 | K19: 6 | L19: -5 | M19: 0
B21: D | D21: 순위 | E21: 팀명 | F21: 경기 | G21: 승 | H21: 무 | I21: 패 | J21: 득점 | K21: 실점 | L21: 득실 | M21: 승 점
D22: 1 | E22: {=_xlfn._xlws.SORT(_xlfn._xlws.SORT(_xlfn._xlws.SORT(_xlfn._xlws.SORT((_xlfn._xlws.FILTER(표2_46810[],표2_46810[경기]>(-1),)),7,1),6,-1),8,-1),9,-1)} -> 뉴캐슬 | F22: 0 | G22: 0 | H22: 0 | I22: 0 | J22: 0 | K22: 0 | L22: 0 | M22: 0
D23: 2 | E23: 뮌헨 | F23: 0 | G23: 0 | H23: 0 | I23: 0 | J23: 0 | K23: 0 | L23: 0 | M23: 0
D24: 3 | E24: 비야레알 | F24: 0 | G24: 0 | H24: 0 | I24: 0 | J24: 0 | K24: 0 | L24: 0 | M24: 0
O25: A | X25: 승 | Y25: 무 | Z25: 패
O26: 팀1 결과 | P26: 팀1 | Q26: 팀1 S | R26: 팀2 S | S26: 팀2 | T26: 팀2 결과 | V26: 팀 | W26: 경기 | X26: 승 | Y26: 무 | Z26: 패 | AA26: 득점 | AB26: 실점 | AC26: 득실 | AD26: 승점점수
O27: =IF(Q27="","",IF(Q27>R27,"승",IF(Q27=R27,"무",IF(Q27<R27,"패","")))) -> 승 | P27: =V27 -> 레버쿠젠 | Q27: 2 | R27: 1 | S27: =V28 -> 레알 마드리드 | T27: =IF(O27="","",IF(O27="무","무",IF(O27="승","패","승"))) -> 패 | V27: 레버쿠젠 | W27: =표2_4[[#This Row],[승]]+표2_4[[#This Row],[무]]+표2_4[[#This Row],[패]] -> 6 | X27: =COUNTIFS(챔스A[팀1 결과],X$25,챔스A[팀1],표2_4[[#This Row],[팀]])+COUNTIFS(챔스A[팀2 결과],X$25,챔스A[팀2],표2_4[[#This Row],[팀]]) -> 2 | Y27: =COUNTIFS(챔스A[팀1 결과],Y$25,챔스A[팀1],표2_4[[#This Row],[팀]])+COUNTIFS(챔스A[팀2 결과],Y$25,챔스A[팀2],표2_4[[#This Row],[팀]]) -> 1 | Z27: =COUNTIFS(챔스A[팀1 결과],Z$25,챔스A[팀1],표2_4[[#This Row],[팀]])+COUNTIFS(챔스A[팀2 결과],Z$25,챔스A[팀2],표2_4[[#This Row],[팀]]) -> 3 | AA27: =SUMIF(챔스A[팀1],표2_4[[#This Row],[팀]],챔스A[팀1 S])+SUMIF(챔스A[팀2],표2_4[[#This Row],[팀]],챔스A[팀2 S]) -> 9 | AB27: =SUMIF(챔스A[팀1],표2_4[[#This Row],[팀]],챔스A[팀2 S])+SUMIF(챔스A[팀2],표2_4[[#This Row],[팀]],챔스A[팀1 S]) -> 16 | AC27: =표2_4[[#This Row],[득점]]-표2_4[[#This Row],[실점]] -> -7 | AD27: =표2_4[[#This Row],[승]]*3+표2_4[[#This Row],[무]] -> 7
O28: =IF(Q28="","",IF(Q28>R28,"승",IF(Q28=R28,"무",IF(Q28<R28,"패","")))) -> 승 | P28: =V27 -> 레버쿠젠 | Q28: 2 | R28: 1 | S28: =V28 -> 레알 마드리드 | T28: =IF(O28="","",IF(O28="무","무",IF(O28="승","패","승"))) -> 패 | V28: 레알 마드리드 | W28: =표2_4[[#This Row],[승]]+표2_4[[#This Row],[무]]+표2_4[[#This Row],[패]] -> 6 | X28: =COUNTIFS(챔스A[팀1 결과],X$25,챔스A[팀1],표2_4[[#This Row],[팀]])+COUNTIFS(챔스A[팀2 결과],X$25,챔스A[팀2],표2_4[[#This Row],[팀]]) -> 2 | Y28: =COUNTIFS(챔스A[팀1 결과],Y$25,챔스A[팀1],표2_4[[#This Row],[팀]])+COUNTIFS(챔스A[팀2 결과],Y$25,챔스A[팀2],표2_4[[#This Row],[팀]]) -> 1 | Z28: =COUNTIFS(챔스A[팀1 결과],Z$25,챔스A[팀1],표2_4[[#This Row],[팀]])+COUNTIFS(챔스A[팀2 결과],Z$25,챔스A[팀2],표2_4[[#This Row],[팀]]) -> 3 | AA28: =SUMIF(챔스A[팀1],표2_4[[#This Row],[팀]],챔스A[팀1 S])+SUMIF(챔스A[팀2],표2_4[[#This Row],[팀]],챔스A[팀2 S]) -> 14 | AB28: =SUMIF(챔스A[팀1],표2_4[[#This Row],[팀]],챔스A[팀2 S])+SUMIF(챔스A[팀2],표2_4[[#This Row],[팀]],챔스A[팀1 S]) -> 14 | AC28: =표2_4[[#This Row],[득점]]-표2_4[[#This Row],[실점]] -> 0 | AD28: =표2_4[[#This Row],[승]]*3+표2_4[[#This Row],[무]] -> 7
O29: =IF(Q29="","",IF(Q29>R29,"승",IF(Q29=R29,"무",IF(Q29<R29,"패","")))) -> 패 | P29: =V27 -> 레버쿠젠 | Q29: 1 | R29: 3 | S29: =V29 -> 첼시 | T29: =IF(O29="","",IF(O29="무","무",IF(O29="승","패","승"))) -> 승 | V29: 첼시 | W29: =표2_4[[#This Row],[승]]+표2_4[[#This Row],[무]]+표2_4[[#This Row],[패]] -> 6 | X29: =COUNTIFS(챔스A[팀1 결과],X$25,챔스A[팀1],표2_4[[#This Row],[팀]])+COUNTIFS(챔스A[팀2 결과],X$25,챔스A[팀2],표2_4[[#This Row],[팀]]) -> 3 | Y29: =COUNTIFS(챔스A[팀1 결과],Y$25,챔스A[팀1],표2_4[[#This Row],[팀]])+COUNTIFS(챔스A[팀2 결과],Y$25,챔스A[팀2],표2_4[[#This Row],[팀]]) -> 2 | Z29: =COUNTIFS(챔스A[팀1 결과],Z$25,챔스A[팀1],표2_4[[#This Row],[팀]])+COUNTIFS(챔스A[팀2 결과],Z$25,챔스A[팀2],표2_4[[#This Row],[팀]]) -> 1 | AA29: =SUMIF(챔스A[팀1],표2_4[[#This Row],[팀]],챔스A[팀1 S])+SUMIF(챔스A[팀2],표2_4[[#This Row],[팀]],챔스A[팀2 S]) -> 18 | AB29: =SUMIF(챔스A[팀1],표2_4[[#This Row],[팀]],챔스A[팀2 S])+SUMIF(챔스A[팀2],표2_4[[#This Row],[팀]],챔스A[팀1 S]) -> 15 | AC29: =표2_4[[#This Row],[득점]]-표2_4[[#This Row],[실점]] -> 3 | AD29: =표2_4[[#This Row],[승]]*3+표2_4[[#This Row],[무]] -> 11
O30: =IF(Q30="","",IF(Q30>R30,"승",IF(Q30=R30,"무",IF(Q30<R30,"패","")))) -> 무 | P30: =V27 -> 레버쿠젠 | Q30: 2 | R30: 2 | S30: =V29 -> 첼시 | T30: =IF(O30="","",IF(O30="무","무",IF(O30="승","패","승"))) -> 무 | V30: ATM | W30: =표2_4[[#This Row],[승]]+표2_4[[#This Row],[무]]+표2_4[[#This Row],[패]] -> 6 | X30: =COUNTIFS(챔스A[팀1 결과],X$25,챔스A[팀1],표2_4[[#This Row],[팀]])+COUNTIFS(챔스A[팀2 결과],X$25,챔스A[팀2],표2_4[[#This Row],[팀]]) -> 3 | Y30: =COUNTIFS(챔스A[팀1 결과],Y$25,챔스A[팀1],표2_4[[#This Row],[팀]])+COUNTIFS(챔스A[팀2 결과],Y$25,챔스A[팀2],표2_4[[#This Row],[팀]]) -> 0 | Z30: =COUNTIFS(챔스A[팀1 결과],Z$25,챔스A[팀1],표2_4[[#This Row],[팀]])+COUNTIFS(챔스A[팀2 결과],Z$25,챔스A[팀2],표2_4[[#This Row],[팀]]) -> 3 | AA30: =SUMIF(챔스A[팀1],표2_4[[#This Row],[팀]],챔스A[팀1 S])+SUMIF(챔스A[팀2],표2_4[[#This Row],[팀]],챔스A[팀2 S]) -> 20 | AB30: =SUMIF(챔스A[팀1],표2_4[[#This Row],[팀]],챔스A[팀2 S])+SUMIF(챔스A[팀2],표2_4[[#This Row],[팀]],챔스A[팀1 S]) -> 16 | AC30: =표2_4[[#This Row],[득점]]-표2_4[[#This Row],[실점]] -> 4 | AD30: =표2_4[[#This Row],[승]]*3+표2_4[[#This Row],[무]] -> 9
O31: =IF(Q31="","",IF(Q31>R31,"승",IF(Q31=R31,"무",IF(Q31<R31,"패","")))) -> 패 | P31: =V27 -> 레버쿠젠 | Q31: 1 | R31: 6 | S31: =V30 -> ATM | T31: =IF(O31="","",IF(O31="무","무",IF(O31="승","패","승"))) -> 승
O32: =IF(Q32="","",IF(Q32>R32,"승",IF(Q32=R32,"무",IF(Q32<R32,"패","")))) -> 패 | P32: =V27 -> 레버쿠젠 | Q32: 1 | R32: 3 | S32: =V30 -> ATM | T32: =IF(O32="","",IF(O32="무","무",IF(O32="승","패","승"))) -> 승 | X32: 승 | Y32: 무 | Z32: 패
O33: =IF(Q33="","",IF(Q33>R33,"승",IF(Q33=R33,"무",IF(Q33<R33,"패","")))) -> 무 | P33: =V28 -> 레알 마드리드 | Q33: 4 | R33: 4 | S33: =V29 -> 첼시 | T33: =IF(O33="","",IF(O33="무","무",IF(O33="승","패","승"))) -> 무 | V33: 팀 | W33: 경기 | X33: 승 | Y33: 무 | Z33: 패 | AA33: 득점 | AB33: 실점 | AC33: 득실 | AD33: 승점점수
O34: =IF(Q34="","",IF(Q34>R34,"승",IF(Q34=R34,"무",IF(Q34<R34,"패","")))) -> 패 | P34: =V28 -> 레알 마드리드 | Q34: 1 | R34: 2 | S34: =V29 -> 첼시 | T34: =IF(O34="","",IF(O34="무","무",IF(O34="승","패","승"))) -> 승 | V34: 맨유 | W34: =표2_46[[#This Row],[승]]+표2_46[[#This Row],[무]]+표2_46[[#This Row],[패]] -> 6 | X34: =COUNTIFS(챔스A_7[팀1 결과],X$32,챔스A_7[팀1],표2_46[[#This Row],[팀]])+COUNTIFS(챔스A_7[팀2 결과],X$32,챔스A_7[팀2],표2_46[[#This Row],[팀]]) -> 3 | Y34: =COUNTIFS(챔스A_7[팀1 결과],Y$32,챔스A_7[팀1],표2_46[[#This Row],[팀]])+COUNTIFS(챔스A_7[팀2 결과],Y$32,챔스A_7[팀2],표2_46[[#This Row],[팀]]) -> 1 | Z34: =COUNTIFS(챔스A_7[팀1 결과],Z$32,챔스A_7[팀1],표2_46[[#This Row],[팀]])+COUNTIFS(챔스A_7[팀2 결과],Z$32,챔스A_7[팀2],표2_46[[#This Row],[팀]]) -> 2 | AA34: =SUMIF(챔스A_7[팀1],표2_46[[#This Row],[팀]],챔스A_7[팀1 S])+SUMIF(챔스A_7[팀2],표2_46[[#This Row],[팀]],챔스A_7[팀2 S]) -> 19 | AB34: =SUMIF(챔스A_7[팀1],표2_46[[#This Row],[팀]],챔스A_7[팀2 S])+SUMIF(챔스A_7[팀2],표2_46[[#This Row],[팀]],챔스A_7[팀1 S]) -> 13 | AC34: =표2_46[[#This Row],[득점]]-표2_46[[#This Row],[실점]] -> 6 | AD34: =표2_46[[#This Row],[승]]*3+표2_46[[#This Row],[무]] -> 10
O35: =IF(Q35="","",IF(Q35>R35,"승",IF(Q35=R35,"무",IF(Q35<R35,"패","")))) -> 승 | P35: =V28 -> 레알 마드리드 | Q35: 4 | R35: 2 | S35: =V30 -> ATM | T35: =IF(O35="","",IF(O35="무","무",IF(O35="승","패","승"))) -> 패 | V35: 아우크스부르크 | W35: =표2_46[[#This Row],[승]]+표2_46[[#This Row],[무]]+표2_46[[#This Row],[패]] -> 6 | X35: =COUNTIFS(챔스A_7[팀1 결과],X$32,챔스A_7[팀1],표2_46[[#This Row],[팀]])+COUNTIFS(챔스A_7[팀2 결과],X$32,챔스A_7[팀2],표2_46[[#This Row],[팀]]) -> 0 | Y35: =COUNTIFS(챔스A_7[팀1 결과],Y$32,챔스A_7[팀1],표2_46[[#This Row],[팀]])+COUNTIFS(챔스A_7[팀2 결과],Y$32,챔스A_7[팀2],표2_46[[#This Row],[팀]]) -> 1 | Z35: =COUNTIFS(챔스A_7[팀1 결과],Z$32,챔스A_7[팀1],표2_46[[#This Row],[팀]])+COUNTIFS(챔스A_7[팀2 결과],Z$32,챔스A_7[팀2],표2_46[[#This Row],[팀]]) -> 5 | AA35: =SUMIF(챔스A_7[팀1],표2_46[[#This Row],[팀]],챔스A_7[팀1 S])+SUMIF(챔스A_7[팀2],표2_46[[#This Row],[팀]],챔스A_7[팀2 S]) -> 5 | AB35: =SUMIF(챔스A_7[팀1],표2_46[[#This Row],[팀]],챔스A_7[팀2 S])+SUMIF(챔스A_7[팀2],표2_46[[#This Row],[팀]],챔스A_7[팀1 S]) -> 23 | AC35: =표2_46[[#This Row],[득점]]-표2_46[[#This Row],[실점]] -> -18 | AD35: =표2_46[[#This Row],[승]]*3+표2_46[[#This Row],[무]] -> 1
O36: =IF(Q36="","",IF(Q36>R36,"승",IF(Q36=R36,"무",IF(Q36<R36,"패","")))) -> 승 | P36: =V28 -> 레알 마드리드 | Q36: 3 | R36: 2 | S36: =V30 -> ATM | T36: =IF(O36="","",IF(O36="무","무",IF(O36="승","패","승"))) -> 패 | V36: 토트넘 | W36: =표2_46[[#This Row],[승]]+표2_46[[#This Row],[무]]+표2_46[[#This Row],[패]] -> 6 | X36: =COUNTIFS(챔스A_7[팀1 결과],X$32,챔스A_7[팀1],표2_46[[#This Row],[팀]])+COUNTIFS(챔스A_7[팀2 결과],X$32,챔스A_7[팀2],표2_46[[#This Row],[팀]]) -> 2 | Y36: =COUNTIFS(챔스A_7[팀1 결과],Y$32,챔스A_7[팀1],표2_46[[#This Row],[팀]])+COUNTIFS(챔스A_7[팀2 결과],Y$32,챔스A_7[팀2],표2_46[[#This Row],[팀]]) -> 1 | Z36: =COUNTIFS(챔스A_7[팀1 결과],Z$32,챔스A_7[팀1],표2_46[[#This Row],[팀]])+COUNTIFS(챔스A_7[팀2 결과],Z$32,챔스A_7[팀2],표2_46[[#This Row],[팀]]) -> 3 | AA36: =SUMIF(챔스A_7[팀1],표2_46[[#This Row],[팀]],챔스A_7[팀1 S])+SUMIF(챔스A_7[팀2],표2_46[[#This Row],[팀]],챔스A_7[팀2 S]) -> 10 | AB36: =SUMIF(챔스A_7[팀1],표2_46[[#This Row],[팀]],챔스A_7[팀2 S])+SUMIF(챔스A_7[팀2],표2_46[[#This Row],[팀]],챔스A_7[팀1 S]) -> 18 | AC36: =표2_46[[#This Row],[득점]]-표2_46[[#This Row],[실점]] -> -8 | AD36: =표2_46[[#This Row],[승]]*3+표2_46[[#This Row],[무]] -> 7
O37: =IF(Q37="","",IF(Q37>R37,"승",IF(Q37=R37,"무",IF(Q37<R37,"패","")))) -> 패 | P37: =V29 -> 첼시 | Q37: 2 | R37: 4 | S37: =V30 -> ATM | T37: =IF(O37="","",IF(O37="무","무",IF(O37="승","패","승"))) -> 승 | V37: 도르트문트 | W37: =표2_46[[#This Row],[승]]+표2_46[[#This Row],[무]]+표2_46[[#This Row],[패]] -> 6 | X37: =COUNTIFS(챔스A_7[팀1 결과],X$32,챔스A_7[팀1],표2_46[[#This Row],[팀]])+COUNTIFS(챔스A_7[팀2 결과],X$32,챔스A_7[팀2],표2_46[[#This Row],[팀]]) -> 5 | Y37: =COUNTIFS(챔스A_7[팀1 결과],Y$32,챔스A_7[팀1],표2_46[[#This Row],[팀]])+COUNTIFS(챔스A_7[팀2 결과],Y$32,챔스A_7[팀2],표2_46[[#This Row],[팀]]) -> 1 | Z37: =COUNTIFS(챔스A_7[팀1 결과],Z$32,챔스A_7[팀1],표2_46[[#This Row],[팀]])+COUNTIFS(챔스A_7[팀2 결과],Z$32,챔스A_7[팀2],표2_46[[#This Row],[팀]]) -> 0 | AA37: =SUMIF(챔스A_7[팀1],표2_46[[#This Row],[팀]],챔스A_7[팀1 S])+SUMIF(챔스A_7[팀2],표2_46[[#This Row],[팀]],챔스A_7[팀2 S]) -> 30 | AB37: =SUMIF(챔스A_7[팀1],표2_46[[#This Row],[팀]],챔스A_7[팀2 S])+SUMIF(챔스A_7[팀2],표2_46[[#This Row],[팀]],챔스A_7[팀1 S]) -> 10 | AC37: =표2_46[[#This Row],[득점]]-표2_46[[#This Row],[실점]] -> 20 | AD37: =표2_46[[#This Row],[승]]*3+표2_46[[#This Row],[무]] -> 16
O38: =IF(Q38="","",IF(Q38>R38,"승",IF(Q38=R38,"무",IF(Q38<R38,"패","")))) -> 승 | P38: =V29 -> 첼시 | Q38: 5 | R38: 3 | S38: =V30 -> ATM | T38: =IF(O38="","",IF(O38="무","무",IF(O38="승","패","승"))) -> 패
X39: 승 | Y39: 무 | Z39: 패
O40: B | V40: 팀 | W40: 경기 | X40: 승 | Y40: 무 | Z40: 패 | AA40: 득점 | AB40: 실점 | AC40: 득실 | AD40: 승점점수
O41: 팀1 결과 | P41: 팀1 | Q41: 팀1 S | R41: 팀2 S | S41: 팀2 | T41: 팀2 결과 | V41: 유벤투스 | W41: =표2_4681015[[#This Row],[승]]+표2_4681015[[#This Row],[무]]+표2_4681015[[#This Row],[패]] -> 2 | X41: =COUNTIFS(챔스A_791118[팀1 결과],X$39,챔스A_791118[팀1],표2_4681015[[#This Row],[팀]])+COUNTIFS(챔스A_791118[팀2 결과],X$39,챔스A_791118[팀2],표2_4681015[[#This Row],[팀]]) -> 0 | Y41: =COUNTIFS(챔스A_791118[팀1 결과],Y$39,챔스A_791118[팀1],표2_4681015[[#This Row],[팀]])+COUNTIFS(챔스A_791118[팀2 결과],Y$39,챔스A_791118[팀2],표2_4681015[[#This Row],[팀]]) -> 0 | Z41: =COUNTIFS(챔스A_791118[팀1 결과],Z$39,챔스A_791118[팀1],표2_4681015[[#This Row],[팀]])+COUNTIFS(챔스A_791118[팀2 결과],Z$39,챔스A_791118[팀2],표2_4681015[[#This Row],[팀]]) -> 2 | AA41: =SUMIF(챔스A_791118[팀1],표2_4681015[[#This Row],[팀]],챔스A_791118[팀1 S])+SUMIF(챔스A_791118[팀2],표2_4681015[[#This Row],[팀]],챔스A_791118[팀2 S]) -> 1 | AB41: =SUMIF(챔스A_791118[팀1],표2_4681015[[#This Row],[팀]],챔스A_791118[팀2 S])+SUMIF(챔스A_791118[팀2],표2_4681015[[#This Row],[팀]],챔스A_791118[팀1 S]) -> 6 | AC41: =표2_4681015[[#This Row],[득점]]-표2_4681015[[#This Row],[실점]] -> -5 | AD41: =표2_4681015[[#This Row],[승]]*3+표2_4681015[[#This Row],[무]] -> 0
O42: =IF(Q42="","",IF(Q42>R42,"승",IF(Q42=R42,"무",IF(Q42<R42,"패","")))) -> 승 | P42: =V34 -> 맨유 | Q42: 6 | R42: 0 | S42: =V35 -> 아우크스부르크 | T42: =IF(O42="","",IF(O42="무","무",IF(O42="승","패","승"))) -> 패 | V42: 인테르 | W42: =표2_4681015[[#This Row],[승]]+표2_4681015[[#This Row],[무]]+표2_4681015[[#This Row],[패]] -> 4 | X42: =COUNTIFS(챔스A_791118[팀1 결과],X$39,챔스A_791118[팀1],표2_4681015[[#This Row],[팀]])+COUNTIFS(챔스A_791118[팀2 결과],X$39,챔스A_791118[팀2],표2_4681015[[#This Row],[팀]]) -> 4 | Y42: =COUNTIFS(챔스A_791118[팀1 결과],Y$39,챔스A_791118[팀1],표2_4681015[[#This Row],[팀]])+COUNTIFS(챔스A_791118[팀2 결과],Y$39,챔스A_791118[팀2],표2_4681015[[#This Row],[팀]]) -> 0 | Z42: =COUNTIFS(챔스A_791118[팀1 결과],Z$39,챔스A_791118[팀1],표2_4681015[[#This Row],[팀]])+COUNTIFS(챔스A_791118[팀2 결과],Z$39,챔스A_791118[팀2],표2_4681015[[#This Row],[팀]]) -> 0 | AA42: =SUMIF(챔스A_791118[팀1],표2_4681015[[#This Row],[팀]],챔스A_791118[팀1 S])+SUMIF(챔스A_791118[팀2],표2_4681015[[#This Row],[팀]],챔스A_791118[팀2 S]) -> 15 | AB42: =SUMIF(챔스A_791118[팀1],표2_4681015[[#This Row],[팀]],챔스A_791118[팀2 S])+SUMIF(챔스A_791118[팀2],표2_4681015[[#This Row],[팀]],챔스A_791118[팀1 S]) -> 7 | AC42: =표2_4681015[[#This Row],[득점]]-표2_4681015[[#This Row],[실점]] -> 8 | AD42: =표2_4681015[[#This Row],[승]]*3+표2_4681015[[#This Row],[무]] -> 12
O43: =IF(Q43="","",IF(Q43>R43,"승",IF(Q43=R43,"무",IF(Q43<R43,"패","")))) -> 승 | P43: =V34 -> 맨유 | Q43: 3 | R43: 1 | S43: =V35 -> 아우크스부르크 | T43: =IF(O43="","",IF(O43="무","무",IF(O43="승","패","승"))) -> 패 | V43: PSV | W43: =표2_4681015[[#This Row],[승]]+표2_4681015[[#This Row],[무]]+표2_4681015[[#This Row],[패]] -> 2 | X43: =COUNTIFS(챔스A_791118[팀1 결과],X$39,챔스A_791118[팀1],표2_4681015[[#This Row],[팀]])+COUNTIFS(챔스A_791118[팀2 결과],X$39,챔스A_791118[팀2],표2_4681015[[#This Row],[팀]]) -> 0 | Y43: =COUNTIFS(챔스A_791118[팀1 결과],Y$39,챔스A_791118[팀1],표2_4681015[[#This Row],[팀]])+COUNTIFS(챔스A_791118[팀2 결과],Y$39,챔스A_791118[팀2],표2_4681015[[#This Row],[팀]]) -> 0 | Z43: =COUNTIFS(챔스A_791118[팀1 결과],Z$39,챔스A_791118[팀1],표2_4681015[[#This Row],[팀]])+COUNTIFS(챔스A_791118[팀2 결과],Z$39,챔스A_791118[팀2],표2_4681015[[#This Row],[팀]]) -> 2 | AA43: =SUMIF(챔스A_791118[팀1],표2_4681015[[#This Row],[팀]],챔스A_791118[팀1 S])+SUMIF(챔스A_791118[팀2],표2_4681015[[#This Row],[팀]],챔스A_791118[팀2 S]) -> 6 | AB43: =SUMIF(챔스A_791118[팀1],표2_4681015[[#This Row],[팀]],챔스A_791118[팀2 S])+SUMIF(챔스A_791118[팀2],표2_4681015[[#This Row],[팀]],챔스A_791118[팀1 S]) -> 9 | AC43: =표2_4681015[[#This Row],[득점]]-표2_4681015[[#This Row],[실점]] -> -3 | AD43: =표2_4681015[[#This Row],[승]]*3+표2_4681015[[#This Row],[무]] -> 0
O44: =IF(Q44="","",IF(Q44>R44,"승",IF(Q44=R44,"무",IF(Q44<R44,"패","")))) -> 승 | P44: =V34 -> 맨유 | Q44: 4 | R44: 1 | S44: =V36 -> 토트넘 | T44: =IF(O44="","",IF(O44="무","무",IF(O44="승","패","승"))) -> 패
O45: =IF(Q45="","",IF(Q45>R45,"승",IF(Q45=R45,"무",IF(Q45<R45,"패","")))) -> 패 | P45: =V34 -> 맨유 | Q45: 2 | R45: 3 | S45: =V36 -> 토트넘 | T45: =IF(O45="","",IF(O45="무","무",IF(O45="승","패","승"))) -> 승 | X45: 승 | Y45: 무 | Z45: 패
...

Sheet UCL토너먼트
E2: 8강 | F2: 준결승 | G2: 결승 | H2: 우승자
E3: 레알마드리드
E5: PSV
E7: 도르트문트 | F7: =E9 -> 맨유
E9: 맨유
E11: 뉴캐슬 | F11: =E13 -> AT마드리드
E13: AT마드리드
E15: 인터밀란 | F15: =E15 -> 인터밀란
E17: 비야레알

Sheet FA CUP
E2: 14강 | F2: 8강 | G2: 준결승 | H2: 결승 | I2: 우승자
C3: FA컵 | D3: 1 | E3: 뮌헨 | F3: =E3 -> 뮌헨
D4: - | E4: -
D5: 2 | E5: 뉴캐슬 | F5: =E5 -> 뉴캐슬
D6: 3 | E6: 맨유
D7: 4 | E7: 레알 마드리드 | F7: =E8 -> 인테르 | G7: =F7 -> 인테르
D8: 5 | E8: 인테르
D9: 6 | E9: 레버쿠젠 | F9: =E9 -> 레버쿠젠
D10: 7 | E10: 아우크스부르크
D11: 8 | E11: 도르트문트 | F11: =E11 -> 도르트문트 | G11: =F11 -> 도르트문트
D12: - | E12: -
D13: 9 | E13: 유벤투스 | F13: =E14 -> PSV
D14: 10 | E14: PSV
D15: 11 | E15: ATM | F15: =E16 -> 비야레알 | G15: =F15 -> 비야레알
D16: 12 | E16: 비야레알
D17: 13 | E17: 토트넘 | F17: =E17 -> 토트넘
D18: 14 | E18: 첼시
