Workbook
Name 슬라이서_상대팀: #N/A
Name 슬라이서_상대팀1: #N/A
Name 슬라이서_팀: #N/A
Name 슬라이서_팀1: #N/A

Sheet 내경기 진행상황
B2: ☆ 1부리그 ☆ | E2: ☆ 챔피언스 리그 ☆ | J2: ☆ FA컵 ☆
B4: 팀명 | C4: 1경기 | E4: C조 | F4: 1경기 | G4: 2경기
B5: 도르트문트 | C5: ='1부리그'!Q11 -> 미진행 | E5: 유벤투스 | F5: =월드컵!T35 -> 패 | G5: =월드컵!T36 -> 패 | J5: [14강] 레알 마드리드
B6: 도르트문트 | C6: ='1부리그'!Q12 -> 미진행 | E6: PSV | F6: =월드컵!O39 -> 승 | G6: =월드컵!O40 -> 승 | J6: [8강]
B7: 뉴캐슬 | C7: ='1부리그'!Q13 -> 미진행 | E7: [8강] | J7: [4강]
B8: 뉴캐슬 | C8: ='1부리그'!Q14 -> 미진행 | E8: [4강] | J8: [결승]
B9: 맨유 | C9: ='1부리그'!Q15 -> 미진행 | E9: [결승]
B10: 맨유 | C10: ='1부리그'!Q16 -> 미진행
B11: 비야레알 | C11: ='1부리그'!Q17 -> 미진행
B12: 비야레알 | C12: ='1부리그'!Q18 -> 미진행
B13: 뮌헨 | C13: ='1부리그'!Q19 -> 미진행
B14: 뮌헨 | C14: ='1부리그'!Q20 -> 미진행

Sheet 1부리그
B2: 순위 | C2: 팀명 | D2: 승 점 | E2: 경기 | F2: 승 | G2: 무 | H2: 패 | I2: 득점 | J2: 실점 | K2: 득실 | M2: 경기당 승점 | N2: 최대 승점
B3: 1 | C3: {=_xlfn._xlws.SORT(_xlfn._xlws.SORT(_xlfn._xlws.SORT(_xlfn._xlws.SORT((_xlfn._xlws.FILTER(표1부리그[],표1부리그[경기]>(-1),)),9,-1),7,-1),8,1),2,-1)} -> 독일 | D3: 0 | E3: 0 | F3: 0 | G3: 0 | H3: 0 | I3: 0 | J3: 0 | K3: 0 | M3: =IFERROR(D3/E3,0) -> 0 | N3: =(10-E3)*3+D3 -> 30
B4: 2 | C4: 미국 | D4: 0 | E4: 0 | F4: 0 | G4: 0 | H4: 0 | I4: 0 | J4: 0 | K4: 0 | M4: =IFERROR(D4/E4,0) -> 0 | N4: =(10-E4)*3+D4 -> 30
B5: 3 | C5: 아르헨티나 | D5: 0 | E5: 0 | F5: 0 | G5: 0 | H5: 0 | I5: 0 | J5: 0 | K5: 0 | M5: =IFERROR(D5/E5,0) -> 0 | N5: =(10-E5)*3+D5 -> 30
B6: 4 | C6: 오스트리아 | D6: 0 | E6: 0 | F6: 0 | G6: 0 | H6: 0 | I6: 0 | J6: 0 | K6: 0 | M6: =IFERROR(D6/E6,0) -> 0 | N6: =(10-E6)*3+D6 -> 30
B7: 5 | C7: 잉글랜드 | D7: 0 | E7: 0 | F7: 0 | G7: 0 | H7: 0 | I7: 0 | J7: 0 | K7: 0 | M7: =IFERROR(D7/E7,0) -> 0 | N7: =(10-E7)*3+D7 -> 30
B8: 6 | C8: 코트디부아르 | D8: 0 | E8: 0 | F8: 0 | G8: 0 | H8: 0 | I8: 0 | J8: 0 | K8: 0 | M8: =IFERROR(D8/E8,0) -> 0 | N8: =(10-E8)*3+D8 -> 30
P10: NO | Q10: 결과 | R10: 팀 | S10: 득점 | T10: 실점 | U10: 상대팀
P11: 1 | Q11: =IF(표1부리그경기결과[[#This Row],[득점]]="","미진행",IF(표1부리그경기결과[[#This Row],[득점]]>표1부리그경기결과[[#This Row],[실점]],"승",IF(표1부리그경기결과[[#This Row],[득점]]=표1부리그경기결과[[#This Row],[실점]],"무",IF(표1부리그경기결과[[#This Row],[득점]]<표1부리그경기결과[[#This Row],[실점]],"패","미진행")))) -> 미진행 | R11: 인테르 | U11: 도르트문트
P12: 2 | Q12: =IF(표1부리그경기결과[[#This Row],[득점]]="","미진행",IF(표1부리그경기결과[[#This Row],[득점]]>표1부리그경기결과[[#This Row],[실점]],"승",IF(표1부리그경기결과[[#This Row],[득점]]=표1부리그경기결과[[#This Row],[실점]],"무",IF(표1부리그경기결과[[#This Row],[득점]]<표1부리그경기결과[[#This Row],[실점]],"패","미진행")))) -> 미진행 | R12: 인테르 | U12: 도르트문트
P13: 3 | Q13: =IF(표1부리그경기결과[[#This Row],[득점]]="","미진행",IF(표1부리그경기결과[[#This Row],[득점]]>표1부리그경기결과[[#This Row],[실점]],"승",IF(표1부리그경기결과[[#This Row],[득점]]=표1부리그경기결과[[#This Row],[실점]],"무",IF(표1부리그경기결과[[#This Row],[득점]]<표1부리그경기결과[[#This Row],[실점]],"패","미진행")))) -> 미진행 | R13: 인테르 | U13: 뉴캐슬
P14: 4 | Q14: =IF(표1부리그경기결과[[#This Row],[득점]]="","미진행",IF(표1부리그경기결과[[#This Row],[득점]]>표1부리그경기결과[[#This Row],[실점]],"승",IF(표1부리그경기결과[[#This Row],[득점]]=표1부리그경기결과[[#This Row],[실점]],"무",IF(표1부리그경기결과[[#This Row],[득점]]<표1부리그경기결과[[#This Row],[실점]],"패","미진행")))) -> 미진행 | R14: 인테르 | U14: 뉴캐슬
P15: 5 | Q15: =IF(표1부리그경기결과[[#This Row],[득점]]="","미진행",IF(표1부리그경기결과[[#This Row],[득점]]>표1부리그경기결과[[#This Row],[실점]],"승",IF(표1부리그경기결과[[#This Row],[득점]]=표1부리그경기결과[[#This Row],[실점]],"무",IF(표1부리그경기결과[[#This Row],[득점]]<표1부리그경기결과[[#This Row],[실점]],"패","미진행")))) -> 미진행 | R15: 인테르 | U15: 맨유
P16: 6 | Q16: =IF(표1부리그경기결과[[#This Row],[득점]]="","미진행",IF(표1부리그경기결과[[#This Row],[득점]]>표1부리그경기결과[[#This Row],[실점]],"승",IF(표1부리그경기결과[[#This Row],[득점]]=표1부리그경기결과[[#This Row],[실점]],"무",IF(표1부리그경기결과[[#This Row],[득점]]<표1부리그경기결과[[#This Row],[실점]],"패","미진행")))) -> 미진행 | R16: 인테르 | U16: 맨유
P17: 7 | Q17: =IF(표1부리그경기결과[[#This Row],[득점]]="","미진행",IF(표1부리그경기결과[[#This Row],[득점]]>표1부리그경기결과[[#This Row],[실점]],"승",IF(표1부리그경기결과[[#This Row],[득점]]=표1부리그경기결과[[#This Row],[실점]],"무",IF(표1부리그경기결과[[#This Row],[득점]]<표1부리그경기결과[[#This Row],[실점]],"패","미진행")))) -> 미진행 | R17: 인테르 | U17: 비야레알
P18: 8 | Q18: =IF(표1부리그경기결과[[#This Row],[득점]]="","미진행",IF(표1부리그경기결과[[#This Row],[득점]]>표1부리그경기결과[[#This Row],[실점]],"승",IF(표1부리그경기결과[[#This Row],[득점]]=표1부리그경기결과[[#This Row],[실점]],"무",IF(표1부리그경기결과[[#This Row],[득점]]<표1부리그경기결과[[#This Row],[실점]],"패","미진행")))) -> 미진행 | R18: 인테르 | U18: 비야레알
P19: 9 | Q19: =IF(표1부리그경기결과[[#This Row],[득점]]="","미진행",IF(표1부리그경기결과[[#This Row],[득점]]>표1부리그경기결과[[#This Row],[실점]],"승",IF(표1부리그경기결과[[#This Row],[득점]]=표1부리그경기결과[[#This Row],[실점]],"무",IF(표1부리그경기결과[[#This Row],[득점]]<표1부리그경기결과[[#This Row],[실점]],"패","미진행")))) -> 미진행 | R19: 인테르 | U19: 뮌헨
P20: 10 | Q20: =IF(표1부리그경기결과[[#This Row],[득점]]="","미진행",IF(표1부리그경기결과[[#This Row],[득점]]>표1부리그경기결과[[#This Row],[실점]],"승",IF(표1부리그경기결과[[#This Row],[득점]]=표1부리그경기결과[[#This Row],[실점]],"무",IF(표1부리그경기결과[[#This Row],[득점]]<표1부리그경기결과[[#This Row],[실점]],"패","미진행")))) -> 미진행 | R20: 인테르 | U20: 뮌헨
P21: 11 | Q21: =IF(표1부리그경기결과[[#This Row],[득점]]="","미진행",IF(표1부리그경기결과[[#This Row],[득점]]>표1부리그경기결과[[#This Row],[실점]],"승",IF(표1부리그경기결과[[#This Row],[득점]]=표1부리그경기결과[[#This Row],[실점]],"무",IF(표1부리그경기결과[[#This Row],[득점]]<표1부리그경기결과[[#This Row],[실점]],"패","미진행")))) -> 미진행 | R21: 뉴캐슬 | U21: 도르트문트
P22: 12 | Q22: =IF(표1부리그경기결과[[#This Row],[득점]]="","미진행",IF(표1부리그경기결과[[#This Row],[득점]]>표1부리그경기결과[[#This Row],[실점]],"승",IF(표1부리그경기결과[[#This Row],[득점]]=표1부리그경기결과[[#This Row],[실점]],"무",IF(표1부리그경기결과[[#This Row],[득점]]<표1부리그경기결과[[#This Row],[실점]],"패","미진행")))) -> 미진행 | R22: 뉴캐슬 | U22: 도르트문트
... P70: 60 | Q70: =IF(표1부리그경기결과[[#This Row],[득점]]="","미진행",IF(표1부리그경기결과[[#This Row],[득점]]>표1부리그경기결과[[#This Row],[실점]],"승",IF(표1부리그경기결과[[#This Row],[득점]]=표1부리그경기결과[[#This Row],[실점]],"무",IF(표1부리그경기결과[[#This Row],[득점]]<표1부리그경기결과[[#This Row],[실점]],"패","미진행")))) -> 미진행 | R70: 뮌헨 | U70: 비야레알

Sheet Sheet2
C18: 프랑스 | D18: 대한민국 | E18: 스페인 | F18: 코트디부아르 | G18: 루마니아 | H18: 오스트리아 | I18: 브라질 | J18: 미국 | K18: 포르투갈 | L18: 크로아티아 | M18: 독일 | N18: 아르헨티나 | O18: 이탈리아 | P18: 잉글랜드
D20: 프랑스
D21: 대한민국
D22: 스페인
D23: 코트디부아르
D24: 루마니아
D25: 오스트리아
D26: 브라질
D27: 미국
D28: 포르투갈
D29: 크로아티아
D30: 독일
D31: 아르헨티나
... D33: 잉글랜드

Sheet 리그테이블 DB
L2: 승 | M2: 무 | N2: 패
C3: 팀 | D3: 승점점수 | E3: 경기 | F3: 승 | G3: 무 | H3: 패 | I3: 득점 | J3: 실점 | K3: 득실 | M3: 팀 | N3: 승점점수 | O3: 경기 | P3: 승 | Q3: 무 | R3: 패 | S3: 득점 | T3: 실점 | U3: 득실
C4: 독일 | D4: =표1부리그[[#This Row],[승]]*3+표1부리그[[#This Row],[무]] -> 0 | E4: =표1부리그[[#This Row],[승]]+표1부리그[[#This Row],[무]]+표1부리그[[#This Row],[패]] -> 0 | F4: =COUNTIFS(표1부리그경기결과[팀],표1부리그[[#This Row],[팀]],표1부리그경기결과[결과],$L$2) -> 0 | G4: =COUNTIFS(표1부리그경기결과[팀],표1부리그[[#This Row],[팀]],표1부리그경기결과[결과],$M$2) -> 0 | H4: =COUNTIFS(표1부리그경기결과[팀],표1부리그[[#This Row],[팀]],표1부리그경기결과[결과],$N$2) -> 0 | I4: =SUMIFS(표1부리그경기결과[득점],표1부리그경기결과[팀],표1부리그[[#This Row],[팀]]) -> 0 | J4: =SUMIFS(표1부리그경기결과[실점],표1부리그경기결과[팀],표1부리그[[#This Row],[팀]]) -> 0 | K4: =표1부리그[[#This Row],[득점]]-표1부리그[[#This Row],[실점]] -> 0 | M4: 대한민국 | N4: =표2부리그[[#This Row],[승]]*3+표2부리그[[#This Row],[무]] -> 6 | O4: =표2부리그[[#This Row],[승]]+표2부리그[[#This Row],[무]]+표2부리그[[#This Row],[패]] -> 10 | P4: =COUNTIFS(표100[팀],표2부리그[[#This Row],[팀]],표100[결과],$L$2) -> 1 | Q4: =COUNTIFS(표100[팀],표2부리그[[#This Row],[팀]],표100[결과],$M$2) -> 3 | R4: =COUNTIFS(표100[팀],표2부리그[[#This Row],[팀]],표100[결과],$N$2) -> 6 | S4: =SUMIFS(표100[득점],표100[팀],표2부리그[[#This Row],[팀]]) -> 13 | T4: =SUMIFS(표100[실점],표100[팀],표2부리그[[#This Row],[팀]]) -> 25 | U4: =표2부리그[[#This Row],[득점]]-표2부리그[[#This Row],[실점]] -> -12
C5: 미국 | D5: =표1부리그[[#This Row],[승]]*3+표1부리그[[#This Row],[무]] -> 0 | E5: =표1부리그[[#This Row],[승]]+표1부리그[[#This Row],[무]]+표1부리그[[#This Row],[패]] -> 0 | F5: =COUNTIFS(표1부리그경기결과[팀],표1부리그[[#This Row],[팀]],표1부리그경기결과[결과],$L$2) -> 0 | G5: =COUNTIFS(표1부리그경기결과[팀],표1부리그[[#This Row],[팀]],표1부리그경기결과[결과],$M$2) -> 0 | H5: =COUNTIFS(표1부리그경기결과[팀],표1부리그[[#This Row],[팀]],표1부리그경기결과[결과],$N$2) -> 0 | I5: =SUMIFS(표1부리그경기결과[득점],표1부리그경기결과[팀],표1부리그[[#This Row],[팀]]) -> 0 | J5: =SUMIFS(표1부리그경기결과[실점],표1부리그경기결과[팀],표1부리그[[#This Row],[팀]]) -> 0 | K5: =표1부리그[[#This Row],[득점]]-표1부리그[[#This Row],[실점]] -> 0 | M5: 루마니아 | N5: =표2부리그[[#This Row],[승]]*3+표2부리그[[#This Row],[무]] -> 5 | O5: =표2부리그[[#This Row],[승]]+표2부리그[[#This Row],[무]]+표2부리그[[#This Row],[패]] -> 8 | P5: =COUNTIFS(표100[팀],표2부리그[[#This Row],[팀]],표100[결과],$L$2) -> 1 | Q5: =COUNTIFS(표100[팀],표2부리그[[#This Row],[팀]],표100[결과],$M$2) -> 2 | R5: =COUNTIFS(표100[팀],표2부리그[[#This Row],[팀]],표100[결과],$N$2) -> 5 | S5: =SUMIFS(표100[득점],표100[팀],표2부리그[[#This Row],[팀]]) -> 8 | T5: =SUMIFS(표100[실점],표100[팀],표2부리그[[#This Row],[팀]]) -> 20 | U5: =표2부리그[[#This Row],[득점]]-표2부리그[[#This Row],[실점]] -> -12
C6: 아르헨티나 | D6: =표1부리그[[#This Row],[승]]*3+표1부리그[[#This Row],[무]] -> 0 | E6: =표1부리그[[#This Row],[승]]+표1부리그[[#This Row],[무]]+표1부리그[[#This Row],[패]] -> 0 | F6: =COUNTIFS(표1부리그경기결과[팀],표1부리그[[#This Row],[팀]],표1부리그경기결과[결과],$L$2) -> 0 | G6: =COUNTIFS(표1부리그경기결과[팀],표1부리그[[#This Row],[팀]],표1부리그경기결과[결과],$M$2) -> 0 | H6: =COUNTIFS(표1부리그경기결과[팀],표1부리그[[#This Row],[팀]],표1부리그경기결과[결과],$N$2) -> 0 | I6: =SUMIFS(표1부리그경기결과[득점],표1부리그경기결과[팀],표1부리그[[#This Row],[팀]]) -> 0 | J6: =SUMIFS(표1부리그경기결과[실점],표1부리그경기결과[팀],표1부리그[[#This Row],[팀]]) -> 0 | K6: =표1부리그[[#This Row],[득점]]-표1부리그[[#This Row],[실점]] -> 0 | M6: 브라질 | N6: =표2부리그[[#This Row],[승]]*3+표2부리그[[#This Row],[무]] -> 14 | O6: =표2부리그[[#This Row],[승]]+표2부리그[[#This Row],[무]]+표2부리그[[#This Row],[패]] -> 10 | P6: =COUNTIFS(표100[팀],표2부리그[[#This Row],[팀]],표100[결과],$L$2) -> 4 | Q6: =COUNTIFS(표100[팀],표2부리그[[#This Row],[팀]],표100[결과],$M$2) -> 2 | R6: =COUNTIFS(표100[팀],표2부리그[[#This Row],[팀]],표100[결과],$N$2) -> 4 | S6: =SUMIFS(표100[득점],표100[팀],표2부리그[[#This Row],[팀]]) -> 24 | T6: =SUMIFS(표100[실점],표100[팀],표2부리그[[#This Row],[팀]]) -> 28 | U6: =표2부리그[[#This Row],[득점]]-표2부리그[[#This Row],[실점]] -> -4
C7: 오스트리아 | D7: =표1부리그[[#This Row],[승]]*3+표1부리그[[#This Row],[무]] -> 0 | E7: =표1부리그[[#This Row],[승]]+표1부리그[[#This Row],[무]]+표1부리그[[#This Row],[패]] -> 0 | F7: =COUNTIFS(표1부리그경기결과[팀],표1부리그[[#This Row],[팀]],표1부리그경기결과[결과],$L$2) -> 0 | G7: =COUNTIFS(표1부리그경기결과[팀],표1부리그[[#This Row],[팀]],표1부리그경기결과[결과],$M$2) -> 0 | H7: =COUNTIFS(표1부리그경기결과[팀],표1부리그[[#This Row],[팀]],표1부리그경기결과[결과],$N$2) -> 0 | I7: =SUMIFS(표1부리그경기결과[득점],표1부리그경기결과[팀],표1부리그[[#This Row],[팀]]) -> 0 | J7: =SUMIFS(표1부리그경기결과[실점],표1부리그경기결과[팀],표1부리그[[#This Row],[팀]]) -> 0 | K7: =표1부리그[[#This Row],[득점]]-표1부리그[[#This Row],[실점]] -> 0 | M7: 스페인 | N7: =표2부리그[[#This Row],[승]]*3+표2부리그[[#This Row],[무]] -> 34 | O7: =표2부리그[[#This Row],[승]]+표2부리그[[#This Row],[무]]+표2부리그[[#This Row],[패]] -> 14 | P7: =COUNTIFS(표100[팀],표2부리그[[#This Row],[팀]],표100[결과],$L$2) -> 11 | Q7: =COUNTIFS(표100[팀],표2부리그[[#This Row],[팀]],표100[결과],$M$2) -> 1 | R7: =COUNTIFS(표100[팀],표2부리그[[#This Row],[팀]],표100[결과],$N$2) -> 2 | S7: =SUMIFS(표100[득점],표100[팀],표2부리그[[#This Row],[팀]]) -> 39 | T7: =SUMIFS(표100[실점],표100[팀],표2부리그[[#This Row],[팀]]) -> 19 | U7: =표2부리그[[#This Row],[득점]]-표2부리그[[#This Row],[실점]] -> 20
C8: 잉글랜드 | D8: =표1부리그[[#This Row],[승]]*3+표1부리그[[#This Row],[무]] -> 0 | E8: =표1부리그[[#This Row],[승]]+표1부리그[[#This Row],[무]]+표1부리그[[#This Row],[패]] -> 0 | F8: =COUNTIFS(표1부리그경기결과[팀],표1부리그[[#This Row],[팀]],표1부리그경기결과[결과],$L$2) -> 0 | G8: =COUNTIFS(표1부리그경기결과[팀],표1부리그[[#This Row],[팀]],표1부리그경기결과[결과],$M$2) -> 0 | H8: =COUNTIFS(표1부리그경기결과[팀],표1부리그[[#This Row],[팀]],표1부리그경기결과[결과],$N$2) -> 0 | I8: =SUMIFS(표1부리그경기결과[득점],표1부리그경기결과[팀],표1부리그[[#This Row],[팀]]) -> 0 | J8: =SUMIFS(표1부리그경기결과[실점],표1부리그경기결과[팀],표1부리그[[#This Row],[팀]]) -> 0 | K8: =표1부리그[[#This Row],[득점]]-표1부리그[[#This Row],[실점]] -> 0 | M8: 이탈리아 | N8: =표2부리그[[#This Row],[승]]*3+표2부리그[[#This Row],[무]] -> 9 | O8: =표2부리그[[#This Row],[승]]+표2부리그[[#This Row],[무]]+표2부리그[[#This Row],[패]] -> 8 | P8: =COUNTIFS(표100[팀],표2부리그[[#This Row],[팀]],표100[결과],$L$2) -> 2 | Q8: =COUNTIFS(표100[팀],표2부리그[[#This Row],[팀]],표100[결과],$M$2) -> 3 | R8: =COUNTIFS(표100[팀],표2부리그[[#This Row],[팀]],표100[결과],$N$2) -> 3 | S8: =SUMIFS(표100[득점],표100[팀],표2부리그[[#This Row],[팀]]) -> 16 | T8: =SUMIFS(표100[실점],표100[팀],표2부리그[[#This Row],[팀]]) -> 19 | U8: =표2부리그[[#This Row],[득점]]-표2부리그[[#This Row],[실점]] -> -3
C9: 코트디부아르 | D9: =표1부리그[[#This Row],[승]]*3+표1부리그[[#This Row],[무]] -> 0 | E9: =표1부리그[[#This Row],[승]]+표1부리그[[#This Row],[무]]+표1부리그[[#This Row],[패]] -> 0 | F9: =COUNTIFS(표1부리그경기결과[팀],표1부리그[[#This Row],[팀]],표1부리그경기결과[결과],$L$2) -> 0 | G9: =COUNTIFS(표1부리그경기결과[팀],표1부리그[[#This Row],[팀]],표1부리그경기결과[결과],$M$2) -> 0 | H9: =COUNTIFS(표1부리그경기결과[팀],표1부리그[[#This Row],[팀]],표1부리그경기결과[결과],$N$2) -> 0 | I9: =SUMIFS(표1부리그경기결과[득점],표1부리그경기결과[팀],표1부리그[[#This Row],[팀]]) -> 0 | J9: =SUMIFS(표1부리그경기결과[실점],표1부리그경기결과[팀],표1부리그[[#This Row],[팀]]) -> 0 | K9: =표1부리그[[#This Row],[득점]]-표1부리그[[#This Row],[실점]] -> 0 | M9: 크로아티아 | N9: =표2부리그[[#This Row],[승]]*3+표2부리그[[#This Row],[무]] -> 3 | O9: =표2부리그[[#This Row],[승]]+표2부리그[[#This Row],[무]]+표2부리그[[#This Row],[패]] -> 8 | P9: =COUNTIFS(표100[팀],표2부리그[[#This Row],[팀]],표100[결과],$L$2) -> 1 | Q9: =COUNTIFS(표100[팀],표2부리그[[#This Row],[팀]],표100[결과],$M$2) -> 0 | R9: =COUNTIFS(표100[팀],표2부리그[[#This Row],[팀]],표100[결과],$N$2) -> 7 | S9: =SUMIFS(표100[득점],표100[팀],표2부리그[[#This Row],[팀]]) -> 7 | T9: =SUMIFS(표100[실점],표100[팀],표2부리그[[#This Row],[팀]]) -> 23 | U9: =표2부리그[[#This Row],[득점]]-표2부리그[[#This Row],[실점]] -> -16
M10: 포르투갈 | N10: =표2부리그[[#This Row],[승]]*3+표2부리그[[#This Row],[무]] -> 3 | O10: =표2부리그[[#This Row],[승]]+표2부리그[[#This Row],[무]]+표2부리그[[#This Row],[패]] -> 2 | P10: =COUNTIFS(표100[팀],표2부리그[[#This Row],[팀]],표100[결과],$L$2) -> 1 | Q10: =COUNTIFS(표100[팀],표2부리그[[#This Row],[팀]],표100[결과],$M$2) -> 0 | R10: =COUNTIFS(표100[팀],표2부리그[[#This Row],[팀]],표100[결과],$N$2) -> 1 | S10: =SUMIFS(표100[득점],표100[팀],표2부리그[[#This Row],[팀]]) -> 2 | T10: =SUMIFS(표100[실점],표100[팀],표2부리그[[#This Row],[팀]]) -> 2 | U10: =표2부리그[[#This Row],[득점]]-표2부리그[[#This Row],[실점]] -> 0
M11: 프랑스 | N11: =표2부리그[[#This Row],[승]]*3+표2부리그[[#This Row],[무]] -> 28 | O11: =표2부리그[[#This Row],[승]]+표2부리그[[#This Row],[무]]+표2부리그[[#This Row],[패]] -> 12 | P11: =COUNTIFS(표100[팀],표2부리그[[#This Row],[팀]],표100[결과],$L$2) -> 9 | Q11: =COUNTIFS(표100[팀],표2부리그[[#This Row],[팀]],표100[결과],$M$2) -> 1 | R11: =COUNTIFS(표100[팀],표2부리그[[#This Row],[팀]],표100[결과],$N$2) -> 2 | S11: =SUMIFS(표100[득점],표100[팀],표2부리그[[#This Row],[팀]]) -> 47 | T11: =SUMIFS(표100[실점],표100[팀],표2부리그[[#This Row],[팀]]) -> 20 | U11: =표2부리그[[#This Row],[득점]]-표2부리그[[#This Row],[실점]] -> 27

Sheet 2부리그
B2: 순위 | C2: 팀명 | D2: 승 점 | E2: 경기 | F2: 승 | G2: 무 | H2: 패 | I2: 득점 | J2: 실점 | K2: 득실 | M2: 경기당 승점 | N2: 최대 승점 | W2: 대한민국
B3: 1 | C3: {=_xlfn._xlws.SORT(_xlfn._xlws.SORT(_xlfn._xlws.SORT(_xlfn._xlws.SORT((_xlfn._xlws.FILTER(표2부리그[],표2부리그[경기]>(-1),)),9,-1),7,-1),8,1),2,-1)} -> 스페인 | D3: 34 | E3: 14 | F3: 11 | G3: 1 | H3: 2 | I3: 39 | J3: 19 | K3: 20 | M3: =IFERROR(D3/E3,0) -> 2.4285714 | N3: =(14-E3)*3+D3 -> 34 | W3: 루마니아
B4: 2 | C4: 프랑스 | D4: 28 | E4: 12 | F4: 9 | G4: 1 | H4: 2 | I4: 47 | J4: 20 | K4: 27 | M4: =IFERROR(D4/E4,0) -> 2.3333333 | N4: =(14-E4)*3+D4 -> 34 | W4: 브라질
B5: 3 | C5: 브라질 | D5: 14 | E5: 10 | F5: 4 | G5: 2 | H5: 4 | I5: 24 | J5: 28 | K5: -4 | M5: =IFERROR(D5/E5,0) -> 1.4 | N5: =(14-E5)*3+D5 -> 26 | W5: 스페인
B6: 4 | C6: 이탈리아 | D6: 9 | E6: 8 | F6: 2 | G6: 3 | H6: 3 | I6: 16 | J6: 19 | K6: -3 | M6: =IFERROR(D6/E6,0) -> 1.125 | N6: =(14-E6)*3+D6 -> 27 | W6: 이탈리아
B7: 5 | C7: 대한민국 | D7: 6 | E7: 10 | F7: 1 | G7: 3 | H7: 6 | I7: 13 | J7: 25 | K7: -12 | M7: =IFERROR(D7/E7,0) -> 0.6 | N7: =(14-E7)*3+D7 -> 18 | W7: 크로아티아
B8: 6 | C8: 루마니아 | D8: 5 | E8: 8 | F8: 1 | G8: 2 | H8: 5 | I8: 8 | J8: 20 | K8: -12 | M8: =IFERROR(D8/E8,0) -> 0.625 | N8: =(14-E8)*3+D8 -> 23 | W8: 포르투갈
B9: 7 | C9: 포르투갈 | D9: 3 | E9: 2 | F9: 1 | G9: 0 | H9: 1 | I9: 2 | J9: 2 | K9: 0 | M9: =IFERROR(D9/E9,0) -> 1.5 | N9: =(14-E9)*3+D9 -> 39 | W9: 프랑스
B10: 8 | C10: 크로아티아 | D10: 3 | E10: 8 | F10: 1 | G10: 0 | H10: 7 | I10: 7 | J10: 23 | K10: -16 | M10: =IFERROR(D10/E10,0) -> 0.375 | N10: =(14-E10)*3+D10 -> 21
P12: NO | Q12: 결과 | R12: 팀 | S12: 득점 | T12: 실점 | U12: 상대팀
P13: 1 | Q13: =IF(표100[[#This Row],[득점]]="","미진행",IF(표100[[#This Row],[득점]]>표100[[#This Row],[실점]],"승",IF(표100[[#This Row],[득점]]=표100[[#This Row],[실점]],"무",IF(표100[[#This Row],[득점]]<표100[[#This Row],[실점]],"패","미진행")))) -> 무 | R13: 대한민국 | S13: 2 | T13: 2 | U13: 루마니아
P14: 2 | Q14: =IF(표100[[#This Row],[득점]]="","미진행",IF(표100[[#This Row],[득점]]>표100[[#This Row],[실점]],"승",IF(표100[[#This Row],[득점]]=표100[[#This Row],[실점]],"무",IF(표100[[#This Row],[득점]]<표100[[#This Row],[실점]],"패","미진행")))) -> 승 | R14: 대한민국 | S14: 2 | T14: 0 | U14: 루마니아
P15: 3 | Q15: =IF(표100[[#This Row],[득점]]="","미진행",IF(표100[[#This Row],[득점]]>표100[[#This Row],[실점]],"승",IF(표100[[#This Row],[득점]]=표100[[#This Row],[실점]],"무",IF(표100[[#This Row],[득점]]<표100[[#This Row],[실점]],"패","미진행")))) -> 패 | R15: 대한민국 | S15: 2 | T15: 4 | U15: 브라질
P16: 4 | Q16: =IF(표100[[#This Row],[득점]]="","미진행",IF(표100[[#This Row],[득점]]>표100[[#This Row],[실점]],"승",IF(표100[[#This Row],[득점]]=표100[[#This Row],[실점]],"무",IF(표100[[#This Row],[득점]]<표100[[#This Row],[실점]],"패","미진행")))) -> 패 | R16: 대한민국 | S16: 1 | T16: 4 | U16: 브라질
P17: 5 | Q17: =IF(표100[[#This Row],[득점]]="","미진행",IF(표100[[#This Row],[득점]]>표100[[#This Row],[실점]],"승",IF(표100[[#This Row],[득점]]=표100[[#This Row],[실점]],"무",IF(표100[[#This Row],[득점]]<표100[[#This Row],[실점]],"패","미진행")))) -> 패 | R17: 대한민국 | S17: 2 | T17: 3 | U17: 스페인
P18: 6 | Q18: =IF(표100[[#This Row],[득점]]="","미진행",IF(표100[[#This Row],[득점]]>표100[[#This Row],[실점]],"승",IF(표100[[#This Row],[득점]]=표100[[#This Row],[실점]],"무",IF(표100[[#This Row],[득점]]<표100[[#This Row],[실점]],"패","미진행")))) -> 패 | R18: 대한민국 | S18: 0 | T18: 1 | U18: 스페인
P19: 7 | Q19: =IF(표100[[#This Row],[득점]]="","미진행",IF(표100[[#This Row],[득점]]>표100[[#This Row],[실점]],"승",IF(표100[[#This Row],[득점]]=표100[[#This Row],[실점]],"무",IF(표100[[#This Row],[득점]]<표100[[#This Row],[실점]],"패","미진행")))) -> 패 | R19: 대한민국 | S19: 0 | T19: 2 | U19: 이탈리아
P20: 8 | Q20: =IF(표100[[#This Row],[득점]]="","미진행",IF(표100[[#This Row],[득점]]>표100[[#This Row],[실점]],"승",IF(표100[[#This Row],[득점]]=표100[[#This Row],[실점]],"무",IF(표100[[#This Row],[득점]]<표100[[#This Row],[실점]],"패","미진행")))) -> 무 | R20: 대한민국 | S20: 3 | T20: 3 | U20: 이탈리아
P21: 9 | Q21: =IF(표100[[#This Row],[득점]]="","미진행",IF(표100[[#This Row],[득점]]>표100[[#This Row],[실점]],"승",IF(표100[[#This Row],[득점]]=표100[[#This Row],[실점]],"무",IF(표100[[#This Row],[득점]]<표100[[#This Row],[실점]],"패","미진행")))) -> 미진행 | R21: 대한민국 | U21: 크로아티아
P22: 10 | Q22: =IF(표100[[#This Row],[득점]]="","미진행",IF(표100[[#This Row],[득점]]>표100[[#This Row],[실점]],"승",IF(표100[[#This Row],[득점]]=표100[[#This Row],[실점]],"무",IF(표100[[#This Row],[득점]]<표100[[#This Row],[실점]],"패","미진행")))) -> 미진행 | R22: 대한민국 | U22: 크로아티아
P23: 11 | Q23: =IF(표100[[#This Row],[득점]]="","미진행",IF(표100[[#This Row],[득점]]>표100[[#This Row],[실점]],"승",IF(표100[[#This Row],[득점]]=표100[[#This Row],[실점]],"무",IF(표100[[#This Row],[득점]]<표100[[#This Row],[실점]],"패","미진행")))) -> 미진행 | R23: 대한민국 | U23: 포르투갈
P24: 12 | Q24: =IF(표100[[#This Row],[득점]]="","미진행",IF(표100[[#This Row],[득점]]>표100[[#This Row],[실점]],"승",IF(표100[[#This Row],[득점]]=표100[[#This Row],[실점]],"무",IF(표100[[#This Row],[득점]]<표100[[#This Row],[실점]],"패","미진행")))) -> 미진행 | R24: 대한민국 | U24: 포르투갈
P25: 13 | Q25: =IF(표100[[#This Row],[득점]]="","미진행",IF(표100[[#This Row],[득점]]>표100[[#This Row],[실점]],"승",IF(표100[[#This Row],[득점]]=표100[[#This Row],[실점]],"무",IF(표100[[#This Row],[득점]]<표100[[#This Row],[실점]],"패","미진행")))) -> 무 | R25: 대한민국 | S25: 1 | T25: 1 | U25: 프랑스
P26: 14 | Q26: =IF(표100[[#This Row],[득점]]="","미진행",IF(표100[[#This Row],[득점]]>표100[[#This Row],[실점]],"승",IF(표100[[#This Row],[득점]]=표100[[#This Row],[실점]],"무",IF(표100[[#This Row],[득점]]<표100[[#This Row],[실점]],"패","미진행")))) -> 패 | R26: 대한민국 | S26: 0 | T26: 5 | U26: 프랑스
P27: 15 | Q27: =IF(표100[[#This Row],[득점]]="","미진행",IF(표100[[#This Row],[득점]]>표100[[#This Row],[실점]],"승",IF(표100[[#This Row],[득점]]=표100[[#This Row],[실점]],"무",IF(표100[[#This Row],[득점]]<표100[[#This Row],[실점]],"패","미진행")))) -> 무 | R27: 루마니아 | S27: 2 | T27: 2 | U27: 대한민국
P28: 16 | Q28: =IF(표100[[#This Row],[득점]]="","미진행",IF(표100[[#This Row],[득점]]>표100[[#This Row],[실점]],"승",IF(표100[[#This Row],[득점]]=표100[[#This Row],[실점]],"무",IF(표100[[#This Row],[득점]]<표100[[#This Row],[실점]],"패","미진행")))) -> 패 | R28: 루마니아 | S28: 0 | T28: 2 | U28: 대한민국
P29: 17 | Q29: =IF(표100[[#This Row],[득점]]="","미진행",IF(표100[[#This Row],[득점]]>표100[[#This Row],[실점]],"승",IF(표100[[#This Row],[득점]]=표100[[#This Row],[실점]],"무",IF(표100[[#This Row],[득점]]<표100[[#This Row],[실점]],"패","미진행")))) -> 미진행 | R29: 루마니아 | U29: 브라질
P30: 18 | Q30: =IF(표100[[#This Row],[득점]]="","미진행",IF(표100[[#This Row],[득점]]>표100[[#This Row],[실점]],"승",IF(표100[[#This Row],[득점]]=표100[[#This Row],[실점]],"무",IF(표100[[#This Row],[득점]]<표100[[#This Row],[실점]],"패","미진행")))) -> 미진행 | R30: 루마니아 | U30: 브라질
P31: 19 | Q31: =IF(표100[[#This Row],[득점]]="","미진행",IF(표100[[#This Row],[득점]]>표100[[#This Row],[실점]],"승",IF(표100[[#This Row],[득점]]=표100[[#This Row],[실점]],"무",IF(표100[[#This Row],[득점]]<표100[[#This Row],[실점]],"패","미진행")))) -> 무 | R31: 루마니아 | S31: 1 | T31: 1 | U31: 스페인
P32: 20 | Q32: =IF(표100[[#This Row],[득점]]="","미진행",IF(표100[[#This Row],[득점]]>표100[[#This Row],[실점]],"승",IF(표100[[#This Row],[득점]]=표100[[#This Row],[실점]],"무",IF(표100[[#This Row],[득점]]<표100[[#This Row],[실점]],"패","미진행")))) -> 패 | R32: 루마니아 | S32: 0 | T32: 1 | U32: 스페인
P33: 21 | Q33: =IF(표100[[#This Row],[득점]]="","미진행",IF(표100[[#This Row],[득점]]>표100[[#This Row],[실점]],"승",IF(표100[[#This Row],[득점]]=표100[[#This Row],[실점]],"무",IF(표100[[#This Row],[득점]]<표100[[#This Row],[실점]],"패","미진행")))) -> 미진행 | R33: 루마니아 | U33: 이탈리아
P34: 22 | Q34: =IF(표100[[#This Row],[득점]]="","미진행",IF(표100[[#This Row],[득점]]>표100[[#This Row],[실점]],"승",IF(표100[[#This Row],[득점]]=표100[[#This Row],[실점]],"무",IF(표100[[#This Row],[득점]]<표100[[#This Row],[실점]],"패","미진행")))) -> 미진행 | R34: 루마니아 | U34: 이탈리아
P35: 23 | Q35: =IF(표100[[#This Row],[득점]]="","미진행",IF(표100[[#This Row],[득점]]>표100[[#This Row],[실점]],"승",IF(표100[[#This Row],[득점]]=표100[[#This Row],[실점]],"무",IF(표100[[#This Row],[득점]]<표100[[#This Row],[실점]],"패","미진행")))) -> 패 | R35: 루마니아 | S35: 0 | T35: 3 | U35: 크로아티아
P36: 24 | Q36: =IF(표100[[#This Row],[득점]]="","미진행",IF(표100[[#This Row],[득점]]>표100[[#This Row],[실점]],"승",IF(표100[[#This Row],[득점]]=표100[[#This Row],[실점]],"무",IF(표100[[#This Row],[득점]]<표100[[#This Row],[실점]],"패","미진행")))) -> 승 | R36: 루마니아 | S36: 3 | T36: 0 | U36: 크로아티아
P37: 25 | Q37: =IF(표100[[#This Row],[득점]]="","미진행",IF(표100[[#This Row],[득점]]>표100[[#This Row],[실점]],"승",IF(표100[[#This Row],[득점]]=표100[[#This Row],[실점]],"무",IF(표100[[#This Row],[득점]]<표100[[#This Row],[실점]],"패","미진행")))) -> 미진행 | R37: 루마니아 | U37: 포르투갈
P38: 26 | Q38: =IF(표100[[#This Row],[득점]]="","미진행",IF(표100[[#This Row],[득점]]>표100[[#This Row],[실점]],"승",IF(표100[[#This Row],[득점]]=표100[[#This Row],[실점]],"무",IF(표100[[#This Row],[득점]]<표100[[#This Row],[실점]],"패","미진행")))) -> 미진행 | R38: 루마니아 | U38: 포르투갈
P39: 27 | Q39: =IF(표100[[#This Row],[득점]]="","미진행",IF(표100[[#This Row],[득점]]>표100[[#This Row],[실점]],"승",IF(표100[[#This Row],[득점]]=표100[[#This Row],[실점]],"무",IF(표100[[#This Row],[득점]]<표100[[#This Row],[실점]],"패","미진행")))) -> 패 | R39: 루마니아 | S39: 1 | T39: 4 | U39: 프랑스
P40: 28 | Q40: =IF(표100[[#This Row],[득점]]="","미진행",IF(표100[[#This Row],[득점]]>표100[[#This Row],[실점]],"승",IF(표100[[#This Row],[득점]]=표100[[#This Row],[실점]],"무",IF(표100[[#This Row],[득점]]<표100[[#This Row],[실점]],"패","미진행")))) -> 패 | R40: 루마니아 | S40: 1 | T40: 7 | U40: 프랑스
P41: 29 | Q41: =IF(표100[[#This Row],[득점]]="","미진행",IF(표100[[#This Row],[득점]]>표100[[#This Row],[실점]],"승",IF(표100[[#This Row],[득점]]=표100[[#This Row],[실점]],"무",IF(표100[[#This Row],[득점]]<표100[[#This Row],[실점]],"패","미진행")))) -> 승 | R41: 브라질 | S41: 4 | T41: 2 | U41: 대한민국
P42: 30 | Q42: =IF(표100[[#This Row],[득점]]="","미진행",IF(표100[[#This Row],[득점]]>표100[[#This Row],[실점]],"승",IF(표100[[#This Row],[득점]]=표100[[#This Row],[실점]],"무",IF(표100[[#This Row],[득점]]<표100[[#This Row],[실점]],"패","미진행")))) -> 승 | R42: 브라질 | S42: 4 | T42: 1 | U42: 대한민국
...

Sheet 월드컵
D2: 월드컵 GROUP STAGE
O3: A | X3: 승 | Y3: 무 | Z3: 패
B4: A | D4: 순위 | E4: 팀명 | F4: 경기 | G4: 승 | H4: 무 | I4: 패 | J4: 득점 | K4: 실점 | L4: 득실 | M4: 승 점 | O4: 팀1 결과 | P4: 팀1 | Q4: 팀1 S | R4: 팀2 S | S4: 팀2 | T4: 팀2 결과 | V4: 팀 | W4: 경기 | X4: 승 | Y4: 무 | Z4: 패 | AA4: 득점 | AB4: 실점 | AC4: 득실 | AD4: 승점점수
D5: 1 | E5: {=_xlfn._xlws.SORT(_xlfn._xlws.SORT(_xlfn._xlws.SORT(_xlfn._xlws.SORT((_xlfn._xlws.FILTER(표2_4[],표2_4[경기]>(-1),)),7,1),6,-1),8,-1),9,-1)} -> 프랑스 | F5: 6 | G5: 2 | H5: 2 | I5: 2 | J5: 17 | K5: 16 | L5: 1 | M5: 8 | O5: =IF(Q5="","",IF(Q5>R5,"승",IF(Q5=R5,"무",IF(Q5<R5,"패","")))) -> 승 | P5: =V5 -> 브라질 | Q5: 4 | R5: 1 | S5: =V6 -> 이탈리아 | T5: =IF(O5="","",IF(O5="무","무",IF(O5="승","패","승"))) -> 패 | V5: 브라질 | W5: =표2_4[[#This Row],[승]]+표2_4[[#This Row],[무]]+표2_4[[#This Row],[패]] -> 6 | X5: =COUNTIFS(챔스A[팀1 결과],X$3,챔스A[팀1],표2_4[[#This Row],[팀]])+COUNTIFS(챔스A[팀2 결과],X$3,챔스A[팀2],표2_4[[#This Row],[팀]]) -> 2 | Y5: =COUNTIFS(챔스A[팀1 결과],Y$3,챔스A[팀1],표2_4[[#This Row],[팀]])+COUNTIFS(챔스A[팀2 결과],Y$3,챔스A[팀2],표2_4[[#This Row],[팀]]) -> 1 | Z5: =COUNTIFS(챔스A[팀1 결과],Z$3,챔스A[팀1],표2_4[[#This Row],[팀]])+COUNTIFS(챔스A[팀2 결과],Z$3,챔스A[팀2],표2_4[[#This Row],[팀]]) -> 3 | AA5: =SUMIF(챔스A[팀1],표2_4[[#This Row],[팀]],챔스A[팀1 S])+SUMIF(챔스A[팀2],표2_4[[#This Row],[팀]],챔스A[팀2 S]) -> 17 | AB5: =SUMIF(챔스A[팀1],표2_4[[#This Row],[팀]],챔스A[팀2 S])+SUMIF(챔스A[팀2],표2_4[[#This Row],[팀]],챔스A[팀1 S]) -> 17 | AC5: =표2_4[[#This Row],[득점]]-표2_4[[#This Row],[실점]] -> 0 | AD5: =표2_4[[#This Row],[승]]*3+표2_4[[#This Row],[무]] -> 7
D6: 2 | E6: 포르투갈 | F6: 4 | G6: 2 | H6: 1 | I6: 1 | J6: 10 | K6: 9 | L6: 1 | M6: 7 | O6: =IF(Q6="","",IF(Q6>R6,"승",IF(Q6=R6,"무",IF(Q6<R6,"패","")))) -> 패 | P6: =V5 -> 브라질 | Q6: 2 | R6: 4 | S6: =V6 -> 이탈리아 | T6: =IF(O6="","",IF(O6="무","무",IF(O6="승","패","승"))) -> 승 | V6: 이탈리아 | W6: =표2_4[[#This Row],[승]]+표2_4[[#This Row],[무]]+표2_4[[#This Row],[패]] -> 4 | X6: =COUNTIFS(챔스A[팀1 결과],X$3,챔스A[팀1],표2_4[[#This Row],[팀]])+COUNTIFS(챔스A[팀2 결과],X$3,챔스A[팀2],표2_4[[#This Row],[팀]]) -> 2 | Y6: =COUNTIFS(챔스A[팀1 결과],Y$3,챔스A[팀1],표2_4[[#This Row],[팀]])+COUNTIFS(챔스A[팀2 결과],Y$3,챔스A[팀2],표2_4[[#This Row],[팀]]) -> 0 | Z6: =COUNTIFS(챔스A[팀1 결과],Z$3,챔스A[팀1],표2_4[[#This Row],[팀]])+COUNTIFS(챔스A[팀2 결과],Z$3,챔스A[팀2],표2_4[[#This Row],[팀]]) -> 2 | AA6: =SUMIF(챔스A[팀1],표2_4[[#This Row],[팀]],챔스A[팀1 S])+SUMIF(챔스A[팀2],표2_4[[#This Row],[팀]],챔스A[팀2 S]) -> 9 | AB6: =SUMIF(챔스A[팀1],표2_4[[#This Row],[팀]],챔스A[팀2 S])+SUMIF(챔스A[팀2],표2_4[[#This Row],[팀]],챔스A[팀1 S]) -> 11 | AC6: =표2_4[[#This Row],[득점]]-표2_4[[#This Row],[실점]] -> -2 | AD6: =표2_4[[#This Row],[승]]*3+표2_4[[#This Row],[무]] -> 6
D7: 3 | E7: 브라질 | F7: 6 | G7: 2 | H7: 1 | I7: 3 | J7: 17 | K7: 17 | L7: 0 | M7: 7 | O7: =IF(Q7="","",IF(Q7>R7,"승",IF(Q7=R7,"무",IF(Q7<R7,"패","")))) -> 패 | P7: =V5 -> 브라질 | Q7: 1 | R7: 2 | S7: =V7 -> 포르투갈 | T7: =IF(O7="","",IF(O7="무","무",IF(O7="승","패","승"))) -> 승 | V7: 포르투갈 | W7: =표2_4[[#This Row],[승]]+표2_4[[#This Row],[무]]+표2_4[[#This Row],[패]] -> 4 | X7: =COUNTIFS(챔스A[팀1 결과],X$3,챔스A[팀1],표2_4[[#This Row],[팀]])+COUNTIFS(챔스A[팀2 결과],X$3,챔스A[팀2],표2_4[[#This Row],[팀]]) -> 2 | Y7: =COUNTIFS(챔스A[팀1 결과],Y$3,챔스A[팀1],표2_4[[#This Row],[팀]])+COUNTIFS(챔스A[팀2 결과],Y$3,챔스A[팀2],표2_4[[#This Row],[팀]]) -> 1 | Z7: =COUNTIFS(챔스A[팀1 결과],Z$3,챔스A[팀1],표2_4[[#This Row],[팀]])+COUNTIFS(챔스A[팀2 결과],Z$3,챔스A[팀2],표2_4[[#This Row],[팀]]) -> 1 | AA7: =SUMIF(챔스A[팀1],표2_4[[#This Row],[팀]],챔스A[팀1 S])+SUMIF(챔스A[팀2],표2_4[[#This Row],[팀]],챔스A[팀2 S]) -> 10 | AB7: =SUMIF(챔스A[팀1],표2_4[[#This Row],[팀]],챔스A[팀2 S])+SUMIF(챔스A[팀2],표2_4[[#This Row],[팀]],챔스A[팀1 S]) -> 9 | AC7: =표2_4[[#This Row],[득점]]-표2_4[[#This Row],[실점]] -> 1 | AD7: =표2_4[[#This Row],[승]]*3+표2_4[[#This Row],[무]] -> 7
D8: 4 | E8: 이탈리아 | F8: 4 | G8: 2 | H8: 0 | I8: 2 | J8: 9 | K8: 11 | L8: -2 | M8: 6 | O8: =IF(Q8="","",IF(Q8>R8,"승",IF(Q8=R8,"무",IF(Q8<R8,"패","")))) -> 승 | P8: =V5 -> 브라질 | Q8: 4 | R8: 2 | S8: =V7 -> 포르투갈 | T8: =IF(O8="","",IF(O8="무","무",IF(O8="승","패","승"))) -> 패 | V8: 프랑스 | W8: =표2_4[[#This Row],[승]]+표2_4[[#This Row],[무]]+표2_4[[#This Row],[패]] -> 6 | X8: =COUNTIFS(챔스A[팀1 결과],X$3,챔스A[팀1],표2_4[[#This Row],[팀]])+COUNTIFS(챔스A[팀2 결과],X$3,챔스A[팀2],표2_4[[#This Row],[팀]]) -> 2 | Y8: =COUNTIFS(챔스A[팀1 결과],Y$3,챔스A[팀1],표2_4[[#This Row],[팀]])+COUNTIFS(챔스A[팀2 결과],Y$3,챔스A[팀2],표2_4[[#This Row],[팀]]) -> 2 | Z8: =COUNTIFS(챔스A[팀1 결과],Z$3,챔스A[팀1],표2_4[[#This Row],[팀]])+COUNTIFS(챔스A[팀2 결과],Z$3,챔스A[팀2],표2_4[[#This Row],[팀]]) -> 2 | AA8: =SUMIF(챔스A[팀1],표2_4[[#This Row],[팀]],챔스A[팀1 S])+SUMIF(챔스A[팀2],표2_4[[#This Row],[팀]],챔스A[팀2 S]) -> 17 | AB8: =SUMIF(챔스A[팀1],표2_4[[#This Row],[팀]],챔스A[팀2 S])+SUMIF(챔스A[팀2],표2_4[[#This Row],[팀]],챔스A[팀1 S]) -> 16 | AC8: =표2_4[[#This Row],[득점]]-표2_4[[#This Row],[실점]] -> 1 | AD8: =표2_4[[#This Row],[승]]*3+표2_4[[#This Row],[무]] -> 8
O9: =IF(Q9="","",IF(Q9>R9,"승",IF(Q9=R9,"무",IF(Q9<R9,"패","")))) -> 패 | P9: =V5 -> 브라질 | Q9: 2 | R9: 4 | S9: =V8 -> 프랑스 | T9: =IF(O9="","",IF(O9="무","무",IF(O9="승","패","승"))) -> 승
B10: B | D10: R | E10: 팀명 | F10: 경기 | G10: 승 | H10: 무 | I10: 패 | J10: 득점 | K10: 실점 | L10: 득실 | M10: 승 점 | O10: =IF(Q10="","",IF(Q10>R10,"승",IF(Q10=R10,"무",IF(Q10<R10,"패","")))) -> 무 | P10: =V5 -> 브라질 | Q10: 4 | R10: 4 | S10: =V8 -> 프랑스 | T10: =IF(O10="","",IF(O10="무","무",IF(O10="승","패","승"))) -> 무 | X10: 승 | Y10: 무 | Z10: 패
D11: 1 | E11: {=_xlfn._xlws.SORT(_xlfn._xlws.SORT(_xlfn._xlws.SORT(_xlfn._xlws.SORT((_xlfn._xlws.FILTER(표2_46[],표2_46[경기]>(-1),)),7,1),6,-1),8,-1),9,-1)} -> 아르헨티나 | F11: 6 | G11: 2 | H11: 4 | I11: 0 | J11: 13 | K11: 8 | L11: 5 | M11: 10 | O11: =IF(Q11="","",IF(Q11>R11,"승",IF(Q11=R11,"무",IF(Q11<R11,"패","")))) | P11: =V6 -> 이탈리아 | S11: =V7 -> 포르투갈 | T11: =IF(O11="","",IF(O11="무","무",IF(O11="승","패","승"))) | V11: 팀 | W11: 경기 | X11: 승 | Y11: 무 | Z11: 패 | AA11: 득점 | AB11: 실점 | AC11: 득실 | AD11: 승점점수
D12: 2 | E12: 잉글랜드 | F12: 6 | G12: 2 | H12: 3 | I12: 1 | J12: 11 | K12: 10 | L12: 1 | M12: 9 | O12: =IF(Q12="","",IF(Q12>R12,"승",IF(Q12=R12,"무",IF(Q12<R12,"패","")))) | P12: =V6 -> 이탈리아 | S12: =V7 -> 포르투갈 | T12: =IF(O12="","",IF(O12="무","무",IF(O12="승","패","승"))) | V12: 대한민국 | W12: =표2_46[[#This Row],[승]]+표2_46[[#This Row],[무]]+표2_46[[#This Row],[패]] -> 6 | X12: =COUNTIFS(챔스A_7[팀1 결과],X$10,챔스A_7[팀1],표2_46[[#This Row],[팀]])+COUNTIFS(챔스A_7[팀2 결과],X$10,챔스A_7[팀2],표2_46[[#This Row],[팀]]) -> 1 | Y12: =COUNTIFS(챔스A_7[팀1 결과],Y$10,챔스A_7[팀1],표2_46[[#This Row],[팀]])+COUNTIFS(챔스A_7[팀2 결과],Y$10,챔스A_7[팀2],표2_46[[#This Row],[팀]]) -> 0 | Z12: =COUNTIFS(챔스A_7[팀1 결과],Z$10,챔스A_7[팀1],표2_46[[#This Row],[팀]])+COUNTIFS(챔스A_7[팀2 결과],Z$10,챔스A_7[팀2],표2_46[[#This Row],[팀]]) -> 5 | AA12: =SUMIF(챔스A_7[팀1],표2_46[[#This Row],[팀]],챔스A_7[팀1 S])+SUMIF(챔스A_7[팀2],표2_46[[#This Row],[팀]],챔스A_7[팀2 S]) -> 10 | AB12: =SUMIF(챔스A_7[팀1],표2_46[[#This Row],[팀]],챔스A_7[팀2 S])+SUMIF(챔스A_7[팀2],표2_46[[#This Row],[팀]],챔스A_7[팀1 S]) -> 16 | AC12: =표2_46[[#This Row],[득점]]-표2_46[[#This Row],[실점]] -> -6 | AD12: =표2_46[[#This Row],[승]]*3+표2_46[[#This Row],[무]] -> 3
D13: 3 | E13: 스페인 | F13: 6 | G13: 2 | H13: 3 | I13: 1 | J13: 13 | K13: 13 | L13: 0 | M13: 9 | O13: =IF(Q13="","",IF(Q13>R13,"승",IF(Q13=R13,"무",IF(Q13<R13,"패","")))) -> 패 | P13: =V6 -> 이탈리아 | Q13: 1 | R13: 4 | S13: =V8 -> 프랑스 | T13: =IF(O13="","",IF(O13="무","무",IF(O13="승","패","승"))) -> 승 | V13: 스페인 | W13: =표2_46[[#This Row],[승]]+표2_46[[#This Row],[무]]+표2_46[[#This Row],[패]] -> 6 | X13: =COUNTIFS(챔스A_7[팀1 결과],X$10,챔스A_7[팀1],표2_46[[#This Row],[팀]])+COUNTIFS(챔스A_7[팀2 결과],X$10,챔스A_7[팀2],표2_46[[#This Row],[팀]]) -> 2 | Y13: =COUNTIFS(챔스A_7[팀1 결과],Y$10,챔스A_7[팀1],표2_46[[#This Row],[팀]])+COUNTIFS(챔스A_7[팀2 결과],Y$10,챔스A_7[팀2],표2_46[[#This Row],[팀]]) -> 3 | Z13: =COUNTIFS(챔스A_7[팀1 결과],Z$10,챔스A_7[팀1],표2_46[[#This Row],[팀]])+COUNTIFS(챔스A_7[팀2 결과],Z$10,챔스A_7[팀2],표2_46[[#This Row],[팀]]) -> 1 | AA13: =SUMIF(챔스A_7[팀1],표2_46[[#This Row],[팀]],챔스A_7[팀1 S])+SUMIF(챔스A_7[팀2],표2_46[[#This Row],[팀]],챔스A_7[팀2 S]) -> 13 | AB13: =SUMIF(챔스A_7[팀1],표2_46[[#This Row],[팀]],챔스A_7[팀2 S])+SUMIF(챔스A_7[팀2],표2_46[[#This Row],[팀]],챔스A_7[팀1 S]) -> 13 | AC13: =표2_46[[#This Row],[득점]]-표2_46[[#This Row],[실점]] -> 0 | AD13: =표2_46[[#This Row],[승]]*3+표2_46[[#This Row],[무]] -> 9
D14: 4 | E14: 대한민국 | F14: 6 | G14: 1 | H14: 0 | I14: 5 | J14: 10 | K14: 16 | L14: -6 | M14: 3 | O14: =IF(Q14="","",IF(Q14>R14,"승",IF(Q14=R14,"무",IF(Q14<R14,"패","")))) -> 승 | P14: =V6 -> 이탈리아 | Q14: 3 | R14: 1 | S14: =V8 -> 프랑스 | T14: =IF(O14="","",IF(O14="무","무",IF(O14="승","패","승"))) -> 패 | V14: 아르헨티나 | W14: =표2_46[[#This Row],[승]]+표2_46[[#This Row],[무]]+표2_46[[#This Row],[패]] -> 6 | X14: =COUNTIFS(챔스A_7[팀1 결과],X$10,챔스A_7[팀1],표2_46[[#This Row],[팀]])+COUNTIFS(챔스A_7[팀2 결과],X$10,챔스A_7[팀2],표2_46[[#This Row],[팀]]) -> 2 | Y14: =COUNTIFS(챔스A_7[팀1 결과],Y$10,챔스A_7[팀1],표2_46[[#This Row],[팀]])+COUNTIFS(챔스A_7[팀2 결과],Y$10,챔스A_7[팀2],표2_46[[#This Row],[팀]]) -> 4 | Z14: =COUNTIFS(챔스A_7[팀1 결과],Z$10,챔스A_7[팀1],표2_46[[#This Row],[팀]])+COUNTIFS(챔스A_7[팀2 결과],Z$10,챔스A_7[팀2],표2_46[[#This Row],[팀]]) -> 0 | AA14: =SUMIF(챔스A_7[팀1],표2_46[[#This Row],[팀]],챔스A_7[팀1 S])+SUMIF(챔스A_7[팀2],표2_46[[#This Row],[팀]],챔스A_7[팀2 S]) -> 13 | AB14: =SUMIF(챔스A_7[팀1],표2_46[[#This Row],[팀]],챔스A_7[팀2 S])+SUMIF(챔스A_7[팀2],표2_46[[#This Row],[팀]],챔스A_7[팀1 S]) -> 8 | AC14: =표2_46[[#This Row],[득점]]-표2_46[[#This Row],[실점]] -> 5 | AD14: =표2_46[[#This Row],[승]]*3+표2_46[[#This Row],[무]] -> 10
O15: =IF(Q15="","",IF(Q15>R15,"승",IF(Q15=R15,"무",IF(Q15<R15,"패","")))) -> 무 | P15: =V7 -> 포르투갈 | Q15: 2 | R15: 2 | S15: =V8 -> 프랑스 | T15: =IF(O15="","",IF(O15="무","무",IF(O15="승","패","승"))) -> 무 | V15: 잉글랜드 | W15: =표2_46[[#This Row],[승]]+표2_46[[#This Row],[무]]+표2_46[[#This Row],[패]] -> 6 | X15: =COUNTIFS(챔스A_7[팀1 결과],X$10,챔스A_7[팀1],표2_46[[#This Row],[팀]])+COUNTIFS(챔스A_7[팀2 결과],X$10,챔스A_7[팀2],표2_46[[#This Row],[팀]]) -> 2 | Y15: =COUNTIFS(챔스A_7[팀1 결과],Y$10,챔스A_7[팀1],표2_46[[#This Row],[팀]])+COUNTIFS(챔스A_7[팀2 결과],Y$10,챔스A_7[팀2],표2_46[[#This Row],[팀]]) -> 3 | Z15: =COUNTIFS(챔스A_7[팀1 결과],Z$10,챔스A_7[팀1],표2_46[[#This Row],[팀]])+COUNTIFS(챔스A_7[팀2 결과],Z$10,챔스A_7[팀2],표2_46[[#This Row],[팀]]) -> 1 | AA15: =SUMIF(챔스A_7[팀1],표2_46[[#This Row],[팀]],챔스A_7[팀1 S])+SUMIF(챔스A_7[팀2],표2_46[[#This Row],[팀]],챔스A_7[팀2 S]) -> 11 | AB15: =SUMIF(챔스A_7[팀1],표2_46[[#This Row],[팀]],챔스A_7[팀2 S])+SUMIF(챔스A_7[팀2],표2_46[[#This Row],[팀]],챔스A_7[팀1 S]) -> 10 | AC15: =표2_46[[#This Row],[득점]]-표2_46[[#This Row],[실점]] -> 1 | AD15: =표2_46[[#This Row],[승]]*3+표2_46[[#This Row],[무]] -> 9
B16: C | D16: 순위 | E16: 팀명 | F16: 경기 | G16: 승 | H16: 무 | I16: 패 | J16: 득점 | K16: 실점 | L16: 득실 | M16: 승 점 | O16: =IF(Q16="","",IF(Q16>R16,"승",IF(Q16=R16,"무",IF(Q16<R16,"패","")))) -> 승 | P16: =V7 -> 포르투갈 | Q16: 4 | R16: 2 | S16: =V8 -> 프랑스 | T16: =IF(O16="","",IF(O16="무","무",IF(O16="승","패","승"))) -> 패
D17: 1 | E17: {=_xlfn._xlws.SORT(_xlfn._xlws.SORT(_xlfn._xlws.SORT(_xlfn._xlws.SORT((_xlfn._xlws.FILTER(표2_4681015[],표2_4681015[경기]>(-1),)),7,1),6,-1),8,-1),9,-1)} -> 독일 | F17: 4 | G17: 4 | H17: 0 | I17: 0 | J17: 13 | K17: 6 | L17: 7 | M17: 12 | X17: 승 | Y17: 무 | Z17: 패
D18: 2 | E18: 루마니아 | F18: 4 | G18: 2 | H18: 0 | I18: 2 | J18: 9 | K18: 9 | L18: 0 | M18: 6 | O18: B | V18: 팀 | W18: 경기 | X18: 승 | Y18: 무 | Z18: 패 | AA18: 득점 | AB18: 실점 | AC18: 득실 | AD18: 승점점수
D19: 3 | E19: 오스트리아 | F19: 4 | G19: 0 | H19: 0 | I19: 4 | J19: 6 | K19: 13 | L19: -7 | M19: 0 | O19: 팀1 결과 | P19: 팀1 | Q19: 팀1 S | R19: 팀2 S | S19: 팀2 | T19: 팀2 결과 | V19: 독일 | W19: =표2_4681015[[#This Row],[승]]+표2_4681015[[#This Row],[무]]+표2_4681015[[#This Row],[패]] -> 4 | X19: =COUNTIFS(챔스A_791118[팀1 결과],X$17,챔스A_791118[팀1],표2_4681015[[#This Row],[팀]])+COUNTIFS(챔스A_791118[팀2 결과],X$17,챔스A_791118[팀2],표2_4681015[[#This Row],[팀]]) -> 4 | Y19: =COUNTIFS(챔스A_791118[팀1 결과],Y$17,챔스A_791118[팀1],표2_4681015[[#This Row],[팀]])+COUNTIFS(챔스A_791118[팀2 결과],Y$17,챔스A_791118[팀2],표2_4681015[[#This Row],[팀]]) -> 0 | Z19: =COUNTIFS(챔스A_791118[팀1 결과],Z$17,챔스A_791118[팀1],표2_4681015[[#This Row],[팀]])+COUNTIFS(챔스A_791118[팀2 결과],Z$17,챔스A_791118[팀2],표2_4681015[[#This Row],[팀]]) -> 0 | AA19: =SUMIF(챔스A_791118[팀1],표2_4681015[[#This Row],[팀]],챔스A_791118[팀1 S])+SUMIF(챔스A_791118[팀2],표2_4681015[[#This Row],[팀]],챔스A_791118[팀2 S]) -> 13 | AB19: =SUMIF(챔스A_791118[팀1],표2_4681015[[#This Row],[팀]],챔스A_791118[팀2 S])+SUMIF(챔스A_791118[팀2],표2_4681015[[#This Row],[팀]],챔스A_791118[팀1 S]) -> 6 | AC19: =표2_4681015[[#This Row],[득점]]-표2_4681015[[#This Row],[실점]] -> 7 | AD19: =표2_4681015[[#This Row],[승]]*3+표2_4681015[[#This Row],[무]] -> 12
O20: =IF(Q20="","",IF(Q20>R20,"승",IF(Q20=R20,"무",IF(Q20<R20,"패","")))) -> 패 | P20: =V12 -> 대한민국 | Q20: 1 | R20: 2 | S20: =V13 -> 스페인 | T20: =IF(O20="","",IF(O20="무","무",IF(O20="승","패","승"))) -> 승 | V20: 루마니아 | W20: =표2_4681015[[#This Row],[승]]+표2_4681015[[#This Row],[무]]+표2_4681015[[#This Row],[패]] -> 4 | X20: =COUNTIFS(챔스A_791118[팀1 결과],X$17,챔스A_791118[팀1],표2_4681015[[#This Row],[팀]])+COUNTIFS(챔스A_791118[팀2 결과],X$17,챔스A_791118[팀2],표2_4681015[[#This Row],[팀]]) -> 2 | Y20: =COUNTIFS(챔스A_791118[팀1 결과],Y$17,챔스A_791118[팀1],표2_4681015[[#This Row],[팀]])+COUNTIFS(챔스A_791118[팀2 결과],Y$17,챔스A_791118[팀2],표2_4681015[[#This Row],[팀]]) -> 0 | Z20: =COUNTIFS(챔스A_791118[팀1 결과],Z$17,챔스A_791118[팀1],표2_4681015[[#This Row],[팀]])+COUNTIFS(챔스A_791118[팀2 결과],Z$17,챔스A_791118[팀2],표2_4681015[[#This Row],[팀]]) -> 2 | AA20: =SUMIF(챔스A_791118[팀1],표2_4681015[[#This Row],[팀]],챔스A_791118[팀1 S])+SUMIF(챔스A_791118[팀2],표2_4681015[[#This Row],[팀]],챔스A_791118[팀2 S]) -> 9 | AB20: =SUMIF(챔스A_791118[팀1],표2_4681015[[#This Row],[팀]],챔스A_791118[팀2 S])+SUMIF(챔스A_791118[팀2],표2_4681015[[#This Row],[팀]],챔스A_791118[팀1 S]) -> 9 | AC20: =표2_4681015[[#This Row],[득점]]-표2_4681015[[#This Row],[실점]] -> 0 | AD20: =표2_4681015[[#This Row],[승]]*3+표2_4681015[[#This Row],[무]] -> 6
B21: D | D21: 순위 | E21: 팀명 | F21: 경기 | G21: 승 | H21: 무 | I21: 패 | J21: 득점 | K21: 실점 | L21: 득실 | M21: 승 점 | O21: =IF(Q21="","",IF(Q21>R21,"승",IF(Q21=R21,"무",IF(Q21<R21,"패","")))) -> 패 | P21: =V12 -> 대한민국 | Q21: 3 | R21: 5 | S21: =V13 -> 스페인 | T21: =IF(O21="","",IF(O21="무","무",IF(O21="승","패","승"))) -> 승 | V21: 오스트리아 | W21: =표2_4681015[[#This Row],[승]]+표2_4681015[[#This Row],[무]]+표2_4681015[[#This Row],[패]] -> 4 | X21: =COUNTIFS(챔스A_791118[팀1 결과],X$17,챔스A_791118[팀1],표2_4681015[[#This Row],[팀]])+COUNTIFS(챔스A_791118[팀2 결과],X$17,챔스A_791118[팀2],표2_4681015[[#This Row],[팀]]) -> 0 | Y21: =COUNTIFS(챔스A_791118[팀1 결과],Y$17,챔스A_791118[팀1],표2_4681015[[#This Row],[팀]])+COUNTIFS(챔스A_791118[팀2 결과],Y$17,챔스A_791118[팀2],표2_4681015[[#This Row],[팀]]) -> 0 | Z21: =COUNTIFS(챔스A_791118[팀1 결과],Z$17,챔스A_791118[팀1],표2_4681015[[#This Row],[팀]])+COUNTIFS(챔스A_791118[팀2 결과],Z$17,챔스A_791118[팀2],표2_4681015[[#This Row],[팀]]) -> 4 | AA21: =SUMIF(챔스A_791118[팀1],표2_4681015[[#This Row],[팀]],챔스A_791118[팀1 S])+SUMIF(챔스A_791118[팀2],표2_4681015[[#This Row],[팀]],챔스A_791118[팀2 S]) -> 6 | AB21: =SUMIF(챔스A_791118[팀1],표2_4681015[[#This Row],[팀]],챔스A_791118[팀2 S])+SUMIF(챔스A_791118[팀2],표2_4681015[[#This Row],[팀]],챔스A_791118[팀1 S]) -> 13 | AC21: =표2_4681015[[#This Row],[득점]]-표2_4681015[[#This Row],[실점]] -> -7 | AD21: =표2_4681015[[#This Row],[승]]*3+표2_4681015[[#This Row],[무]] -> 0
D22: 1 | E22: {=_xlfn._xlws.SORT(_xlfn._xlws.SORT(_xlfn._xlws.SORT(_xlfn._xlws.SORT((_xlfn._xlws.FILTER(표2_46810[],표2_46810[경기]>(-1),)),7,1),6,-1),8,-1),9,-1)} -> 코트디부아르 | F22: 4 | G22: 4 | H22: 0 | I22: 0 | J22: 12 | K22: 3 | L22: 9 | M22: 12 | O22: =IF(Q22="","",IF(Q22>R22,"승",IF(Q22=R22,"무",IF(Q22<R22,"패","")))) -> 패 | P22: =V12 -> 대한민국 | Q22: 0 | R22: 4 | S22: =V14 -> 아르헨티나 | T22: =IF(O22="","",IF(O22="무","무",IF(O22="승","패","승"))) -> 승 | X22: 승 | Y22: 무 | Z22: 패
D23: 2 | E23: 미국 | F23: 4 | G23: 2 | H23: 0 | I23: 2 | J23: 12 | K23: 8 | L23: 4 | M23: 6 | O23: =IF(Q23="","",IF(Q23>R23,"승",IF(Q23=R23,"무",IF(Q23<R23,"패","")))) -> 패 | P23: =V12 -> 대한민국 | Q23: 2 | R23: 3 | S23: =V14 -> 아르헨티나 | T23: =IF(O23="","",IF(O23="무","무",IF(O23="승","패","승"))) -> 승 | V23: 팀 | W23: 경기 | X23: 승 | Y23: 무 | Z23: 패 | AA23: 득점 | AB23: 실점 | AC23: 득실 | AD23: 승점점수
D24: 3 | E24: 크로아티아 | F24: 4 | G24: 0 | H24: 0 | I24: 4 | J24: 3 | K24: 16 | L24: -13 | M24: 0 | O24: =IF(Q24="","",IF(Q24>R24,"승",IF(Q24=R24,"무",IF(Q24<R24,"패","")))) -> 패 | P24: =V12 -> 대한민국 | Q24: 0 | R24: 2 | S24: =V15 -> 잉글랜드 | T24: =IF(O24="","",IF(O24="무","무",IF(O24="승","패","승"))) -> 승 | V24: 미국 | W24: =표2_46810[[#This Row],[승]]+표2_46810[[#This Row],[무]]+표2_46810[[#This Row],[패]] -> 4 | X24: =COUNTIFS(챔스A_7911[팀1 결과],X$22,챔스A_7911[팀1],표2_46810[[#This Row],[팀]])+COUNTIFS(챔스A_7911[팀2 결과],X$22,챔스A_7911[팀2],표2_46810[[#This Row],[팀]]) -> 2 | Y24: =COUNTIFS(챔스A_7911[팀1 결과],Y$22,챔스A_7911[팀1],표2_46810[[#This Row],[팀]])+COUNTIFS(챔스A_7911[팀2 결과],Y$22,챔스A_7911[팀2],표2_46810[[#This Row],[팀]]) -> 0 | Z24: =COUNTIFS(챔스A_7911[팀1 결과],Z$22,챔스A_7911[팀1],표2_46810[[#This Row],[팀]])+COUNTIFS(챔스A_7911[팀2 결과],Z$22,챔스A_7911[팀2],표2_46810[[#This Row],[팀]]) -> 2 | AA24: =SUMIF(챔스A_7911[팀1],표2_46810[[#This Row],[팀]],챔스A_7911[팀1 S])+SUMIF(챔스A_7911[팀2],표2_46810[[#This Row],[팀]],챔스A_7911[팀2 S]) -> 12 | AB24: =SUMIF(챔스A_7911[팀1],표2_46810[[#This Row],[팀]],챔스A_7911[팀2 S])+SUMIF(챔스A_7911[팀2],표2_46810[[#This Row],[팀]],챔스A_7911[팀1 S]) -> 8 | AC24: =표2_46810[[#This Row],[득점]]-표2_46810[[#This Row],[실점]] -> 4 | AD24: =표2_46810[[#This Row],[승]]*3+표2_46810[[#This Row],[무]] -> 6
O25: =IF(Q25="","",IF(Q25>R25,"승",IF(Q25=R25,"무",IF(Q25<R25,"패","")))) -> 승 | P25: =V12 -> 대한민국 | Q25: 4 | R25: 0 | S25: =V15 -> 잉글랜드 | T25: =IF(O25="","",IF(O25="무","무",IF(O25="승","패","승"))) -> 패 | V25: 코트디부아르 | W25: =표2_46810[[#This Row],[승]]+표2_46810[[#This Row],[무]]+표2_46810[[#This Row],[패]] -> 4 | X25: =COUNTIFS(챔스A_7911[팀1 결과],X$22,챔스A_7911[팀1],표2_46810[[#This Row],[팀]])+COUNTIFS(챔스A_7911[팀2 결과],X$22,챔스A_7911[팀2],표2_46810[[#This Row],[팀]]) -> 4 | Y25: =COUNTIFS(챔스A_7911[팀1 결과],Y$22,챔스A_7911[팀1],표2_46810[[#This Row],[팀]])+COUNTIFS(챔스A_7911[팀2 결과],Y$22,챔스A_7911[팀2],표2_46810[[#This Row],[팀]]) -> 0 | Z25: =COUNTIFS(챔스A_7911[팀1 결과],Z$22,챔스A_7911[팀1],표2_46810[[#This Row],[팀]])+COUNTIFS(챔스A_7911[팀2 결과],Z$22,챔스A_7911[팀2],표2_46810[[#This Row],[팀]]) -> 0 | AA25: =SUMIF(챔스A_7911[팀1],표2_46810[[#This Row],[팀]],챔스A_7911[팀1 S])+SUMIF(챔스A_7911[팀2],표2_46810[[#This Row],[팀]],챔스A_7911[팀2 S]) -> 12 | AB25: =SUMIF(챔스A_7911[팀1],표2_46810[[#This Row],[팀]],챔스A_7911[팀2 S])+SUMIF(챔스A_7911[팀2],표2_46810[[#This Row],[팀]],챔스A_7911[팀1 S]) -> 3 | AC25: =표2_46810[[#This Row],[득점]]-표2_46810[[#This Row],[실점]] -> 9 | AD25: =표2_46810[[#This Row],[승]]*3+표2_46810[[#This Row],[무]] -> 12
O26: =IF(Q26="","",IF(Q26>R26,"승",IF(Q26=R26,"무",IF(Q26<R26,"패","")))) -> 무 | P26: =V13 -> 스페인 | Q26: 1 | R26: 1 | S26: =V14 -> 아르헨티나 | T26: =IF(O26="","",IF(O26="무","무",IF(O26="승","패","승"))) -> 무 | V26: 크로아티아 | W26: =표2_46810[[#This Row],[승]]+표2_46810[[#This Row],[무]]+표2_46810[[#This Row],[패]] -> 4 | X26: =COUNTIFS(챔스A_7911[팀1 결과],X$22,챔스A_7911[팀1],표2_46810[[#This Row],[팀]])+COUNTIFS(챔스A_7911[팀2 결과],X$22,챔스A_7911[팀2],표2_46810[[#This Row],[팀]]) -> 0 | Y26: =COUNTIFS(챔스A_7911[팀1 결과],Y$22,챔스A_7911[팀1],표2_46810[[#This Row],[팀]])+COUNTIFS(챔스A_7911[팀2 결과],Y$22,챔스A_7911[팀2],표2_46810[[#This Row],[팀]]) -> 0 | Z26: =COUNTIFS(챔스A_7911[팀1 결과],Z$22,챔스A_7911[팀1],표2_46810[[#This Row],[팀]])+COUNTIFS(챔스A_7911[팀2 결과],Z$22,챔스A_7911[팀2],표2_46810[[#This Row],[팀]]) -> 4 | AA26: =SUMIF(챔스A_7911[팀1],표2_46810[[#This Row],[팀]],챔스A_7911[팀1 S])+SUMIF(챔스A_7911[팀2],표2_46810[[#This Row],[팀]],챔스A_7911[팀2 S]) -> 3 | AB26: =SUMIF(챔스A_7911[팀1],표2_46810[[#This Row],[팀]],챔스A_7911[팀2 S])+SUMIF(챔스A_7911[팀2],표2_46810[[#This Row],[팀]],챔스A_7911[팀1 S]) -> 16 | AC26: =표2_46810[[#This Row],[득점]]-표2_46810[[#This Row],[실점]] -> -13 | AD26: =표2_46810[[#This Row],[승]]*3+표2_46810[[#This Row],[무]] -> 0
O27: =IF(Q27="","",IF(Q27>R27,"승",IF(Q27=R27,"무",IF(Q27<R27,"패","")))) -> 무 | P27: =V13 -> 스페인 | Q27: 2 | R27: 2 | S27: =V14 -> 아르헨티나 | T27: =IF(O27="","",IF(O27="무","무",IF(O27="승","패","승"))) -> 무
O28: =IF(Q28="","",IF(Q28>R28,"승",IF(Q28=R28,"무",IF(Q28<R28,"패","")))) -> 무 | P28: =V13 -> 스페인 | Q28: 2 | R28: 2 | S28: =V15 -> 잉글랜드 | T28: =IF(O28="","",IF(O28="무","무",IF(O28="승","패","승"))) -> 무
O29: =IF(Q29="","",IF(Q29>R29,"승",IF(Q29=R29,"무",IF(Q29<R29,"패","")))) -> 패 | P29: =V13 -> 스페인 | Q29: 1 | R29: 4 | S29: =V15 -> 잉글랜드 | T29: =IF(O29="","",IF(O29="무","무",IF(O29="승","패","승"))) -> 승
O30: =IF(Q30="","",IF(Q30>R30,"승",IF(Q30=R30,"무",IF(Q30<R30,"패","")))) -> 무 | P30: =V14 -> 아르헨티나 | Q30: 1 | R30: 1 | S30: =V15 -> 잉글랜드 | T30: =IF(O30="","",IF(O30="무","무",IF(O30="승","패","승"))) -> 무
O31: =IF(Q31="","",IF(Q31>R31,"승",IF(Q31=R31,"무",IF(Q31<R31,"패","")))) -> 무 | P31: =V14 -> 아르헨티나 | Q31: 2 | R31: 2 | S31: =V15 -> 잉글랜드 | T31: =IF(O31="","",IF(O31="무","무",IF(O31="승","패","승"))) -> 무
O33: C
O34: 팀1 결과 | P34: 팀1 | Q34: 팀1 S | R34: 팀2 S | S34: 팀2 | T34: 팀2 결과
O35: =IF(Q35="","",IF(Q35>R35,"승",IF(Q35=R35,"무",IF(Q35<R35,"패","")))) -> 승 | P35: =V19 -> 독일 | Q35: 3 | R35: 1 | S35: =V20 -> 루마니아 | T35: =IF(O35="","",IF(O35="무","무",IF(O35="승","패","승"))) -> 패
O36: =IF(Q36="","",IF(Q36>R36,"승",IF(Q36=R36,"무",IF(Q36<R36,"패","")))) -> 승 | P36: =V19 -> 독일 | Q36: 3 | R36: 2 | S36: =V20 -> 루마니아 | T36: =IF(O36="","",IF(O36="무","무",IF(O36="승","패","승"))) -> 패
O37: =IF(Q37="","",IF(Q37>R37,"승",IF(Q37=R37,"무",IF(Q37<R37,"패","")))) -> 승 | P37: =V19 -> 독일 | Q37: 3 | R37: 0 | S37: =V21 -> 오스트리아 | T37: =IF(O37="","",IF(O37="무","무",IF(O37="승","패","승"))) -> 패
O38: =IF(Q38="","",IF(Q38>R38,"승",IF(Q38=R38,"무",IF(Q38<R38,"패","")))) -> 승 | P38: =V19 -> 독일 | Q38: 4 | R38: 3 | S38: =V21 -> 오스트리아 | T38: =IF(O38="","",IF(O38="무","무",IF(O38="승","패","승"))) -> 패
O39: =IF(Q39="","",IF(Q39>R39,"승",IF(Q39=R39,"무",IF(Q39<R39,"패","")))) -> 승 | P39: =V20 -> 루마니아 | Q39: 3 | R39: 1 | S39: =V21 -> 오스트리아 | T39: =IF(O39="","",IF(O39="무","무",IF(O39="승","패","승"))) -> 패
O40: =IF(Q40="","",IF(Q40>R40,"승",IF(Q40=R40,"무",IF(Q40<R40,"패","")))) -> 승 | P40: =V20 -> 루마니아 | Q40: 3 | R40: 2 | S40: =V21 -> 오스트리아 | T40: =IF(O40="","",IF(O40="무","무",IF(O40="승","패","승"))) -> 패
O42: D
O43: 팀1 결과 | P43: 팀1 | Q43: 팀1 S | R43: 팀2 S | S43: 팀2 | T43: 팀2 결과
...

Sheet 유로
D2: 챔피언스리그 GROUP STAGE | O2: A | X2: 승 | Y2: 무 | Z2: 패
O3: 팀1 결과 | P3: 팀1 | Q3: 팀1 S | R3: 팀2 S | S3: 팀2 | T3: 팀2 결과 | V3: 팀 | W3: 경기 | X3: 승 | Y3: 무 | Z3: 패 | AA3: 득점 | AB3: 실점 | AC3: 득실 | AD3: 승점점수
B4: A | D4: 순위 | E4: 팀명 | F4: 경기 | G4: 승 | H4: 무 | I4: 패 | J4: 득점 | K4: 실점 | L4: 득실 | M4: 승 점 | O4: =IF(Q4="","",IF(Q4>R4,"승",IF(Q4=R4,"무",IF(Q4<R4,"패","")))) | P4: =V4 -> 루마니아 | S4: =V5 -> 이탈리아 | T4: =IF(O4="","",IF(O4="무","무",IF(O4="승","패","승"))) | V4: 루마니아 | W4: =표2_42[[#This Row],[승]]+표2_42[[#This Row],[무]]+표2_42[[#This Row],[패]] -> 0 | X4: =COUNTIFS(챔스A_8[팀1 결과],X$2,챔스A_8[팀1],표2_42[[#This Row],[팀]])+COUNTIFS(챔스A_8[팀2 결과],X$2,챔스A_8[팀2],표2_42[[#This Row],[팀]]) -> 0 | Y4: =COUNTIFS(챔스A_8[팀1 결과],Y$2,챔스A_8[팀1],표2_42[[#This Row],[팀]])+COUNTIFS(챔스A_8[팀2 결과],Y$2,챔스A_8[팀2],표2_42[[#This Row],[팀]]) -> 0 | Z4: =COUNTIFS(챔스A_8[팀1 결과],Z$2,챔스A_8[팀1],표2_42[[#This Row],[팀]])+COUNTIFS(챔스A_8[팀2 결과],Z$2,챔스A_8[팀2],표2_42[[#This Row],[팀]]) -> 0 | AA4: =SUMIF(챔스A_8[팀1],표2_42[[#This Row],[팀]],챔스A_8[팀1 S])+SUMIF(챔스A_8[팀2],표2_42[[#This Row],[팀]],챔스A_8[팀2 S]) -> 0 | AB4: =SUMIF(챔스A_8[팀1],표2_42[[#This Row],[팀]],챔스A_8[팀2 S])+SUMIF(챔스A_8[팀2],표2_42[[#This Row],[팀]],챔스A_8[팀1 S]) -> 0 | AC4: =표2_42[[#This Row],[득점]]-표2_42[[#This Row],[실점]] -> 0 | AD4: =표2_42[[#This Row],[승]]*3+표2_42[[#This Row],[무]] -> 0
D5: 1 | E5: {=_xlfn._xlws.SORT(_xlfn._xlws.SORT(_xlfn._xlws.SORT(_xlfn._xlws.SORT((_xlfn._xlws.FILTER(표2_42[],표2_42[경기]>(-1),)),7,1),6,-1),8,-1),9,-1)} -> 루마니아 | F5: 0 | G5: 0 | H5: 0 | I5: 0 | J5: 0 | K5: 0 | L5: 0 | M5: 0 | O5: =IF(Q5="","",IF(Q5>R5,"승",IF(Q5=R5,"무",IF(Q5<R5,"패","")))) | P5: =V4 -> 루마니아 | S5: =V5 -> 이탈리아 | T5: =IF(O5="","",IF(O5="무","무",IF(O5="승","패","승"))) | V5: 이탈리아 | W5: =표2_42[[#This Row],[승]]+표2_42[[#This Row],[무]]+표2_42[[#This Row],[패]] -> 0 | X5: =COUNTIFS(챔스A_8[팀1 결과],X$2,챔스A_8[팀1],표2_42[[#This Row],[팀]])+COUNTIFS(챔스A_8[팀2 결과],X$2,챔스A_8[팀2],표2_42[[#This Row],[팀]]) -> 0 | Y5: =COUNTIFS(챔스A_8[팀1 결과],Y$2,챔스A_8[팀1],표2_42[[#This Row],[팀]])+COUNTIFS(챔스A_8[팀2 결과],Y$2,챔스A_8[팀2],표2_42[[#This Row],[팀]]) -> 0 | Z5: =COUNTIFS(챔스A_8[팀1 결과],Z$2,챔스A_8[팀1],표2_42[[#This Row],[팀]])+COUNTIFS(챔스A_8[팀2 결과],Z$2,챔스A_8[팀2],표2_42[[#This Row],[팀]]) -> 0 | AA5: =SUMIF(챔스A_8[팀1],표2_42[[#This Row],[팀]],챔스A_8[팀1 S])+SUMIF(챔스A_8[팀2],표2_42[[#This Row],[팀]],챔스A_8[팀2 S]) -> 0 | AB5: =SUMIF(챔스A_8[팀1],표2_42[[#This Row],[팀]],챔스A_8[팀2 S])+SUMIF(챔스A_8[팀2],표2_42[[#This Row],[팀]],챔스A_8[팀1 S]) -> 0 | AC5: =표2_42[[#This Row],[득점]]-표2_42[[#This Row],[실점]] -> 0 | AD5: =표2_42[[#This Row],[승]]*3+표2_42[[#This Row],[무]] -> 0
D6: 2 | E6: 이탈리아 | F6: 0 | G6: 0 | H6: 0 | I6: 0 | J6: 0 | K6: 0 | L6: 0 | M6: 0 | O6: =IF(Q6="","",IF(Q6>R6,"승",IF(Q6=R6,"무",IF(Q6<R6,"패","")))) | P6: =V4 -> 루마니아 | S6: =V6 -> 포르투갈 | T6: =IF(O6="","",IF(O6="무","무",IF(O6="승","패","승"))) | V6: 포르투갈 | W6: =표2_42[[#This Row],[승]]+표2_42[[#This Row],[무]]+표2_42[[#This Row],[패]] -> 0 | X6: =COUNTIFS(챔스A_8[팀1 결과],X$2,챔스A_8[팀1],표2_42[[#This Row],[팀]])+COUNTIFS(챔스A_8[팀2 결과],X$2,챔스A_8[팀2],표2_42[[#This Row],[팀]]) -> 0 | Y6: =COUNTIFS(챔스A_8[팀1 결과],Y$2,챔스A_8[팀1],표2_42[[#This Row],[팀]])+COUNTIFS(챔스A_8[팀2 결과],Y$2,챔스A_8[팀2],표2_42[[#This Row],[팀]]) -> 0 | Z6: =COUNTIFS(챔스A_8[팀1 결과],Z$2,챔스A_8[팀1],표2_42[[#This Row],[팀]])+COUNTIFS(챔스A_8[팀2 결과],Z$2,챔스A_8[팀2],표2_42[[#This Row],[팀]]) -> 0 | AA6: =SUMIF(챔스A_8[팀1],표2_42[[#This Row],[팀]],챔스A_8[팀1 S])+SUMIF(챔스A_8[팀2],표2_42[[#This Row],[팀]],챔스A_8[팀2 S]) -> 0 | AB6: =SUMIF(챔스A_8[팀1],표2_42[[#This Row],[팀]],챔스A_8[팀2 S])+SUMIF(챔스A_8[팀2],표2_42[[#This Row],[팀]],챔스A_8[팀1 S]) -> 0 | AC6: =표2_42[[#This Row],[득점]]-표2_42[[#This Row],[실점]] -> 0 | AD6: =표2_42[[#This Row],[승]]*3+표2_42[[#This Row],[무]] -> 0
D7: 3 | E7: 포르투갈 | F7: 0 | G7: 0 | H7: 0 | I7: 0 | J7: 0 | K7: 0 | L7: 0 | M7: 0 | O7: =IF(Q7="","",IF(Q7>R7,"승",IF(Q7=R7,"무",IF(Q7<R7,"패","")))) | P7: =V4 -> 루마니아 | S7: =V6 -> 포르투갈 | T7: =IF(O7="","",IF(O7="무","무",IF(O7="승","패","승")))
O8: =IF(Q8="","",IF(Q8>R8,"승",IF(Q8=R8,"무",IF(Q8<R8,"패","")))) | P8: =V5 -> 이탈리아 | S8: =V6 -> 포르투갈 | T8: =IF(O8="","",IF(O8="무","무",IF(O8="승","패","승"))) | X8: 승 | Y8: 무 | Z8: 패
B9: B | D9: R | E9: 팀명 | F9: 경기 | G9: 승 | H9: 무 | I9: 패 | J9: 득점 | K9: 실점 | L9: 득실 | M9: 승 점 | O9: =IF(Q9="","",IF(Q9>R9,"승",IF(Q9=R9,"무",IF(Q9<R9,"패","")))) | P9: =V5 -> 이탈리아 | S9: =V6 -> 포르투갈 | T9: =IF(O9="","",IF(O9="무","무",IF(O9="승","패","승"))) | V9: 팀 | W9: 경기 | X9: 승 | Y9: 무 | Z9: 패 | AA9: 득점 | AB9: 실점 | AC9: 득실 | AD9: 승점점수
D10: 1 | E10: {=_xlfn._xlws.SORT(_xlfn._xlws.SORT(_xlfn._xlws.SORT(_xlfn._xlws.SORT((_xlfn._xlws.FILTER(표2_469[],표2_469[경기]>(-1),)),7,1),6,-1),8,-1),9,-1)} -> 오스트리아 | F10: 4 | G10: 2 | H10: 2 | I10: 0 | J10: 11 | K10: 7 | L10: 4 | M10: 8 | V10: 독일 | W10: =표2_469[[#This Row],[승]]+표2_469[[#This Row],[무]]+표2_469[[#This Row],[패]] -> 4 | X10: =COUNTIFS(챔스A_713[팀1 결과],X$8,챔스A_713[팀1],표2_469[[#This Row],[팀]])+COUNTIFS(챔스A_713[팀2 결과],X$8,챔스A_713[팀2],표2_469[[#This Row],[팀]]) -> 1 | Y10: =COUNTIFS(챔스A_713[팀1 결과],Y$8,챔스A_713[팀1],표2_469[[#This Row],[팀]])+COUNTIFS(챔스A_713[팀2 결과],Y$8,챔스A_713[팀2],표2_469[[#This Row],[팀]]) -> 2 | Z10: =COUNTIFS(챔스A_713[팀1 결과],Z$8,챔스A_713[팀1],표2_469[[#This Row],[팀]])+COUNTIFS(챔스A_713[팀2 결과],Z$8,챔스A_713[팀2],표2_469[[#This Row],[팀]]) -> 1 | AA10: =SUMIF(챔스A_713[팀1],표2_469[[#This Row],[팀]],챔스A_713[팀1 S])+SUMIF(챔스A_713[팀2],표2_469[[#This Row],[팀]],챔스A_713[팀2 S]) -> 12 | AB10: =SUMIF(챔스A_713[팀1],표2_469[[#This Row],[팀]],챔스A_713[팀2 S])+SUMIF(챔스A_713[팀2],표2_469[[#This Row],[팀]],챔스A_713[팀1 S]) -> 11 | AC10: =표2_469[[#This Row],[득점]]-표2_469[[#This Row],[실점]] -> 1 | AD10: =표2_469[[#This Row],[승]]*3+표2_469[[#This Row],[무]] -> 5
D11: 2 | E11: 독일 | F11: 4 | G11: 1 | H11: 2 | I11: 1 | J11: 12 | K11: 11 | L11: 1 | M11: 5 | O11: B | V11: 오스트리아 | W11: =표2_469[[#This Row],[승]]+표2_469[[#This Row],[무]]+표2_469[[#This Row],[패]] -> 4 | X11: =COUNTIFS(챔스A_713[팀1 결과],X$8,챔스A_713[팀1],표2_469[[#This Row],[팀]])+COUNTIFS(챔스A_713[팀2 결과],X$8,챔스A_713[팀2],표2_469[[#This Row],[팀]]) -> 2 | Y11: =COUNTIFS(챔스A_713[팀1 결과],Y$8,챔스A_713[팀1],표2_469[[#This Row],[팀]])+COUNTIFS(챔스A_713[팀2 결과],Y$8,챔스A_713[팀2],표2_469[[#This Row],[팀]]) -> 2 | Z11: =COUNTIFS(챔스A_713[팀1 결과],Z$8,챔스A_713[팀1],표2_469[[#This Row],[팀]])+COUNTIFS(챔스A_713[팀2 결과],Z$8,챔스A_713[팀2],표2_469[[#This Row],[팀]]) -> 0 | AA11: =SUMIF(챔스A_713[팀1],표2_469[[#This Row],[팀]],챔스A_713[팀1 S])+SUMIF(챔스A_713[팀2],표2_469[[#This Row],[팀]],챔스A_713[팀2 S]) -> 11 | AB11: =SUMIF(챔스A_713[팀1],표2_469[[#This Row],[팀]],챔스A_713[팀2 S])+SUMIF(챔스A_713[팀2],표2_469[[#This Row],[팀]],챔스A_713[팀1 S]) -> 7 | AC11: =표2_469[[#This Row],[득점]]-표2_469[[#This Row],[실점]] -> 4 | AD11: =표2_469[[#This Row],[승]]*3+표2_469[[#This Row],[무]] -> 8
D12: 3 | E12: 프랑스 | F12: 4 | G12: 0 | H12: 2 | I12: 2 | J12: 7 | K12: 12 | L12: -5 | M12: 2 | O12: 팀1 결과 | P12: 팀1 | Q12: 팀1 S | R12: 팀2 S | S12: 팀2 | T12: 팀2 결과 | V12: 프랑스 | W12: =표2_469[[#This Row],[승]]+표2_469[[#This Row],[무]]+표2_469[[#This Row],[패]] -> 4 | X12: =COUNTIFS(챔스A_713[팀1 결과],X$8,챔스A_713[팀1],표2_469[[#This Row],[팀]])+COUNTIFS(챔스A_713[팀2 결과],X$8,챔스A_713[팀2],표2_469[[#This Row],[팀]]) -> 0 | Y12: =COUNTIFS(챔스A_713[팀1 결과],Y$8,챔스A_713[팀1],표2_469[[#This Row],[팀]])+COUNTIFS(챔스A_713[팀2 결과],Y$8,챔스A_713[팀2],표2_469[[#This Row],[팀]]) -> 2 | Z12: =COUNTIFS(챔스A_713[팀1 결과],Z$8,챔스A_713[팀1],표2_469[[#This Row],[팀]])+COUNTIFS(챔스A_713[팀2 결과],Z$8,챔스A_713[팀2],표2_469[[#This Row],[팀]]) -> 2 | AA12: =SUMIF(챔스A_713[팀1],표2_469[[#This Row],[팀]],챔스A_713[팀1 S])+SUMIF(챔스A_713[팀2],표2_469[[#This Row],[팀]],챔스A_713[팀2 S]) -> 7 | AB12: =SUMIF(챔스A_713[팀1],표2_469[[#This Row],[팀]],챔스A_713[팀2 S])+SUMIF(챔스A_713[팀2],표2_469[[#This Row],[팀]],챔스A_713[팀1 S]) -> 12 | AC12: =표2_469[[#This Row],[득점]]-표2_469[[#This Row],[실점]] -> -5 | AD12: =표2_469[[#This Row],[승]]*3+표2_469[[#This Row],[무]] -> 2
O13: =IF(Q13="","",IF(Q13>R13,"승",IF(Q13=R13,"무",IF(Q13<R13,"패","")))) -> 패 | P13: =V10 -> 독일 | Q13: 1 | R13: 4 | S13: =V11 -> 오스트리아 | T13: =IF(O13="","",IF(O13="무","무",IF(O13="승","패","승"))) -> 승
B14: C | D14: 순위 | E14: 팀명 | F14: 경기 | G14: 승 | H14: 무 | I14: 패 | J14: 득점 | K14: 실점 | L14: 득실 | M14: 승 점 | O14: =IF(Q14="","",IF(Q14>R14,"승",IF(Q14=R14,"무",IF(Q14<R14,"패","")))) -> 무 | P14: =V10 -> 독일 | Q14: 3 | R14: 3 | S14: =V11 -> 오스트리아 | T14: =IF(O14="","",IF(O14="무","무",IF(O14="승","패","승"))) -> 무 | X14: 승 | Y14: 무 | Z14: 패
D15: 1 | E15: {=_xlfn._xlws.SORT(_xlfn._xlws.SORT(_xlfn._xlws.SORT(_xlfn._xlws.SORT((_xlfn._xlws.FILTER(표2_468101519[],표2_468101519[경기]>(-1),)),7,1),6,-1),8,-1),9,-1)} -> 잉글랜드 | F15: 4 | G15: 3 | H15: 1 | I15: 0 | J15: 13 | K15: 5 | L15: 8 | M15: 10 | O15: =IF(Q15="","",IF(Q15>R15,"승",IF(Q15=R15,"무",IF(Q15<R15,"패","")))) -> 무 | P15: =V10 -> 독일 | Q15: 3 | R15: 3 | S15: =V12 -> 프랑스 | T15: =IF(O15="","",IF(O15="무","무",IF(O15="승","패","승"))) -> 무 | V15: 팀 | W15: 경기 | X15: 승 | Y15: 무 | Z15: 패 | AA15: 득점 | AB15: 실점 | AC15: 득실 | AD15: 승점점수
D16: 2 | E16: 크로아티아 | F16: 4 | G16: 1 | H16: 1 | I16: 2 | J16: 7 | K16: 8 | L16: -1 | M16: 4 | O16: =IF(Q16="","",IF(Q16>R16,"승",IF(Q16=R16,"무",IF(Q16<R16,"패","")))) -> 승 | P16: =V10 -> 독일 | Q16: 5 | R16: 1 | S16: =V12 -> 프랑스 | T16: =IF(O16="","",IF(O16="무","무",IF(O16="승","패","승"))) -> 패 | V16: 스페인 | W16: =표2_468101519[[#This Row],[승]]+표2_468101519[[#This Row],[무]]+표2_468101519[[#This Row],[패]] -> 4 | X16: =COUNTIFS(챔스A_79111820[팀1 결과],X$14,챔스A_79111820[팀1],표2_468101519[[#This Row],[팀]])+COUNTIFS(챔스A_79111820[팀2 결과],X$14,챔스A_79111820[팀2],표2_468101519[[#This Row],[팀]]) -> 1 | Y16: =COUNTIFS(챔스A_79111820[팀1 결과],Y$14,챔스A_79111820[팀1],표2_468101519[[#This Row],[팀]])+COUNTIFS(챔스A_79111820[팀2 결과],Y$14,챔스A_79111820[팀2],표2_468101519[[#This Row],[팀]]) -> 0 | Z16: =COUNTIFS(챔스A_79111820[팀1 결과],Z$14,챔스A_79111820[팀1],표2_468101519[[#This Row],[팀]])+COUNTIFS(챔스A_79111820[팀2 결과],Z$14,챔스A_79111820[팀2],표2_468101519[[#This Row],[팀]]) -> 3 | AA16: =SUMIF(챔스A_79111820[팀1],표2_468101519[[#This Row],[팀]],챔스A_79111820[팀1 S])+SUMIF(챔스A_79111820[팀2],표2_468101519[[#This Row],[팀]],챔스A_79111820[팀2 S]) -> 4 | AB16: =SUMIF(챔스A_79111820[팀1],표2_468101519[[#This Row],[팀]],챔스A_79111820[팀2 S])+SUMIF(챔스A_79111820[팀2],표2_468101519[[#This Row],[팀]],챔스A_79111820[팀1 S]) -> 11 | AC16: =표2_468101519[[#This Row],[득점]]-표2_468101519[[#This Row],[실점]] -> -7 | AD16: =표2_468101519[[#This Row],[승]]*3+표2_468101519[[#This Row],[무]] -> 3
D17: 3 | E17: 스페인 | F17: 4 | G17: 1 | H17: 0 | I17: 3 | J17: 4 | K17: 11 | L17: -7 | M17: 3 | O17: =IF(Q17="","",IF(Q17>R17,"승",IF(Q17=R17,"무",IF(Q17<R17,"패","")))) -> 무 | P17: =V11 -> 오스트리아 | Q17: 2 | R17: 2 | S17: =V12 -> 프랑스 | T17: =IF(O17="","",IF(O17="무","무",IF(O17="승","패","승"))) -> 무 | V17: 잉글랜드 | W17: =표2_468101519[[#This Row],[승]]+표2_468101519[[#This Row],[무]]+표2_468101519[[#This Row],[패]] -> 4 | X17: =COUNTIFS(챔스A_79111820[팀1 결과],X$14,챔스A_79111820[팀1],표2_468101519[[#This Row],[팀]])+COUNTIFS(챔스A_79111820[팀2 결과],X$14,챔스A_79111820[팀2],표2_468101519[[#This Row],[팀]]) -> 3 | Y17: =COUNTIFS(챔스A_79111820[팀1 결과],Y$14,챔스A_79111820[팀1],표2_468101519[[#This Row],[팀]])+COUNTIFS(챔스A_79111820[팀2 결과],Y$14,챔스A_79111820[팀2],표2_468101519[[#This Row],[팀]]) -> 1 | Z17: =COUNTIFS(챔스A_79111820[팀1 결과],Z$14,챔스A_79111820[팀1],표2_468101519[[#This Row],[팀]])+COUNTIFS(챔스A_79111820[팀2 결과],Z$14,챔스A_79111820[팀2],표2_468101519[[#This Row],[팀]]) -> 0 | AA17: =SUMIF(챔스A_79111820[팀1],표2_468101519[[#This Row],[팀]],챔스A_79111820[팀1 S])+SUMIF(챔스A_79111820[팀2],표2_468101519[[#This Row],[팀]],챔스A_79111820[팀2 S]) -> 13 | AB17: =SUMIF(챔스A_79111820[팀1],표2_468101519[[#This Row],[팀]],챔스A_79111820[팀2 S])+SUMIF(챔스A_79111820[팀2],표2_468101519[[#This Row],[팀]],챔스A_79111820[팀1 S]) -> 5 | AC17: =표2_468101519[[#This Row],[득점]]-표2_468101519[[#This Row],[실점]] -> 8 | AD17: =표2_468101519[[#This Row],[승]]*3+표2_468101519[[#This Row],[무]] -> 10
O18: =IF(Q18="","",IF(Q18>R18,"승",IF(Q18=R18,"무",IF(Q18<R18,"패","")))) -> 승 | P18: =V11 -> 오스트리아 | Q18: 2 | R18: 1 | S18: =V12 -> 프랑스 | T18: =IF(O18="","",IF(O18="무","무",IF(O18="승","패","승"))) -> 패 | V18: 크로아티아 | W18: =표2_468101519[[#This Row],[승]]+표2_468101519[[#This Row],[무]]+표2_468101519[[#This Row],[패]] -> 4 | X18: =COUNTIFS(챔스A_79111820[팀1 결과],X$14,챔스A_79111820[팀1],표2_468101519[[#This Row],[팀]])+COUNTIFS(챔스A_79111820[팀2 결과],X$14,챔스A_79111820[팀2],표2_468101519[[#This Row],[팀]]) -> 1 | Y18: =COUNTIFS(챔스A_79111820[팀1 결과],Y$14,챔스A_79111820[팀1],표2_468101519[[#This Row],[팀]])+COUNTIFS(챔스A_79111820[팀2 결과],Y$14,챔스A_79111820[팀2],표2_468101519[[#This Row],[팀]]) -> 1 | Z18: =COUNTIFS(챔스A_79111820[팀1 결과],Z$14,챔스A_79111820[팀1],표2_468101519[[#This Row],[팀]])+COUNTIFS(챔스A_79111820[팀2 결과],Z$14,챔스A_79111820[팀2],표2_468101519[[#This Row],[팀]]) -> 2 | AA18: =SUMIF(챔스A_79111820[팀1],표2_468101519[[#This Row],[팀]],챔스A_79111820[팀1 S])+SUMIF(챔스A_79111820[팀2],표2_468101519[[#This Row],[팀]],챔스A_79111820[팀2 S]) -> 7 | AB18: =SUMIF(챔스A_79111820[팀1],표2_468101519[[#This Row],[팀]],챔스A_79111820[팀2 S])+SUMIF(챔스A_79111820[팀2],표2_468101519[[#This Row],[팀]],챔스A_79111820[팀1 S]) -> 8 | AC18: =표2_468101519[[#This Row],[득점]]-표2_468101519[[#This Row],[실점]] -> -1 | AD18: =표2_468101519[[#This Row],[승]]*3+표2_468101519[[#This Row],[무]] -> 4
O20: C
O21: 팀1 결과 | P21: 팀1 | Q21: 팀1 S | R21: 팀2 S | S21: 팀2 | T21: 팀2 결과
O22: =IF(Q22="","",IF(Q22>R22,"승",IF(Q22=R22,"무",IF(Q22<R22,"패","")))) -> 패 | P22: =V16 -> 스페인 | Q22: 0 | R22: 6 | S22: =V17 -> 잉글랜드 | T22: =IF(O22="","",IF(O22="무","무",IF(O22="승","패","승"))) -> 승
O23: =IF(Q23="","",IF(Q23>R23,"승",IF(Q23=R23,"무",IF(Q23<R23,"패","")))) -> 패 | P23: =V16 -> 스페인 | Q23: 1 | R23: 2 | S23: =V17 -> 잉글랜드 | T23: =IF(O23="","",IF(O23="무","무",IF(O23="승","패","승"))) -> 승
O24: =IF(Q24="","",IF(Q24>R24,"승",IF(Q24=R24,"무",IF(Q24<R24,"패","")))) -> 승 | P24: =V16 -> 스페인 | Q24: 1 | R24: 0 | S24: =V18 -> 크로아티아 | T24: =IF(O24="","",IF(O24="무","무",IF(O24="승","패","승"))) -> 패
O25: =IF(Q25="","",IF(Q25>R25,"승",IF(Q25=R25,"무",IF(Q25<R25,"패","")))) -> 패 | P25: =V16 -> 스페인 | Q25: 2 | R25: 3 | S25: =V18 -> 크로아티아 | T25: =IF(O25="","",IF(O25="무","무",IF(O25="승","패","승"))) -> 승
O26: =IF(Q26="","",IF(Q26>R26,"승",IF(Q26=R26,"무",IF(Q26<R26,"패","")))) -> 승 | P26: =V17 -> 잉글랜드 | Q26: 2 | R26: 1 | S26: =V18 -> 크로아티아 | T26: =IF(O26="","",IF(O26="무","무",IF(O26="승","패","승"))) -> 패
O27: =IF(Q27="","",IF(Q27>R27,"승",IF(Q27=R27,"무",IF(Q27<R27,"패","")))) -> 무 | P27: =V17 -> 잉글랜드 | Q27: 3 | R27: 3 | S27: =V18 -> 크로아티아 | T27: =IF(O27="","",IF(O27="무","무",IF(O27="승","패","승"))) -> 무

Sheet FA CUP
C3: FA컵 | D3: 1 | E3: 뮌헨 | F3: =E3 -> 뮌헨
D4: - | E4: -
D5: 2 | E5: 뉴캐슬
D6: 3 | E6: 맨유
D7: 4 | E7: 레알 마드리드
D8: 5 | E8: 인테르
D9: 6 | E9: 레버쿠젠 | F9: =E9 -> 레버쿠젠
D10: 7 | E10: 아우크스부르크
D11: 8 | E11: 도르트문트 | F11: =E11 -> 도르트문트
D12: - | E12: -
D13: 9 | E13: 유벤투스
D14: 10 | E14: PSV
D15: 11 | E15: ATM | F15: =E16 -> 비야레알 | G15: =F15 -> 비야레알
D16: 12 | E16: 비야레알
D17: 13 | E17: 토트넘 | F17: =E17 -> 토트넘
D18: 14 | E18: 첼시
